Workbook

Sheet README
A1: KMT HomePrice.uz — оценка размера рынка и спроса, Ташкент, этап 1
A2: Версия 0.1 · 18.10.2026 · Связан с 01_Product/research/market_size.md (выводы и допущения)
A4: Структура: Данные (только источники и опубликованные цифры) → Допущения (параметры вывода, 3 сценария) → СверхуВниз → СнизуВверх → Сценарии → Сравнение → Чувствительность → Конкуренты → ЗапросДанных → Проверки.
A5: Данные и допущения разделены намеренно: лист «Данные» не содержит оценок, лист «Допущения» не содержит фактов (кроме ссылок на «Данные»).
A6: Цвета: синий — вводимое значение (данные или допущение); чёрный — формула; зелёный — ссылка на другой лист; жёлтая заливка — ключевое допущение, которое надо заменить данными в первую очередь.
A7: Теги: [факт] — опубликовано источником (дата и год данных указаны); [гипотеза] — допущение или расчёт на непроверенных данных; [проверить] — нужна проверка или данные от владельца/KMT.
A8: Сценарии: осторожный / базовый / оптимистичный. Это не «пессимизм/оптимизм» одной цифры, а согласованные наборы параметров; независимыми их считать нельзя.
A9: Важно: все деньги в сумах, пересчёт в доллары по курсу ЦБ на 17.10.2026 (лист «Данные»). Цены предложения (объявления) в этой модели как цены сделок не используются.
A10: Пересчёт: меняйте только синие ячейки на листах «Данные» и «Допущения». Остальное считается формулами.

Sheet Данные
A1: Данные: только опубликованные цифры и факты проекта. Оценки здесь не хранятся.
A3: ID | B3: Показатель | C3: Значение | D3: Ед. | E3: Источник (ссылка) | F3: Дата публикации | G3: Год / период данных | H3: Тег | I3: Примечание
A4: D1 | B4: Договоры купли-продажи жилья по стране, 2025 | C4: 319500 | D4: шт. | E4: ЦБ РУз «Анализ рынка недвижимости» в пересказе Spot: https://www.spot.uz/ru/2026/04/08/real-estate-review/ | F4: 08.04.2026 | G4: 2025 г. | H4: [факт] | I4: Жильё в целом (первичка + вторичка, вероятно и дома). Разбивки по квартирам и по Ташкенту нет.
A5: D2 | B5: …из них IV квартал 2025 | C5: 89700 | D5: шт. | E5: там же | F5: 08.04.2026 | G5: IV кв. 2025 | H5: [факт]
A6: D3 | B6: Сделки купли-продажи по стране, январь–июнь 2026 | C6: 171000 | D6: шт. | E6: ЦЭИР (через review.uz) в пересказе Anhor: https://anhor.uz/news/rynok-nedvizhimosti-uzbekistana-sdelki-2026/ | F6: 03.08.2026 | G6: янв–июнь 2026 | H6: [факт] | I6: «Более 171 тыс.», +25,3% к тому же периоду 2025.
A7: D4 | B7: Сделки по Ташкенту, июнь 2026 | C7: 7800 | D7: шт. | E7: там же | F7: 03.08.2026 | G7: июнь 2026 | H7: [факт] | I7: Около 7,8 тыс. операций; рост за полугодие по Ташкенту +34,9%.
A8: D5 | B8: Доля Ташкента в сделках по стране, июнь 2026 | C8: 0.308 | D8: доля | E8: там же | F8: 03.08.2026 | G8: июнь 2026 | H8: [факт] | I8: Один месяц; сезонность неизвестна.
A9: D6 | B9: Доля ипотечного жилья в сделках, 2025 | C9: 0.22 | D9: доля | E9: ЦБ РУз через Spot, 08.04.2026 (ссылка у D1) | F9: 08.04.2026 | G9: 2025 г. | H9: [факт] | I9: В 2024 г. 21,3%.
A10: D7 | B10: Выдано ипотеки по стране, 2025 | C10: 21.2 | D10: трлн сум | E10: там же | F10: 08.04.2026 | G10: 2025 г. | H10: [факт] | I10: +29% к 2024.
A11: D8 | B11: Заёмщиков по ипотеке по стране, янв–июнь 2026 | C11: 42575 | D11: чел. | E11: ЦБ через Spot: https://www.spot.uz/ru/2026/07/26/mortgage/ | F11: 26.07.2026 | G11: янв–июнь 2026 | H11: [факт]
A12: D9 | B12: Объём ипотеки по стране, янв–июнь 2026 | C12: 13.1 | D12: трлн сум | E12: там же | F12: 26.07.2026 | G12: янв–июнь 2026 | H12: [факт] | I12: +38% к прошлому году.
A13: D10 | B13: Объём ипотеки по Ташкенту, янв–июнь 2026 | C13: 4.01 | D13: трлн сум | E13: там же | F13: 26.07.2026 | G13: янв–июнь 2026 | H13: [факт] | I13: Только объём; числа заёмщиков по Ташкенту нет.
A14: D11 | B14: Ипотека на вторичном рынке: заёмщиков, янв–июнь 2026 | C14: 10580 | D14: чел. | E14: там же | F14: 26.07.2026 | G14: янв–июнь 2026 | H14: [факт] | I14: 3,3 трлн сум, 25% объёма.
A15: D12 | B15: Ипотека на первичном рынке: заёмщиков, янв–июнь 2026 | C15: 31995 | D15: чел. | E15: там же | F15: 26.07.2026 | G15: янв–июнь 2026 | H15: [факт] | I15: 9,8 трлн сум, 75% объёма.
A16: D13 | B16: Ипотечных кредитов по стране, янв–май 2026 (Минэкономфин) | C16: 21553 | D16: шт. | E16: Kun.uz: https://kun.uz/en/news/2026/07/06/tashkent-real-estate-market-shows-modest-price-growth-in-june-523ae3 | F16: 06.07.2026 | G16: янв–май 2026 | H16: [факт] | I16: НЕ СХОДИТСЯ с D8 (42,6 тыс. за 6 мес.): разные определения? См. лист «Проверки».
A17: D14 | B17: Квартиры в многоквартирных домах, г. Ташкент, на 01.01.2025 | C17: 562700 | D17: шт. | E17: Нацкомстат: https://stat.uz/en/press-center/news-of-committee/61670-ko-p-kvartirali-uylarda-joylashgan-xonadonlar-soni-4-7-ga-oshgan-3 | F17: 15.05.2025 | G17: на 01.01.2025 | H17: [факт] | I17: 35,4% по стране (1,6 млн).
A18: D15 | B18: Квартир Ташкента охвачено массовой оценкой | C18: 600000 | D18: шт. | E18: Spot: https://www.spot.uz/ru/2026/08/14/property-valuation/ ; https://www.spot.uz/ru/2026/09/09/real-estate/ | F18: 14.08.2026 / 09.09.2026 | G18: данные на 01.07.2026 | H18: [факт] | I18: «Более 600 тыс.»; частных домов более 213 тыс.
A19: D16 | B19: Кадастровая стоимость этих квартир | C19: 57.7 | D19: трлн сум | E19: там же | F19: 14.08.2026 | G19: на 2026 | H19: [факт]
A20: D17 | B20: Стоимость по массовой оценке | C20: 426.7 | D20: трлн сум | E20: там же | F20: 14.08.2026 | G20: на 01.07.2026 | H20: [факт] | I20: Власти: может быть на 20–30% ниже рынка (Anhor: https://anhor.uz/ru/news/nedvizhimost-tashkent-vyshe-kadastrova).
A21: D18 | B21: Нотариальных сделок в базе массовой оценки | C21: 85000 | D21: шт. | E21: Spot 09.09.2026 (ссылка у D15) | F21: 09.09.2026 | G21: период не указан | H21: [факт] | I21: Период выборки неизвестен — нельзя сопоставлять с годовым числом сделок.
A22: D19 | B22: Собственников, выразивших позицию к 07.09.2026 | C22: 5000 | D22: чел. | E22: Gazeta.uz: https://www.gazeta.uz/ru/2026/09/08/appraisal-tashkent/ | F22: 08.09.2026 | G22: по 07.09.2026 | H22: [факт] | I22: Около 5 тыс. — ранняя, самоотобранная выборка. Общее число уведомлённых не опубликовано.
A23: D20 | B23: …из них не согласились | C23: 0.22 | D23: доля | E23: там же | F23: 08.09.2026 | G23: по 07.09.2026 | H23: [факт] | I23: 78% согласились; большинство несогласных просят ПОВЫСИТЬ стоимость.
A24: D21 | B24: Срок обсуждения для собственников | C24: 60 | D24: дней | E24: Spot 09.09.2026 (ссылка у D15) | F24: 09.09.2026 | G24: с 05.09.2026 | H24: [факт] | I24: Возможное продление на 30 дней; по проекту закона 3–6 мес. (Gazeta) — расхождение.
A25: D22 | B25: Период переоценки на охваченной территории: не реже 1 раза в | C25: 3 | D25: года | E25: Gazeta.uz (ссылка у D19) | F25: 08.09.2026 | G25: по проекту закона | H25: [факт] | I25: Закон ещё не принят.
A26: D23 | B26: Население г. Ташкента на 01.01.2026 | C26: 3178100 | D26: чел. | E26: Нацкомстат: https://stat.uz/ru/press-tsentr/novosti-goskomstata/66573-zbekiston-a-olisi-38-2- | F26: 28.01.2026 | G26: на 01.01.2026 | H26: [факт]
A27: D24 | B27: Население Узбекистана на 01.01.2026 | C27: 38236704 | D27: чел. | E27: там же | F27: 28.01.2026 | G27: на 01.01.2026 | H27: [факт]
A28: D25 | B28: Удовлетворённых исков о разводе по стране, 2025 | C28: 37544 | D28: шт. | E28: Верховный суд через Kun.uz: https://kun.uz/ru/news/2026/01/29/v-uzbekistane-vyroslo-chislo-razvodov | F28: 29.01.2026 | G28: 2025 г. | H28: [факт] | I28: Рассмотрено 70 535. Ташкента отдельно нет.
A29: D26 | B29: Средняя цена квартиры в Ташкенте, многоэтажные дома (цены предложения) | C29: 16.5 | D29: млн сум/м² | E29: Наццентр массовой оценки через Kun.uz (ссылка у D13) | F29: 03.07.2026 | G29: на 01.07.2026 | H29: [факт] | I29: ЦЕНЫ ПРЕДЛОЖЕНИЯ с торговых площадок, не сделок.
A30: D27 | B30: Курс USD, ЦБ РУз | C30: 12055.9 | D30: сум/USD | E30: https://cbu.uz/ru/arkhiv-kursov-valyut/ | F30: 16.10.2026 | G30: на 17.10.2026 | H30: [факт]
A31: D28 | B31: Цена отчёта KMT (уровень 3) | C31: 1000000 | D31: сум | E31: Документы проекта: 11_Marketing_Growth/02_Marketing_Context.md | F31: 18.10.2026 | G31: 2026 | H31: [факт проекта] | I31: Срок 2 дня; отчёт принимает любой банк — со слов владельца, письменно не подтверждено.
A32: D29 | B32: Ставка налога на имущество физлиц (жильё до 200 м²), 2026 | C32: 0.0036 | D32: доля | E32: Spot: https://www.spot.uz/ru/2026/01/07/property-tax-2026/ | F32: 07.01.2026 | G32: 2026 г. | H32: [факт] | I32: Применение результатов массовой оценки к налогу — вопрос будущего, нужен закон.
A33: D30 | B33: Организации поиска: органический трафик uybor.uz | C33: 7000 | D33: визитов/мес | E33: AhrefsTop: https://ahrefstop.com/websites/uybor.uz | F33: окт. 2026 | G33: окт. 2026 | H33: [гипотеза] | I33: Оценка стороннего сервиса, не данные сайта. Ahrefs занижает рынок с узбекским/русским поиском [проверить].
A34: D31 | B34: Органический трафик realting.uz | C34: 11000 | D34: визитов/мес | E34: AhrefsTop: https://ahrefstop.com/websites/realting.uz | F34: окт. 2026 | G34: окт. 2026 | H34: [гипотеза] | I34: Оценка стороннего сервиса.
A35: D32 | B35: Органический трафик olx.uz (все категории) | C35: 1600000 | D35: визитов/мес | E35: AhrefsTop: https://ahrefstop.com/websites/olx.uz | F35: окт. 2026 | G35: окт. 2026 | H35: [гипотеза] | I35: Почти весь — брендовые запросы («olx», «olx uz»); к недвижимости отнести нельзя.
A36: D33 | B36: Объявлений о продаже квартир в Ташкенте (после склейки дублей), UyScan | C36: 29821 | D36: шт. | E36: https://www.uyscan.uz (наблюдение 18.10.2026), профиль в 12_Business/competitors/uyscan-uz.md | F36: 18.10.2026 | G36: на 18.10.2026 | H36: [факт] | I36: 52 803 сырых объявлений. Предложение, не сделки.
A37: D34 | B37: Доля многоквартирных домов среди домохозяйств г. Ташкента | C37: 0.634 | D37: доля | E37: Нацкомстат: https://stat.uz/ru/press-tsentr/novosti-goskomstata/41549-toshkent-shahrida-63-4-uy-xo-jaliklari-ko-p-kvartirali-uylarda-yashaydi-2 | F37: 12.07.2023 | G37: янв–июнь 2023 | H37: [факт] | I37: Данные 2023 г. устарели.
A38: D35 | B38: Ориентир проекта: доля контактов от расчётов ур. 1 | C38: 0.2 | D38: доля | E38: Документ 05_4P.md (15–25%) | F38: 15.10.2026 | G38: — | H38: [гипотеза] | I38: Взят проектом из общих ориентиров, не измерен.
A39: D36 | B39: Ориентир проекта: доля заказов ур. 3 от контактов | C39: 0.035 | D39: доля | E39: Документ 05_4P.md (2–5%) | F39: 15.10.2026 | G39: — | H39: [гипотеза] | I39: Середина диапазона; не измерен.
A40: D37 | B40: Пользователей Telegram в Узбекистане | C40: 25000000 | D40: чел. | E40: Kursiv через 01_PEST.md: https://uz.kursiv.media/2026-07-07/v-kakih-soczsetyah-zalipayut-uzbekistanczy-analiz-digital-rynka/ | F40: 07.07.2026 | G40: 2026 | H40: [факт проекта] | I40: Не перепроверено в этом исследовании.

Sheet Допущения
A1: Допущения: все значения здесь — параметры вывода, а не данные. Любое можно и нужно заменить данными (см. лист «ЗапросДанных»).
A3: ID | B3: Параметр | C3: Осторожный | D3: Базовый | E3: Оптимистичный | F3: Ед. | G3: Тег | H3: Обоснование и как проверить
A4: sh_T | B4: Доля Ташкента в договорах купли-продажи жилья | C4: 0.25 | D4: =Данные!$C$8 -> 0.308 | E4: =Данные!$C$8 -> 0.308 | F4: доля | G4: [гипотеза] | H4: Факт — только июнь 2026 (30,8%). В осторожном сценарии 25% на случай сезонной аномалии. Проверить: помесячные данные ЦЭИР/Кадастра за 12 мес.
A5: sh_apt | B5: Доля квартир в договорах по Ташкенту | C5: 0.7 | D5: 0.8 | E5: 0.9 | F5: доля | G5: [гипотеза] | H5: Данных нет: в статистике «жильё». 63,4% домохозяйств Ташкента в многоквартирных домах (2023), сделки смещены к квартирам. Проверить: запрос в Агентство кадастра по типу объекта.
A6: m_up | B6: Рост 2026 г. к полугодовому темпу (поправка на II полугодие) | C6: 0 | D6: 0 | E6: 0.1 | F6: доля | G6: [гипотеза] | H6: Используется только в оптимистичном сценарии для годовой ипотеки. Сезонность ипотеки неизвестна.
A7: m_shT | B7: Доля Ташкента в числе ипотечных кредитов (по числу) | C7: 0.22 | D7: 0.26 | E7: =Данные!$C$13/Данные!$C$12 -> 0.30610687 | F7: доля | G7: [гипотеза] | H7: Известна доля по ОБЪЁМУ (30,6%); по числу, вероятно, ниже, т.к. кредиты в Ташкенте крупнее. Проверить: ЦБ/банки — число кредитов по Ташкенту.
A8: m_sec | B8: Доля вторичного рынка в ипотеке Ташкента (по числу) | C8: 0.25 | D8: 0.3 | E8: 0.4 | F8: доля | G8: [гипотеза] | H8: По стране 24,9% по числу (10 580 из 42 575). Для Ташкента, вероятно, выше. Проверить: данные банков.
A9: m_nm | B9: Кредиты под залог квартиры вне ипотеки, к числу ипотечных | C9: 0 | D9: 0.2 | E9: 0.4 | F9: доля | G9: [гипотеза] | H9: Открытых данных нет (потребкредиты и бизнес-кредиты под залог жилья). Проверить: опрос 3–5 банков.
A10: ch_sec | B10: Доля вторичной ипотеки и залоговых кредитов, где заёмщик может выбрать независимого оценщика (напр. KMT) | C10: 0.15 | D10: 0.3 | E10: 0.5 | F10: доля | G10: [гипотеза] | H10: Владелец: отчёт KMT принимает любой банк (письменно не подтверждено). Банки могут держать список оценщиков. Проверить: интервью с 3–5 банками и ипотечными брокерами.
A11: ch_prim | B11: То же для первичного рынка (новостройки) | C11: 0.02 | D11: 0.05 | E11: 0.1 | F11: доля | G11: [гипотеза] | H11: Оценка обычно идёт через банк/застройщика. Проверить: интервью.
A12: cdr | B12: Смертность, на 1000 жителей | C12: 4.5 | D12: 5 | E12: 5.5 | F12: ‰ | G12: [гипотеза] | H12: Показатель по Ташкенту в этом исследовании не найден. Проверить: Нацкомстат, число умерших по г. Ташкенту за 2025.
A13: dead_own | B13: Доля умерших, оставивших квартиру в Ташкенте | C13: 0.25 | D13: 0.35 | E13: 0.45 | F13: доля | G13: [гипотеза] | H13: Нет данных. Проверить: нотариат (число наследственных дел с квартирой).
A14: inh_ord | B14: Доля наследств с квартирой, где заказана независимая оценка | C14: 0.1 | D14: 0.2 | E14: 0.3 | F14: доля | G14: [гипотеза] | H14: Нет данных. Нотариус может принять оценку и по другим правилам. Проверить: опрос 2–3 нотариусов.
A15: court_sh | B15: Доля удовлетворённых разводов, где нужна оценка квартиры | C15: 0.03 | D15: 0.06 | E15: 0.1 | F15: доля | G15: [гипотеза] | H15: Нет данных. Проверить: статистика судов по спорам о разделе имущества.
A16: court_oth | B16: Надбавка на прочие споры (наследство, долги, раздел) к разводам | C16: 0.5 | D16: 1 | E16: 1.5 | F16: × | G16: [гипотеза] | H16: Нет данных. Владелец: суды у KMT — редкий сегмент.
A17: tax_dis | B17: Доля собственников, несогласных с массовой оценкой | C17: 0.1 | D17: =Данные!$C$23 -> 0.22 | E17: =Данные!$C$23 -> 0.22 | F17: доля | G17: [гипотеза] | H17: Факт 22% — ранняя выборка ~5 тыс. самоотобранных. Осторожно: 10%.
A18: tax_ord | B18: Доля несогласных, заказавших платную независимую оценку | C18: 0.002 | D18: 0.01 | E18: 0.03 | F18: доля | G18: [гипотеза] | H18: Нет данных. Большинство несогласных, по Gazeta, просят повысить цену — им не обязательно платить. Проверить: число обращений в KMT за 6 недель (Q1 ЗапросДанных).
A19: tax_leg | B19: Правовая применимость независимой оценки для оспаривания (закон не принят) | C19: 0.5 | D19: 1 | E19: 1 | F19: доля | G19: [гипотеза] | H19: По проекту закона независимая оценка возможна после решения комиссии. Проверить: юрист (Р. Навруз-зода).
A20: tax_win | B20: Доля волны платных оценок, попадающая в окно этапа 1 | C20: 0.1 | D20: 0.25 | E20: 0.5 | F20: доля | G20: [гипотеза] | H20: Обсуждение с 05.09, 60 (+30) дней; старт каналов с ПДн ~18.11 (A4). Значительная часть волны пройдёт до нашего старта.
A21: price3 | B21: Средняя цена официальной оценки квартиры на рынке | C21: 500000 | D21: 800000 | E21: =Данные!$C$31 -> 1000000 | F21: сум | G21: [гипотеза] | H21: Цена KMT 1 млн — факт; рыночная цена банковских оценок неизвестна. Проверить: прайсы 5 оценочных компаний.
A22: nonclose | B22: Прохожие: ищущие цену, но не закрывшие сделку, на 1 закрытую сделку | C22: 1 | D22: 2 | E22: 3 | F22: × | G22: [гипотеза] | H22: Нет данных. Для оценки ёмкости верхней воронки (ур. 1–2).
A23: adopt | B23: Доля участников решения о цене, пользующихся онлайн-оценкой (любой) | C23: 0.1 | D23: 0.2 | E23: 0.3 | F23: доля | G23: [гипотеза] | H23: Нет данных об узбекском рынке. Проверить: опрос 100+ респондентов; данные UyScan/STAI о числе расчётов.
A24: our_sh | B24: Доля HomePrice в онлайн-расчётах Ташкента на этапе 1 | C24: 0.01 | D24: 0.03 | E24: 0.08 | F24: доля | G24: [гипотеза] | H24: Новый игрок, без бюджета; конкуренты — STAI, UyScan, портальные виджеты.
A25: pay2 | B25: Доля платящих за уровень 2 после теста | C25: 0.02 | D25: 0.05 | E25: 0.1 | F25: доля | G25: [гипотеза] | H25: Нет данных. Проверить: тест цены Gabor-Granger.
A26: price2 | B26: Цена уровня 2 | C26: 50000 | D26: 100000 | E26: 150000 | F26: сум | G26: [гипотеза] | H26: Диапазон 50–150 тыс. из 05_4P.md — гипотеза проекта.
A27: reach | B27: Доля событий SAM, доходящих до заказа KMT через HomePrice на этапе 1 (сверху вниз) | C27: 0.003 | D27: 0.01 | E27: 0.03 | F27: доля | G27: [гипотеза] | H27: Нет данных. Это «доля охвата» — главный независимый параметр сравнения с методом снизу вверх.
A28: wave_reach | B28: Доля волны платных оценок налоговой темы, доходящая до KMT через HomePrice | C28: 0.005 | D28: 0.02 | E28: 0.05 | F28: доля | G28: [гипотеза] | H28: Владелец: основной входящий спрос к KMT — налоговая тема (числа не названы).
A29: months | B29: Длительность этапа 1 в расчёте | C29: 3 | D29: 3 | E29: 3 | F29: мес. | G29: [гипотеза] | H29: По Stage1_Plan первые каналы с ПДн включаются на ~6-й неделе; 3 месяца — рабочая рамка. Проверить с владельцем.
A30: ramp | B30: Коэффициент наращивания (средний уровень за этап / устойчивый) | C30: 0.5 | D30: 0.5 | E30: 0.5 | F30: доля | G30: [гипотеза] | H30: Линейный рост от 0 до устойчивого уровня.
A31: org | B31: Органические визиты на сайт в месяц (устойчивый уровень) | C31: 600 | D31: 1500 | E31: 4500 | F31: визитов/мес | G31: [гипотеза] | H31: Ориентиры: uybor.uz ~7 тыс., realting.uz ~11 тыс. органики (AhrefsTop, окт. 2026). Новый сайт без бюджета: 10–60% от них. Проверить: Wordstat/Search Console.
A32: tg_subs | B32: Подписчики Telegram-канала HomePrice к концу этапа | C32: 300 | D32: 1200 | E32: 4000 | F32: чел. | G32: [гипотеза] | H32: Размер аналогичных каналов не найден в открытых источниках. Проверить: tgstat/telemetr по 10 каналам недвижимости Ташкента.
A33: tg_rate | B33: Визитов на сайт в месяц на 1 подписчика | C33: 0.5 | D33: 0.8 | E33: 1 | F33: визитов | G33: [гипотеза] | H33: Недельный пост с ссылкой (задача F1). Нет данных.
... A40: calc | B40: Доля визитов, завершивших расчёт | C40: 0.06 | D40: 0.12 | E40: 0.2 | F40: доля | G40: [гипотеза] | H40: Воронка не измерена (аналитика подключена, входов нет). Проверить: первые 100 расчётов.
A41: cont | B41: Доля расчётов → обращение к KMT (клик/сообщение) | C41: 0.08 | D41: 0.15 | E41: =Данные!$C$38 -> 0.2 | F41: доля | G41: [гипотеза] | H41: Проект: 15–25% (общий ориентир). До pd.gov.uz контакты не собираем: обращение инициирует клиент, учёт — вопрос юристу.
A42: ord | B42: Доля обращений → заказ уровня 3 | C42: 0.02 | D42: =Данные!$C$39 -> 0.035 | E42: 0.05 | F42: доля | G42: [гипотеза] | H42: Проект: 2–5% (общий ориентир).
A43: p_ord | B43: Прямых заказов уровня 3 от одного партнёра в месяц | C43: 0.2 | D43: 0.5 | E43: 1 | F43: заказов | G43: [гипотеза] | H43: Нет данных. Проверить: пилот с 2–3 брокерами.

Sheet СверхуВниз
A1: Сверху вниз: события, где нужна оценка квартиры в Ташкенте, и доля, доступная KMT/HomePrice. Год = последние 12 мес. (2025–2026).
A3: Показатель | B3: Осторожный | C3: Базовый | D3: Оптимистичный | E3: Ед. | F3: Как считается / тег
A4: 1. Сделки с жильём
A5: Договоры купли-продажи жилья по стране за год | B5: =Данные!$C$4 -> 319500 | C5: =Данные!$C$4 -> 319500 | D5: =Данные!$C$4 -> 319500 | E5: шт. | F5: [факт] ЦБ, 2025 г. (D1)
A6: Доля Ташкента | B6: =Допущения!C$4 -> 0.25 | C6: =Допущения!D$4 -> 0.308 | D6: =Допущения!E$4 -> 0.308 | E6: доля | F6: [гипотеза] из июня 2026 (D5)
A7: Договоры по Ташкенту за год (жильё, первичка+вторичка) | B7: =B5*B6 -> 79875 | C7: =C5*C6 -> 98406 | D7: =D5*D6 -> 98406 | E7: шт. | F7: [гипотеза] = страна × доля
A8: Доля квартир | B8: =Допущения!C$5 -> 0.7 | C8: =Допущения!D$5 -> 0.8 | D8: =Допущения!E$5 -> 0.9 | E8: доля | F8: [гипотеза]
A9: Сделки с квартирами в Ташкенте за год | B9: =B7*B8 -> 55912.5 | C9: =C7*C8 -> 78724.8 | D9: =D7*D8 -> 88565.4 | E9: шт. | F9: [гипотеза]
A10: Оборот фонда: сделки / квартиры в МКД Ташкента | B10: =B9/Данные!$C$17 -> 0.09936467 | C10: =C9/Данные!$C$17 -> 0.13990546 | D10: =D9/Данные!$C$17 -> 0.15739364 | E10: доля | F10: [гипотеза] проверка правдоподобия (D14 на 01.01.2025); >12% — вероятен перегиб, см. «Проверки»
A11: 2. Ипотека и залог
A12: Ипотечных кредитов по стране за год | B12: =Данные!$C$4*Данные!$C$9 -> 70290 | C12: =Данные!$C$11*2 -> 85150 | D12: =Данные!$C$11*2*(1+Допущения!E$6) -> 93665 | E12: шт. | F12: [гипотеза] осторожный: 2025 = договоры×22%; базовый: январь–июнь 2026 ×2; оптимистичный: +поправка. Сверка со средним чеком — «Проверки»
A13: Доля Ташкента (по числу) | B13: =Допущения!C$7 -> 0.22 | C13: =Допущения!D$7 -> 0.26 | D13: =Допущения!E$7 -> 0.30610687 | E13: доля | F13: [гипотеза]
A14: Ипотечных кредитов в Ташкенте за год | B14: =B12*B13 -> 15463.8 | C14: =C12*C13 -> 22139 | D14: =D12*D13 -> 28671.5 | E14: шт. | F14: [гипотеза]
A15: …из них на вторичном рынке | B15: =B14*Допущения!C$8 -> 3865.95 | C15: =C14*Допущения!D$8 -> 6641.7 | D15: =D14*Допущения!E$8 -> 11468.6 | E15: шт. | F15: [гипотеза]
A16: …из них на первичном рынке | B16: =B14-B15 -> 11597.85 | C16: =C14-C15 -> 15497.3 | D16: =D14-D15 -> 17202.9 | E16: шт. | F16: [гипотеза]
A17: Залоговые кредиты под квартиры вне ипотеки | B17: =B14*Допущения!C$9 -> 0 | C17: =C14*Допущения!D$9 -> 4427.8 | D17: =D14*Допущения!E$9 -> 11468.6 | E17: шт. | F17: [гипотеза] открытых данных нет
A18: 3. Наследство
A19: Население Ташкента | B19: =Данные!$C$26 -> 3178100 | C19: =Данные!$C$26 -> 3178100 | D19: =Данные!$C$26 -> 3178100 | E19: чел. | F19: [факт] 01.01.2026 (D23)
A20: Умерших в год | B20: =B19*Допущения!C$12/1000 -> 14301.45 | C20: =C19*Допущения!D$12/1000 -> 15890.5 | D20: =D19*Допущения!E$12/1000 -> 17479.55 | E20: чел. | F20: [гипотеза] смертность по Ташкенту не найдена
A21: …оставивших квартиру в Ташкенте | B21: =B20*Допущения!C$13 -> 3575.3625 | C21: =C20*Допущения!D$13 -> 5561.675 | D21: =D20*Допущения!E$13 -> 7865.7975 | E21: шт. | F21: [гипотеза]
A22: Наследств с независимой оценкой квартиры | B22: =B21*Допущения!C$14 -> 357.53625 | C22: =C21*Допущения!D$14 -> 1112.335 | D22: =D21*Допущения!E$14 -> 2359.7393 | E22: шт. | F22: [гипотеза]
A23: 4. Суды
A24: Удовлетворённых разводов в Ташкенте (по доле населения) | B24: =Данные!$C$28*Данные!$C$26/Данные!$C$27 -> 3120.5249 | C24: =Данные!$C$28*Данные!$C$26/Данные!$C$27 -> 3120.5249 | D24: =Данные!$C$28*Данные!$C$26/Данные!$C$27 -> 3120.5249 | E24: шт. | F24: [гипотеза] страна × доля населения (D25, D23, D24)
A25: Судебных споров с оценкой квартиры (с надбавкой на прочие) | B25: =B24*Допущения!C$15*(1+Допущения!C$16) -> 140.42362 | C25: =C24*Допущения!D$15*(1+Допущения!D$16) -> 374.46299 | D25: =D24*Допущения!E$15*(1+Допущения!E$16) -> 780.13122 | E25: шт. | F25: [гипотеза]
A26: 5. Массовая оценка и налог на имущество (волна, Ташкент)
A27: Квартир в массовой оценке | B27: =Данные!$C$18 -> 600000 | C27: =Данные!$C$18 -> 600000 | D27: =Данные!$C$18 -> 600000 | E27: шт. | F27: [факт] D15
A28: Доля несогласных | B28: =Допущения!C$17 -> 0.1 | C28: =Допущения!D$17 -> 0.22 | D28: =Допущения!E$17 -> 0.22 | E28: доля | F28: [гипотеза] из 22% (D20)
A29: Доля заказавших платную оценку | B29: =Допущения!C$18 -> 0.002 | C29: =Допущения!D$18 -> 0.01 | D29: =Допущения!E$18 -> 0.03 | E29: доля | F29: [гипотеза]
A30: Правовая применимость | B30: =Допущения!C$19 -> 0.5 | C30: =Допущения!D$19 -> 1 | D30: =Допущения!E$19 -> 1 | E30: доля | F30: [гипотеза]
A31: Платных независимых оценок в волне (разово, не в год) | B31: =B27*B28*B29*B30 -> 60 | C31: =C27*C28*C29*C30 -> 1320 | D31: =D27*D28*D29*D30 -> 3960 | E31: шт. | F31: [гипотеза] разовая волна; считается отдельно от годового потока
A32: Повторяющийся поток после волны (в год) | B32: =B31/Данные!$C$25 -> 20 | C32: =C31/Данные!$C$25 -> 440 | D32: =D31/Данные!$C$25 -> 1320 | E32: шт. | F32: [гипотеза] волна / период переоценки (D22: 3 года)
A33: 6. Ёмкость рынка официальных оценок (TAM) — любой оценщик, год
A34: События, требующие оценки (ипотека + залог + наследство + суды + повторяющийся налог) | B34: =B14+B17+B22+B25+B32 -> 15981.76 | C34: =C14+C17+C22+C25+C32 -> 28493.598 | D34: =D14+D17+D22+D25+D32 -> 44599.97 | E34: шт./год | F34: [гипотеза] без первичной разовой волны
A35: Средняя цена оценки | B35: =Допущения!C$21 -> 500000 | C35: =Допущения!D$21 -> 800000 | D35: =Допущения!E$21 -> 1000000 | E35: сум | F35: [гипотеза] (KMT: 1 млн, D28)
A36: TAM, сум в год | B36: =B34*B35 -> 7.9908799e+09 | C36: =C34*C35 -> 2.2794878e+10 | D36: =D34*D35 -> 4.459997e+10 | E36: сум | F36: [гипотеза]
A37: TAM, USD в год | B37: =B36/Данные!$C$30 -> 662819.03 | C37: =C36/Данные!$C$30 -> 1890765.4 | D37: =D36/Данные!$C$30 -> 3699431 | E37: USD | F37: [гипотеза] курс D27 на 17.10.2026
A38: 7. Доступная часть (SAM): заказчик выбирает независимого оценщика
A39: Вторичная ипотека × доля выбора | B39: =B15*Допущения!C$10 -> 579.8925 | C39: =C15*Допущения!D$10 -> 1992.51 | D39: =D15*Допущения!E$10 -> 5734.3 | E39: шт. | F39: [гипотеза]
A40: Первичная ипотека × доля выбора | B40: =B16*Допущения!C$11 -> 231.957 | C40: =C16*Допущения!D$11 -> 774.865 | D40: =D16*Допущения!E$11 -> 1720.29 | E40: шт. | F40: [гипотеза]
A41: Залоговые вне ипотеки × доля выбора | B41: =B17*Допущения!C$10 -> 0 | C41: =C17*Допущения!D$10 -> 1328.34 | D41: =D17*Допущения!E$10 -> 5734.3 | E41: шт. | F41: [гипотеза]
...

Sheet СнизуВверх
A1: Снизу вверх: воронка этапа 1 от каналов привлечения (устойчивый месячный уровень к концу этапа). Источник канальных чисел — допущения; открытых данных по поисковым запросам нет.
A3: Показатель | B3: Осторожный | C3: Базовый | D3: Оптимистичный | E3: Ед. | F3: Как считается / тег
A4: 1. Каналы и визиты
A5: Органический поиск | B5: =Допущения!C$31 -> 600 | C5: =Допущения!D$31 -> 1500 | D5: =Допущения!E$31 -> 4500 | E5: визитов/мес | F5: [гипотеза] ориентир: uybor.uz ~7 тыс., realting.uz ~11 тыс. (Данные D30–D31)
A6: Подписчиков Telegram | B6: =Допущения!C$32 -> 300 | C6: =Допущения!D$32 -> 1200 | D6: =Допущения!E$32 -> 4000 | E6: чел. | F6: [гипотеза]
A7: Визиты из Telegram | B7: =B6*Допущения!C$33 -> 150 | C7: =C6*Допущения!D$33 -> 960 | D7: =D6*Допущения!E$33 -> 4000 | E7: визитов/мес | F7: [гипотеза]
A8: Партнёры: брокеры/риелторы | B8: =Допущения!C$34 -> 1 | C8: =Допущения!D$34 -> 2 | D8: =Допущения!E$34 -> 5 | E8: шт. | F8: [гипотеза]
A9: Партнёры: оценочные компании | B9: =Допущения!C$35 -> 0 | C9: =Допущения!D$35 -> 1 | D9: =Допущения!E$35 -> 3 | E9: шт. | F9: [гипотеза]
A10: Партнёры: банки | B10: =Допущения!C$36 -> 0 | C10: =Допущения!D$36 -> 0 | D10: =Допущения!E$36 -> 1 | E10: шт. | F10: [гипотеза]
A11: Партнёры: нотариусы | B11: =Допущения!C$37 -> 0 | C11: =Допущения!D$37 -> 1 | D11: =Допущения!E$37 -> 1 | E11: шт. | F11: [гипотеза]
A12: Партнёров всего | B12: =B8+B9+B10+B11 -> 1 | C12: =C8+C9+C10+C11 -> 4 | D12: =D8+D9+D10+D11 -> 10 | E12: шт. | F12: расчёт
A13: Визиты от партнёров | B13: =B12*Допущения!C$38 -> 100 | C13: =C12*Допущения!D$38 -> 800 | D13: =D12*Допущения!E$38 -> 3000 | E13: визитов/мес | F13: [гипотеза]
A14: Визитов всего (с прочим и прямым трафиком) | B14: =(B5+B7+B13)*(1+Допущения!C$39) -> 935 | C14: =(C5+C7+C13)*(1+Допущения!D$39) -> 3586 | D14: =(D5+D7+D13)*(1+Допущения!E$39) -> 12650 | E14: визитов/мес | F14: [гипотеза]
A15: 2. Воронка
A16: Доля визитов, завершивших расчёт | B16: =Допущения!C$40 -> 0.06 | C16: =Допущения!D$40 -> 0.12 | D16: =Допущения!E$40 -> 0.2 | E16: доля | F16: [гипотеза]
A17: Расчётов HomePrice в месяц (снизу вверх) | B17: =B14*B16 -> 56.1 | C17: =C14*C16 -> 430.32 | D17: =D14*D16 -> 2530 | E17: расчётов/мес | F17: [гипотеза]
A18: Доля расчётов → обращение к KMT | B18: =Допущения!C$41 -> 0.08 | C18: =Допущения!D$41 -> 0.15 | D18: =Допущения!E$41 -> 0.2 | E18: доля | F18: [гипотеза]
A19: Обращений к KMT из воронки | B19: =B17*B18 -> 4.488 | C19: =C17*C18 -> 64.548 | D19: =D17*D18 -> 506 | E19: обращений/мес | F19: [гипотеза]
A20: Доля обращений → заказ ур. 3 | B20: =Допущения!C$42 -> 0.02 | C20: =Допущения!D$42 -> 0.035 | D20: =Допущения!E$42 -> 0.05 | E20: доля | F20: [гипотеза]
A21: Заказов ур. 3 из воронки сайта | B21: =B19*B20 -> 0.08976 | C21: =C19*C20 -> 2.25918 | D21: =D19*D20 -> 25.3 | E21: заказов/мес | F21: [гипотеза]
A22: Прямых заказов от партнёров | B22: =B12*Допущения!C$43 -> 0.2 | C22: =C12*Допущения!D$43 -> 2 | D22: =D12*Допущения!E$43 -> 10 | E22: заказов/мес | F22: [гипотеза]
A23: Заказов ур. 3 в месяц (снизу вверх) | B23: =B21+B22 -> 0.28976 | C23: =C21+C22 -> 4.25918 | D23: =D21+D22 -> 35.3 | E23: заказов/мес | F23: [гипотеза]
A24: 3. Итоги этапа 1
A25: Длительность этапа | B25: =Допущения!C$29 -> 3 | C25: =Допущения!D$29 -> 3 | D25: =Допущения!E$29 -> 3 | E25: мес. | F25: [гипотеза]
A26: Заказов ур. 3 за этап (с наращиванием) | B26: =B23*B25*Допущения!C$30 -> 0.43464 | C26: =C23*C25*Допущения!D$30 -> 6.38877 | D26: =D23*D25*Допущения!E$30 -> 52.95 | E26: заказов | F26: [гипотеза]
A27: Расчётов за этап (с наращиванием) | B27: =B17*B25*Допущения!C$30 -> 84.15 | C27: =C17*C25*Допущения!D$30 -> 645.48 | D27: =D17*D25*Допущения!E$30 -> 3795 | E27: расчётов | F27: [гипотеза]
A28: Выручка ур. 3 брутто за этап, сум (по цене KMT) | B28: =B26*Данные!$C$31 -> 434640 | C28: =C26*Данные!$C$31 -> 6388770 | D28: =D26*Данные!$C$31 -> 52950000 | E28: сум | F28: [гипотеза] без маржи (маржа KMT неизвестна, L7)
A29: …в USD | B29: =B28/Данные!$C$30 -> 36.052057 | C29: =C28/Данные!$C$30 -> 529.92891 | D29: =D28/Данные!$C$30 -> 4392.0404 | E29: USD | F29: [гипотеза]

Sheet Сценарии
A1: Три сценария этапа 1. Метод основной — снизу вверх; сверху вниз — проверка. Все значения — [гипотеза].
A3: Показатель этапа 1 (устойчивый месячный уровень) | B3: Осторожный | C3: Базовый | D3: Оптимистичный | E3: Ед. | F3: Примечание
A4: Расчётов в месяц (снизу вверх) | B4: =СнизуВверх!B17 -> 56.1 | C4: =СнизуВверх!C17 -> 430.32 | D4: =СнизуВверх!D17 -> 2530 | E4: расчётов/мес | F4: Основная оценка
A5: Расчётов в месяц (сверху вниз) | B5: =СверхуВниз!B52 -> 18.6375 | C5: =СверхуВниз!C52 -> 236.1744 | D5: =СверхуВниз!D52 -> 1417.0464 | E5: расчётов/мес | F5: Проверка по ёмкости рынка
A6: Заказов ур. 3 в месяц (снизу вверх) | B6: =СнизуВверх!B23 -> 0.28976 | C6: =СнизуВверх!C23 -> 4.25918 | D6: =СнизуВверх!D23 -> 35.3 | E6: заказов/мес | F6: Основная оценка, без налоговой волны
A7: Заказов ур. 3 в месяц (сверху вниз) | B7: =СверхуВниз!B57 -> 0.33245234 | C7: =СверхуВниз!C57 -> 5.0187608 | D7: =СверхуВниз!D57 -> 44.121901 | E7: заказов/мес | F7: Проверка
A8: Налоговая волна: заказов в месяц (оверлей) | B8: =СверхуВниз!B60 -> 0.01 | C8: =СверхуВниз!C60 -> 2.2 | D8: =СверхуВниз!D60 -> 33 | E8: заказов/мес | F8: Разовая; зависит от срока закона и старта каналов
A9: Заказов ур. 3 в месяц с волной (снизу вверх + оверлей) | B9: =B6+B8 -> 0.29976 | C9: =C6+C8 -> 6.45918 | D9: =D6+D8 -> 68.3 | E9: заказов/мес | F9: Верхняя граница месяца пика
A10: Заказов ур. 3 за этап (снизу вверх, с наращиванием) | B10: =СнизуВверх!B26 -> 0.43464 | C10: =СнизуВверх!C26 -> 6.38877 | D10: =СнизуВверх!D26 -> 52.95 | E10: заказов
A11: Партнёров к концу этапа | B11: =СнизуВверх!B12 -> 1 | C11: =СнизуВверх!C12 -> 4 | D11: =СнизуВверх!D12 -> 10 | E11: шт. | F11: Порог для агрегатора по SWOT: 10 партнёров
A12: Выручка ур. 3 брутто за этап, USD | B12: =СнизуВверх!B29 -> 36.052057 | C12: =СнизуВверх!C29 -> 529.92891 | D12: =СнизуВверх!D29 -> 4392.0404 | E12: USD | F12: Цена KMT 1 млн сум; маржа не учтена
A13: SAM, событий в год | B13: =СверхуВниз!B42 -> 1329.8094 | C13: =СверхуВниз!C42 -> 6022.513 | D13: =СверхуВниз!D42 -> 17648.76 | E13: шт./год | F13: Доступный рынок
A14: TAM, USD в год | B14: =СверхуВниз!B37 -> 662819.03 | C14: =СверхуВниз!C37 -> 1890765.4 | D14: =СверхуВниз!D37 -> 3699431 | E14: USD | F14: Потолок рынка официальных оценок квартир Ташкента
A15: SAM, USD в год | B15: =СверхуВниз!B44 -> 55151.808 | C15: =СверхуВниз!C44 -> 399639.21 | D15: =СверхуВниз!D44 -> 1463910.7 | E15: USD
A16: Доля SAM, берущаяся заказами за год (снизу вверх) | B16: =B6*12/B13 -> 0.0026147507 | C16: =C6*12/C13 -> 0.0084865172 | D16: =D6*12/D13 -> 0.024001686 | E16: доля | F16: Проверка правдоподобия: значения >10% нереалистичны для нового канала

Sheet Сравнение
A1: Правило проекта: если методы расходятся больше чем вдвое — не усреднять, искать причину («оценка не сошлась»).
A3: Сравнение двух методов | B3: Осторожный | C3: Базовый | D3: Оптимистичный | E3: Ед. | F3: Вывод
A4: Расчёты/мес: снизу вверх ÷ сверху вниз | B4: =Сценарии!B4/Сценарии!B5 -> 3.0100604 | C4: =Сценарии!C4/Сценарии!C5 -> 1.8220434 | D4: =Сценарии!D4/Сценарии!D5 -> 1.7854038 | E4: × | F4: Если ×>2 — воронка снизу вверх оптимистичнее ёмкости рынка (или доля HomePrice занижена).
A5: Расчёты: статус | B5: =IF(OR(B4>2,B4<0.5),"не сошлось","сошлось (в 2 раза)") -> не сошлось | C5: =IF(OR(C4>2,C4<0.5),"не сошлось","сошлось (в 2 раза)") -> сошлось (в 2 раза) | D5: =IF(OR(D4>2,D4<0.5),"не сошлось","сошлось (в 2 раза)") -> сошлось (в 2 раза)
A6: Заказы/мес: снизу вверх ÷ сверху вниз | B6: =Сценарии!B6/Сценарии!B7 -> 0.87158357 | C6: =Сценарии!C6/Сценарии!C7 -> 0.84865172 | D6: =Сценарии!D6/Сценарии!D7 -> 0.80005619 | E6: × | F6: Параметры охвата (reach) и воронки задавались независимо; близость — согласованность допущений, а не подтверждение.
A7: Заказы: статус | B7: =IF(OR(B6>2,B6<0.5),"не сошлось","сошлось (в 2 раза)") -> сошлось (в 2 раза) | C7: =IF(OR(C6>2,C6<0.5),"не сошлось","сошлось (в 2 раза)") -> сошлось (в 2 раза) | D7: =IF(OR(D6>2,D6<0.5),"не сошлось","сошлось (в 2 раза)") -> сошлось (в 2 раза)
A8: Визиты/мес снизу вверх ÷ органика uybor.uz (ориентир) | B8: =СнизуВверх!B14/Данные!$C$33 -> 0.13357143 | C8: =СнизуВверх!C14/Данные!$C$33 -> 0.51228571 | D8: =СнизуВверх!D14/Данные!$C$33 -> 1.8071429 | E8: × | F8: Новый сайт без бюджета не должен превышать установленный портал; ×>1 — тревожный знак.

Sheet Чувствительность
A1: Чувствительность заказов ур. 3 (снизу вверх, базовый сценарий) к изменению параметра на ±20%, остальное без изменений.
A3: Параметр (базовый сценарий) | B3: ×0,8: заказов/мес | C3: ×1,2: заказов/мес | D3: Δ вниз | E3: Δ вверх | F3: Размах
A4: Органические визиты | B4: =((СнизуВверх!$C$5*0.8)+(СнизуВверх!$C$6*1*Допущения!D$33)+(СнизуВверх!$C$12*1*Допущения!D$38))*(1+Допущения!D$39)*СнизуВверх!$C$16*1*СнизуВверх!$C$18*1*СнизуВверх!$C$20*1+СнизуВверх!$C$12*1*Допущения!D$43*1 -> 4.05128 | C4: =((СнизуВверх!$C$5*1.2)+(СнизуВверх!$C$6*1*Допущения!D$33)+(СнизуВверх!$C$12*1*Допущения!D$38))*(1+Допущения!D$39)*СнизуВверх!$C$16*1*СнизуВверх!$C$18*1*СнизуВверх!$C$20*1+СнизуВверх!$C$12*1*Допущения!D$43*1 -> 4.46708 | D4: =B4-СнизуВверх!$C$23 -> -0.2079 | E4: =C4-СнизуВверх!$C$23 -> 0.2079 | F4: =C4-B4 -> 0.4158
A5: Подписчики Telegram | B5: =((СнизуВверх!$C$5*1)+(СнизуВверх!$C$6*0.8*Допущения!D$33)+(СнизуВверх!$C$12*1*Допущения!D$38))*(1+Допущения!D$39)*СнизуВверх!$C$16*1*СнизуВверх!$C$18*1*СнизуВверх!$C$20*1+СнизуВверх!$C$12*1*Допущения!D$43*1 -> 4.126124 | C5: =((СнизуВверх!$C$5*1)+(СнизуВверх!$C$6*1.2*Допущения!D$33)+(СнизуВверх!$C$12*1*Допущения!D$38))*(1+Допущения!D$39)*СнизуВверх!$C$16*1*СнизуВверх!$C$18*1*СнизуВверх!$C$20*1+СнизуВверх!$C$12*1*Допущения!D$43*1 -> 4.392236 | D5: =B5-СнизуВверх!$C$23 -> -0.133056 | E5: =C5-СнизуВверх!$C$23 -> 0.133056 | F5: =C5-B5 -> 0.266112
A6: Число партнёров | B6: =((СнизуВверх!$C$5*1)+(СнизуВверх!$C$6*1*Допущения!D$33)+(СнизуВверх!$C$12*0.8*Допущения!D$38))*(1+Допущения!D$39)*СнизуВверх!$C$16*1*СнизуВверх!$C$18*1*СнизуВверх!$C$20*1+СнизуВверх!$C$12*0.8*Допущения!D$43*1 -> 3.7483 | C6: =((СнизуВверх!$C$5*1)+(СнизуВверх!$C$6*1*Допущения!D$33)+(СнизуВверх!$C$12*1.2*Допущения!D$38))*(1+Допущения!D$39)*СнизуВверх!$C$16*1*СнизуВверх!$C$18*1*СнизуВверх!$C$20*1+СнизуВверх!$C$12*1.2*Допущения!D$43*1 -> 4.77006 | D6: =B6-СнизуВверх!$C$23 -> -0.51088 | E6: =C6-СнизуВверх!$C$23 -> 0.51088 | F6: =C6-B6 -> 1.02176
A7: Доля визитов, завершивших расчёт | B7: =((СнизуВверх!$C$5*1)+(СнизуВверх!$C$6*1*Допущения!D$33)+(СнизуВверх!$C$12*1*Допущения!D$38))*(1+Допущения!D$39)*СнизуВверх!$C$16*0.8*СнизуВверх!$C$18*1*СнизуВверх!$C$20*1+СнизуВверх!$C$12*1*Допущения!D$43*1 -> 3.807344 | C7: =((СнизуВверх!$C$5*1)+(СнизуВверх!$C$6*1*Допущения!D$33)+(СнизуВверх!$C$12*1*Допущения!D$38))*(1+Допущения!D$39)*СнизуВверх!$C$16*1.2*СнизуВверх!$C$18*1*СнизуВверх!$C$20*1+СнизуВверх!$C$12*1*Допущения!D$43*1 -> 4.711016 | D7: =B7-СнизуВверх!$C$23 -> -0.451836 | E7: =C7-СнизуВверх!$C$23 -> 0.451836 | F7: =C7-B7 -> 0.903672
A8: Доля расчётов → обращение | B8: =((СнизуВверх!$C$5*1)+(СнизуВверх!$C$6*1*Допущения!D$33)+(СнизуВверх!$C$12*1*Допущения!D$38))*(1+Допущения!D$39)*СнизуВверх!$C$16*1*СнизуВверх!$C$18*0.8*СнизуВверх!$C$20*1+СнизуВверх!$C$12*1*Допущения!D$43*1 -> 3.807344 | C8: =((СнизуВверх!$C$5*1)+(СнизуВверх!$C$6*1*Допущения!D$33)+(СнизуВверх!$C$12*1*Допущения!D$38))*(1+Допущения!D$39)*СнизуВверх!$C$16*1*СнизуВверх!$C$18*1.2*СнизуВверх!$C$20*1+СнизуВверх!$C$12*1*Допущения!D$43*1 -> 4.711016 | D8: =B8-СнизуВверх!$C$23 -> -0.451836 | E8: =C8-СнизуВверх!$C$23 -> 0.451836 | F8: =C8-B8 -> 0.903672
A9: Доля обращений → заказ | B9: =((СнизуВверх!$C$5*1)+(СнизуВверх!$C$6*1*Допущения!D$33)+(СнизуВверх!$C$12*1*Допущения!D$38))*(1+Допущения!D$39)*СнизуВверх!$C$16*1*СнизуВверх!$C$18*1*СнизуВверх!$C$20*0.8+СнизуВверх!$C$12*1*Допущения!D$43*1 -> 3.807344 | C9: =((СнизуВверх!$C$5*1)+(СнизуВверх!$C$6*1*Допущения!D$33)+(СнизуВверх!$C$12*1*Допущения!D$38))*(1+Допущения!D$39)*СнизуВверх!$C$16*1*СнизуВверх!$C$18*1*СнизуВверх!$C$20*1.2+СнизуВверх!$C$12*1*Допущения!D$43*1 -> 4.711016 | D9: =B9-СнизуВверх!$C$23 -> -0.451836 | E9: =C9-СнизуВверх!$C$23 -> 0.451836 | F9: =C9-B9 -> 0.903672
A10: Заказов от партнёра в месяц | B10: =((СнизуВверх!$C$5*1)+(СнизуВверх!$C$6*1*Допущения!D$33)+(СнизуВверх!$C$12*1*Допущения!D$38))*(1+Допущения!D$39)*СнизуВверх!$C$16*1*СнизуВверх!$C$18*1*СнизуВверх!$C$20*1+СнизуВверх!$C$12*1*Допущения!D$43*0.8 -> 3.85918 | C10: =((СнизуВверх!$C$5*1)+(СнизуВверх!$C$6*1*Допущения!D$33)+(СнизуВверх!$C$12*1*Допущения!D$38))*(1+Допущения!D$39)*СнизуВверх!$C$16*1*СнизуВверх!$C$18*1*СнизуВверх!$C$20*1+СнизуВверх!$C$12*1*Допущения!D$43*1.2 -> 4.65918 | D10: =B10-СнизуВверх!$C$23 -> -0.4 | E10: =C10-СнизуВверх!$C$23 -> 0.4 | F10: =C10-B10 -> 0.8
A12: Базовый заказов/мес (контроль, должен совпасть с листом «СнизуВверх») | B12: =((СнизуВверх!$C$5*1)+(СнизуВверх!$C$6*1*Допущения!D$33)+(СнизуВверх!$C$12*1*Допущения!D$38))*(1+Допущения!D$39)*СнизуВверх!$C$16*1*СнизуВверх!$C$18*1*СнизуВверх!$C$20*1+СнизуВверх!$C$12*1*Допущения!D$43*1 -> 4.25918 | C12: =СнизуВверх!$C$23 -> 4.25918 | D12: =IF(ABS(B12-C12)<0.000001,"совпадает","РАСХОЖДЕНИЕ") -> совпадает
A14: Вывод: заказы пропорциональны произведению трёх долей воронки (расчёт × обращение × заказ); ни одна из них не измерена — именно их надо замерить первыми.

Sheet Конкуренты
A1: Масштаб аудитории конкурентов по открытым оценкам. Прямых данных о посещаемости STAI и UyScan, поисковых запросах и Telegram-каналах в открытом доступе не найдено.
A3: Игрок | B3: Показатель | C3: Значение | D3: Источник | E3: Дата / период | F3: Тег | G3: Комментарий
A4: OLX.uz | B4: Органический поисковый трафик (все категории) | C4: =Данные!$C$35 -> 1600000 | D4: AhrefsTop, оценка | E4: окт. 2026 | F4: [гипотеза] | G4: Брендовые запросы: «olx» 147 тыс./мес, «olx uz» 109 тыс./мес (объём запросов, там же).
A5: OLX.uz | B5: Semrush: «Traffic» 6,51 млн (период не указан) | C5: 6510000 | D5: https://www.semrush.com/website/olx.uz/overview/ | E5: сент. 2026 | F5: [проверить] | G5: Страница без детализации; период и тип трафика не указаны — не использовать в расчёте.
A6: Uybor.uz | B6: Органический поисковый трафик | C6: =Данные!$C$33 -> 7000 | D6: AhrefsTop, оценка | E6: окт. 2026 | F6: [гипотеза] | G6: Топ-запросы — брендовые («uy», «уй бор»). Оценка занижает прямой и мобильный трафик.
A7: Realting.uz | B7: Органический поисковый трафик | C7: =Данные!$C$34 -> 11000 | D7: AhrefsTop, оценка | E7: окт. 2026 | F7: [гипотеза] | G7: Площадка международная; Узбекистан 95,5%.
A8: UyScan | B8: Объявлений Ташкента после склейки дублей | C8: =Данные!$C$36 -> 29821 | D8: uyscan.uz, наблюдение | E8: 18.10.2026 | F8: [факт] | G8: Посещаемость, подписчики @UyScanBot и канала не опубликованы.
A9: STAI.UZ | B9: Объектов в базе | C9: 289627 | D9: Профиль 12_Business/competitors/stai-uz.md | E9: 18.10.2026 | F9: [факт проекта] | G9: Посещаемость и число отчётов не найдены.
A10: Telegram | B10: Пользователей в Узбекистане | C10: =Данные!$C$40 -> 25000000 | D10: Kursiv через 01_PEST.md | E10: 07.07.2026 | F10: [факт проекта] | G10: Размеры тематических каналов недвижимости Ташкента в открытом поиске не найдены (tgstat/telemetr не отдали данных).
A12: Вывод | B12: Даже у установленных порталов органический поиск по оценкам Ahrefs — единицы–десятки тысяч визитов в месяц; брендовый поиск доминирует. Это верхний ориентир для нового сайта без бюджета.

Sheet ЗапросДанных
A1: Запрос данных у владельца и KMT, а также внешние источники (Темур / KMT / Азизбек / юрист)
A3: № | B3: Что нужно | C3: У кого | D3: Как получить | E3: Какой параметр заменяет | F3: Приоритет
A4: 1 | B4: Число обращений в KMT по месяцам за последние 12 мес., с разбивкой по цели: ипотека / налог (массовая оценка) / наследство / суд / продажа / прочее | C4: KMT (Темур) | D4: Выгрузка из CRM или журнала заявок; если CRM нет — ручной подсчёт по почте/мессенджерам | E4: reach, tax_ord, ch_sec, inh_ord, court_sh | F4: P0
A5: 2 | B5: Число заказов отчётов KMT по квартирам Ташкента за 12 мес. и средний чек, срок, маржа (задача L7) | C5: KMT | D5: Бухучёт/реестр отчётов | E5: price3, ord, оценка доли SAM | F5: P0
A6: 3 | B6: Источники лидов KMT: откуда приходят обращения (поиск, знакомые, банки, брокеры, Telegram, реклама) | C6: KMT | D6: Вопрос при каждом обращении 4 недели; поле «источник» | E6: org, tg_subs, pv, p_ord | F6: P0
A7: 4 | B7: Доля налоговой темы среди обращений за последние 6 недель (с 05.09.2026) и число людей, готовых заказать оценку | C7: KMT | D7: Подсчёт обращений с 05.09; 5 дословных вопросов | E7: tax_dis, tax_ord, wave_reach | F7: P0
A8: 5 | B8: Поисковые запросы по теме (рус. и узб.): «оценка квартиры Ташкент», «квартира баҳолаш», «цена кв.м Ташкент», «налог на имущество квартира», «кадастровая стоимость», «наследство квартира оценка» | C8: Азизбек / Темур | D8: Яндекс Вордстат (регион Ташкент), Google Keyword Planner, Google Trends, Search Console после запуска; AhrefsTop — только оценка | E8: org, calc, adopt | F8: P0
A9: 6 | B9: Размеры 10–15 Telegram-каналов и ботов по недвижимости и ипотеке Ташкента (подписчики, охват поста, цена рекламы) | C9: Азизбек | D9: tgstat.com, telemetr.me, ручной просмотр; запрос цен рекламы у админов | E9: tg_subs, tg_rate | F9: P1
A10: 7 | B10: Число ипотечных кредитов и оценок залога по Ташкенту (по числу, вторичка/первичка), долю заёмщиков, выбирающих оценщика | C10: Банки, ипотечные брокеры (связи Темура), ЦБ | D10: 3–5 интервью; запрос в ЦБ/Минэкономфин: число кредитов по Ташкенту | E10: m_shT, m_sec, ch_sec, ch_prim | F10: P0
A11: 8 | B11: Число сделок с квартирами в Ташкенте за 12 мес. (вторичка и первичка раздельно) | C11: Агентство кадастра, ЦЭИР, нотариальная палата | D11: Официальный запрос; открытые данные ЦЭИР по месяцам | E11: sh_T, sh_apt | F11: P1
A12: 9 | B12: Число наследственных дел с квартирой и судебных споров о разделе жилья в Ташкенте | C12: Нотариальная палата, Верховный суд | D12: Запрос; интервью 2–3 нотариуса | E12: dead_own, inh_ord, court_sh, court_oth | F12: P2
A13: 10 | B13: Число оценочных организаций и оценщиков, цены банковских оценок квартир | C13: Реестр, 5 оценочных компаний | D13: Звонки-«тайный покупатель» без оплаты; реестр | E13: price3, p_ap | F13: P1
A14: 11 | B14: Сроки и юридический статус независимой оценки при оспаривании массовой оценки (закон «О массовой оценке») | C14: Юрист (Р. Навруз-зода) | D14: Заключение по тексту закона после принятия | E14: tax_leg, tax_win | F14: P0
A15: 12 | B15: Письменное подтверждение: любой банк принимает отчёт KMT | C15: KMT / банки | D15: Письма 3 банков | E15: ch_sec | F15: P0
A16: 13 | B16: Первые 100 реальных расчётов: воронка по шагам (посетитель → расчёт → клик «заказать») | C16: Азизбек (аналитика) | D16: События E2 после запуска | E16: calc, cont, ord | F16: P0

Sheet Проверки
A1: Контроль целостности и правдоподобия (формулы)
A3: Проверка | B3: Значение | C3: Порог / ожидание | D3: Статус | E3: Комментарий
A4: Средний чек ипотеки: 2025 (D7÷(D1×D6)) к I пол. 2026 (D9÷D8) | B4: =(Данные!$C$10/(Данные!$C$4*Данные!$C$9))/(Данные!$C$12/Данные!$C$11) -> 0.98022478 | C4: 0,9–1,1 | D4: =IF(AND(B4>=0.9,B4<=1.1),"OK","ВНИМАНИЕ") -> OK | E4: Сверка двух независимых способов оценки числа ипотек по стране.
A5: Доля Ташкента: по объёму ипотеки (D10÷D9) минус по сделкам (D5) | B5: =Данные!$C$13/Данные!$C$12-Данные!$C$8 -> -0.0018931298 | C5: |разница| < 0,05 | D5: =IF(ABS(B5)<0.05,"OK","ВНИМАНИЕ") -> OK | E5: Согласованность двух долей Ташкента.
A6: Квартир в массовой оценке (D15) ÷ квартир в МКД на 01.01.2025 (D14) | B6: =Данные!$C$18/Данные!$C$17 -> 1.0662875 | C6: 0,95–1,25 | D6: =IF(AND(B6>=0.95,B6<=1.25),"OK","ВНИМАНИЕ") -> OK | E6: Фонд на 2025 г. и охват 2026 г. должны быть близки.
A7: Оборот фонда по базовому сценарию (сделки с квартирами ÷ фонд) | B7: =СверхуВниз!C10 -> 0.13990546 | C7: < 12% в год | D7: =IF(B7<0.12,"OK","ВНИМАНИЕ") -> ВНИМАНИЕ | E7: Вероятно включены первичные продажи новостроек и дома; число Ташкента завышено [проверить].
A8: Ипотек Jan–May (Минэкономфин, D13) ÷ Jan–Jun (ЦБ, D8) | B8: =Данные!$C$16/Данные!$C$11 -> 0.50623605 | C8: ≈ 0,83 (5/6) | D8: =IF(AND(B8>=0.7,B8<=0.95),"OK","НЕ СХОДИТСЯ") -> НЕ СХОДИТСЯ | E8: Источники считают по-разному (D13 вдвое меньше ожидаемого). Используем ЦБ (D8); различие — в «Запросе данных».
A9: Доли ответивших: согласны + не согласны (D19) | B9: =(1-Данные!$C$23)+Данные!$C$23 -> 1 | C9: =1 -> 1 | D9: =IF(ABS(B9-1)<0.0001,"OK","ОШИБКА") -> OK | E9: Контроль.
A10: Осторожный ≤ базовый ≤ оптимистичный: заказы/мес (снизу вверх) | B10: =СнизуВверх!B23 -> 0.28976 | C10: порядок | D10: =IF(AND(СнизуВверх!B23<=СнизуВверх!C23,СнизуВверх!C23<=СнизуВверх!D23),"OK","ОШИБКА") -> OK | E10: Монотонность сценариев.
A11: Осторожный ≤ базовый ≤ оптимистичный: SAM, событий в год | B11: =СверхуВниз!B42 -> 1329.8094 | C11: порядок | D11: =IF(AND(СверхуВниз!B42<=СверхуВниз!C42,СверхуВниз!C42<=СверхуВниз!D42),"OK","ОШИБКА") -> OK | E11: Монотонность сценариев.
A12: SAM ≤ TAM (базовый) | B12: =СверхуВниз!C42/СверхуВниз!C34 -> 0.21136372 | C12: ≤ 1 | D12: =IF(B12<=1,"OK","ОШИБКА") -> OK | E12: Логика.
A13: Годовая доля SAM, берущаяся заказами (базовый) | B13: =Сценарии!C16 -> 0.0084865172 | C13: < 10% | D13: =IF(B13<0.1,"OK","ВНИМАНИЕ") -> OK | E13: Правдоподобие для нового канала.
A14: Чувствительность: базовый заказов совпадает с СнизуВверх | B14: =Чувствительность!B12-Чувствительность!C12 -> 0 | C14: =0 -> 0 | D14: =IF(ABS(B14)<0.000001,"OK","ОШИБКА") -> OK | E14: Контроль формулы чувствительности.
