Workbook

Sheet Входные данные
A1: Модель этапа 1 HomePrice.uz v0.2 — Входные данные
A2: Единицы: сум, если не указано иное. Формулы других листов читают только этот лист. Ячейка «База» (столбец F) — то, что вы вводите; «Пессимист» и «Оптимист» берутся из неё, если не заданы отдельно. Ответы владельца от 18.10.2026 (форма) внесены.
A4: Цветовая разметка
B5: [факт] — известно от владельца или из документов (18.10.2026); [проверить] — со слов, не сверено с учётом
B6: [гипотеза] — предположение; часть помечена [проверить]
B7: [заглушка] — временное значение до данных (market_sizing.xlsx и др.), не оценка
B8: нужно от Темура — пусто, пока нет данных; модель считает пустое как 0 и сообщает об этом в листе «Проверка»
B9: [выбор] — переключатель модели
B10: Статус проверки модели: | C10: =Проверка!C3 -> ФОРМУЛЫ ОК, НЕ ХВАТАЕТ ДАННЫХ ВЛАДЕЛЬЦА
A12: № | B12: Параметр | C12: Ед. | D12: Статус | E12: Пессимист | F12: База | G12: Оптимист | H12: Источник | I12: Комментарий / что нужно
A13: A. Цена отчёта уровня 3 и срок
A14: P01 | B14: Доля заказов по ~800 тыс. сум | C14: % | D14: [факт][проверить] | E14: =IF(F14="","",F14) -> 0.15 | F14: 0.15 | G14: =IF(F14="","",F14) -> 0.15 | H14: Владелец, форма 18.10.2026, вопрос 1 | I14: Оценка по памяти, не выгрузка из учёта.
A15: P02 | B15: Доля заказов по ~1 млн сум | C15: % | D15: [факт][проверить] | E15: =IF(F15="","",F15) -> 0.75 | F15: 0.75 | G15: =IF(F15="","",F15) -> 0.75 | H15: Владелец, форма 18.10.2026, вопрос 1 | I15: То же.
A16: P03 | B16: Доля заказов дороже 1 млн сум | C16: % | D16: [факт][проверить] | E16: =IF(F16="","",F16) -> 0.1 | F16: 0.1 | G16: =IF(F16="","",F16) -> 0.1 | H16: Владелец, форма 18.10.2026, вопрос 1 | I16: То же. Сумма трёх долей должна быть 100% (проверка C).
A17: P04 | B17: Цена «лёгкого» заказа | C17: сум | D17: [факт] | E17: =IF(F17="","",F17) -> 800000 | F17: 800000 | G17: =IF(F17="","",F17) -> 800000 | H17: Владелец, форма 18.10.2026, вопрос 1 | I17: «Бывает, что делаем и за 800 000».
A18: P05 | B18: Цена обычного заказа | C18: сум | D18: [факт] | E18: =IF(F18="","",F18) -> 1000000 | F18: 1000000 | G18: =IF(F18="","",F18) -> 1000000 | H18: Владелец, форма 18.10.2026, вопрос 1; 05_4P | I18: Средний по Ташкенту.
A19: P06 | B19: Типичная цена заказа «дороже» | C19: сум | D19: [факт][проверить] | E19: =IF(F19="","",F19) -> 1500000 | F19: 1500000 | G19: =IF(F19="","",F19) -> 1500000 | H19: Владелец, форма 18.10.2026, вопрос 1 | I19: Оценка.
A20: P07 | B20: Средняя цена отчёта (формула по долям выше) | C20: сум | D20: [факт][проверить] | E20: =IF(F20="","",F20) -> 1020000 | F20: =F14*F17+F15*F18+F16*F19 -> 1020000 | G20: =IF(F20="","",F20) -> 1020000 | H20: Расчёт по долям и ценам | I20: Формула в столбце «База»: можно заменить числом.
A21: P08 | B21: Срок отчёта | C21: дней | D21: [факт] | E21: =IF(F21="","",F21) -> 2 | F21: 2 | G21: =IF(F21="","",F21) -> 2 | H21: 05_4P; 02_Marketing_Context | I21: Цель — 1 день. В расчёте не используется.
A22: P09 | B22: Цена включает НДС? (1 = да, 0 = нет) | C22: 1/0 | D22: [факт] | E22: =IF(F22="","",F22) -> 0 | F22: 0 | G22: =IF(F22="","",F22) -> 0 | H22: Владелец, форма 18.10.2026, вопрос 2 | I22: KMT не платит НДС.
A23: P10 | B23: Ставка НДС | C23: % | D23: [факт] | E23: =IF(F23="","",F23) -> 0 | F23: 0 | G23: =IF(F23="","",F23) -> 0 | H23: Владелец, форма 18.10.2026, вопрос 2 | I23: 0, так как KMT не плательщик. Статус Bizzone по НДС не уточнялся.
A24: P11 | B24: Курс сум за доллар (справочно) | C24: сум/$ | D24: [гипотеза][проверить] | E24: =IF(F24="","",F24) -> 12000 | F24: 12000 | G24: =IF(F24="","",F24) -> 12000 | H24: 05_4P, 14_Rebaseline п.4.1 | I24: Только для пересчёта допустимой стоимости привлечения в доллары. Проверить на дату.
A25: B. Прибыль (маржа) и прямые затраты одного заказа
A26: P12 | B26: Метод маржи (1 = процент, 2 = построчно, 3 = средняя прибыль в сумах) | C26: 1/2/3 | D26: [выбор] | E26: =IF(F26="","",F26) -> 3 | F26: 3 | G26: =IF(F26="","",F26) -> 3 | H26: Решение модели | I26: 3 — по ответу владельца (вопрос 3). 2 — построчно, пока считается как проверка.
A27: P13 | B27: Средняя прибыль с одного заказа (метод 3) | C27: сум/заказ | D27: [факт][проверить] | E27: 300000 | F27: 400000 | G27: 700000 | H27: Владелец, форма 18.10.2026, вопрос 3 и 5 | I27: Пессимист — самая маленькая (300 тыс.), База — средняя (400 тыс.) со слов. Оптимист 700 тыс. — [гипотеза]: построчные затраты из вопросов 4–5 дают 700 тыс.; разница с 400 тыс. — возможно, административные расходы и офис, которые для дополнительного заказа не растут. Максимум 900 тыс. не используется (одиночный заказ).
A28: P14 | B28: Маржа, % выручки (метод 1, прежняя оценка ≈50%) | C28: % | D28: [гипотеза] | E28: 0.3 | F28: 0.5 | G28: 0.5 | H28: Владелец 18.10 (первая оценка); пессимист — заглушка из 14 п.4.1 | I28: Не используется при методе 3. Оставлена для сравнения.
A29: P15 | B29: Гонорар или зарплата оценщика | C29: сум/заказ | D29: [факт] | E29: =IF(F29="","",F29) -> 100000 | F29: 100000 | G29: =IF(F29="","",F29) -> 100000 | H29: Владелец, форма 18.10.2026, вопрос 5 | I29: Для метода 2 и сверки с вопросом 3.
A30: P16 | B30: Выезд (стоимость × доля заказов с выездом) | C30: сум/заказ | D30: [факт] | E30: =IF(F30="","",F30) -> 100000 | F30: 100000 | G30: =IF(F30="","",F30) -> 100000 | H30: Владелец, форма 18.10.2026, вопрос 4 | I30: 100 000 сум на выезд, нужен у 100% заказов.
A31: P17 | B31: Проверка документов, оформление отчёта | C31: сум/заказ | D31: [факт] | E31: =IF(F31="","",F31) -> 20000 | F31: 20000 | G31: =IF(F31="","",F31) -> 20000 | H31: Владелец, форма 18.10.2026, вопрос 5
A32: P18 | B32: Налоги и сборы с заказа | C32: сум/заказ | D32: [факт] | E32: =IF(F32="","",F32) -> 70000 | F32: 70000 | G32: =IF(F32="","",F32) -> 70000 | H32: Владелец, форма 18.10.2026, вопрос 5
A33: P19 | B33: Платёжные и банковские комиссии | C33: сум/заказ | D33: [факт] | E33: =IF(F33="","",F33) -> 0 | F33: 0 | G33: =IF(F33="","",F33) -> 0 | H33: Владелец, форма 18.10.2026, вопрос 5 | I33: Банк включён в строку «прочее» (dc6).
A34: P20 | B34: Прочее: связь, печать, банк | C34: сум/заказ | D34: [факт] | E34: =IF(F34="","",F34) -> 10000 | F34: 10000 | G34: =IF(F34="","",F34) -> 10000 | H34: Владелец, форма 18.10.2026, вопрос 5
A35: P21 | B35: Юридические и страховые расходы (ответственность оценщика) | C35: сум/заказ | D35: нужно от Темура | E35: =IF(F35="","",F35) | G35: =IF(F35="","",F35) | H35: — | I35: Не спрашивалось. Администратор и офис, которые владелец вычитал в вопросе 3, в вопросе 5 не названы — см. сверку в «Юнит-экономика».
A36: C. Решения I1, D10, агрегатор и партнёры
A37: P22 | B37: I1: кому идут заказы (1 = только KMT, 2 = агрегатор: часть заказов уходит партнёрам с комиссией проекту) | C37: 1/2 | D37: [выбор] | E37: =IF(F37="","",F37) -> 2 | F37: 2 | G37: =IF(F37="","",F37) -> 2 | H37: Решение за владельцем; в 08 не записано | I37: Ответы на вопросы 13–14 прочитаны как намерение подключить партнёров. Переключатель 1 даёт вариант «только KMT»; оба варианта рядом — в листе D10_I1.
A38: P23 | B38: D10: что видит клиент после оценки (1 = блок KMT с контактами без формы, 2 = нейтральный текст) | C38: 1/2 | D38: [выбор] | E38: =IF(F38="","",F38) -> 1 | F38: 1 | G38: =IF(F38="","",F38) -> 1 | H38: Владелец 18.10: блок KMT с контактами, без формы до A4 | I38: Решение за владельцем. Блок «только KMT» не совместим с передачей 70% заказов партнёрам: для партнёров нужен нейтральный список оценщиков (D10-г, не смоделирован).
A39: P24 | B39: Берёт ли проект (Bizzone) комиссию и с заказов, идущих в KMT? (1 = да, 0 = нет) | C39: 1/0 | D39: [факт] | E39: =IF(F39="","",F39) -> 1 | F39: 1 | G39: =IF(F39="","",F39) -> 1 | H39: Владелец, форма 18.10.2026, вопрос 13 | I39: «Да, и с заказов KMT».
A40: P25 | B40: Комиссия сайта как агрегатора, % от суммы договора без НДС | C40: % | D40: [факт] | E40: =IF(F40="","",F40) -> 0.1 | F40: 0.1 | G40: =IF(F40="","",F40) -> 0.1 | H40: Владелец 18.10; Владелец, форма 18.10.2026, вопрос 13 | I40: Платит оценочная компания-партнёр. Для заказов KMT — межгрупповой платёж.
A41: P26 | B41: Доля заказов с сайта, которая уходит партнёрам (после их подключения) | C41: % | D41: [гипотеза] | E41: =IF(F41="","",F41) -> 0.7 | F41: 0.7 | G41: =IF(F41="","",F41) -> 0.7 | H41: Владелец, форма 18.10.2026, вопрос 14 | I41: Оценка владельца. Работает только при I1 = 2.
A42: P27 | B42: Партнёры принимают заказы после месяца №… от запуска | C42: мес | D42: [гипотеза] | E42: 9 | F42: 6 | G42: 3 | H42: Владелец, форма 18.10.2026, вопрос 14 | I42: База = «через 6 месяцев» со слов владельца. Пессимист и оптимист ±3 месяца — моя гипотеза, не данные.
...

Sheet Вопросы к Темуру
A1: Вопросы к Темуру: что осталось уточнить после ответов 18.10.2026
A2: Красных входов осталось немного; главный вопрос — размер рынка (market_sizing.xlsx), без него сценарии объёма остаются заглушкой.
A4: № | B4: Вопрос | C4: Зачем (какие ячейки) | D4: Формат ответа
A5: Q1 | B5: Прибыль с заказа: вы назвали среднюю 400 тыс. сум, а построчные затраты (гонорар 100 тыс., выезд 100 тыс., документы 20 тыс., налоги 70 тыс., прочее 10 тыс.) дают 700 тыс. Что входит в оставшиеся 300 тыс. (администратор, офис, юридические)? Они растут с каждым заказом или это постоянные расходы? | C5: margin_abs, dc7. Если постоянные — для дополнительного заказа прибыль ближе к 700 тыс. | D5: Список статей и сумма
A6: Q2 | B6: Ставки 20 / 20 / 5 млн сум в месяц: это цена полного месяца (40 ч в неделю), из которой оплачиваются фактические часы, или сумма за ваши фактические часы как есть? Сейчас принято первое. | C6: rate_mode. Разница видна в таблице 12 листа «Чувствительность» | D6: 1 / 2 / 3
A7: Q3 | B7: Темур и Равшан — 100% на разработку: после запуска их время в проекте не считается. Так и есть? Кто ведёт контент, партнёров, ответы клиентам после запуска? | C7: dT, dR. Влияет на постоянные расходы | D7: Доли %
A8: Q4 | B8: Колл-центр 5 млн сум в месяц с первого месяца: нужен ли он при нескольких заказах в месяц? Это самая большая статья после труда. | C8: oth. Меняет БУ в разы | D8: Да/нет и сумма
A9: Q5 | B9: Конверсия интерес → заказ: вы ввели 5% в сценариях «Осторожный» и «Базовый» (в «Оптимистичном» осталось 5% по умолчанию). Все три сценария на 5% — это намеренно? Если да, чем «Осторожный» хуже? Мои исходные 2% / 3,5% есть в таблицах чувствительности. | C9: c2 | D9: Три числа
A10: Q6 | B10: Вознаграждение рекомендателям 10%: для скольких заказов из 100 планируется (банки, брокеры, нотариусы)? Юрист: допустимо ли оно? | C10: share_ref. Пока 0 | D10: Доля %, решение юриста
A11: Q7 | B11: Договор между Bizzone и KMT о комиссии 10% с заказов KMT: оформляется или только идея? Платит ли комиссию партнёр сверху к своей цене или из неё? | C11: agg_kmt, fee | D11: Да/нет
A12: Q8 | B12: Партнёры берут 70% заказов с сайта через 6 месяцев. Достаточно ли 3–5 партнёров на такую долю? А «блок KMT с контактами» (D10 б+) при этом остаётся? Он не передаёт заказы партнёрам. | C12: sp, pstart, sel_i1, sel_d10 (решения за вами) | D12: Решение
A13: Q9 | B13: Статус Bizzone по НДС: комиссия сайта 10% облагается НДС? | C13: fee, vat_incl | D13: Да/нет и ставка
A14: Q10 | B14: Когда будет готов market_sizing.xlsx и какая доля рынка достижима? Сейчас объём расчётов — заглушка 100 / 300 / 900 в месяц. | C14: calcs (главная неопределённость модели) | D14: Дата и доля
A15: Q11 | B15: Нулевые пошлины и платёжная интеграция (Click/Payme): действительно ноль? | C15: ot2, ot3 | D15: Да/нет и сумма
A16: Q12 | B16: Доли заказов 15% / 75% / 10% по цене — по памяти или по учёту? Можно ли выгрузить последние 30 заказов (цена, прибыль)? | C16: p800, p1m, pHigh, margin_abs | D16: Выгрузка без ФИО

Sheet Юнит-экономика
A1: Юнит-экономика заказа уровня 3 (отчёт KMT) и комиссия агрегатора
A2: Все числа — из листа «Входные данные». «Владелец» = KMT и проект вместе (комиссия внутри группы взаимно гасится). «Проект» = только Bizzone.
B4: Показатель | C4: Пессимист | D4: База | E4: Оптимист | F4: Комментарий
B5: 1. Выручка и прямые затраты заказа KMT
B6: Средняя цена отчёта | C6: =N('Входные данные'!$E$20) -> 1020000 | D6: =N('Входные данные'!$F$20) -> 1020000 | E6: =N('Входные данные'!$G$20) -> 1020000 | F6: По долям заказов 800 тыс. / 1 млн / дороже (вопрос 1)
B7: НДС в цене | C7: =IF(N('Входные данные'!$E$22)=1,'Юнит-экономика'!$C$6-'Юнит-экономика'!$C$6/(1+N('Входные данные'!$E$23)),0) -> 0 | D7: =IF(N('Входные данные'!$F$22)=1,'Юнит-экономика'!$D$6-'Юнит-экономика'!$D$6/(1+N('Входные данные'!$F$23)),0) -> 0 | E7: =IF(N('Входные данные'!$G$22)=1,'Юнит-экономика'!$E$6-'Юнит-экономика'!$E$6/(1+N('Входные данные'!$G$23)),0) -> 0 | F7: [факт] KMT не платит НДС
B8: Выручка без НДС | C8: ='Юнит-экономика'!$C$6-'Юнит-экономика'!$C$7 -> 1020000 | D8: ='Юнит-экономика'!$D$6-'Юнит-экономика'!$D$7 -> 1020000 | E8: ='Юнит-экономика'!$E$6-'Юнит-экономика'!$E$7 -> 1020000
B9: Сумма построчных прямых затрат (метод 2) | C9: =N('Входные данные'!$E$29)+N('Входные данные'!$E$30)+N('Входные данные'!$E$31)+N('Входные данные'!$E$32)+N('Входные данные'!$E$33)+N('Входные данные'!$E$34)+N('Входные данные'!$E$35) -> 300000 | D9: =N('Входные данные'!$F$29)+N('Входные данные'!$F$30)+N('Входные данные'!$F$31)+N('Входные данные'!$F$32)+N('Входные данные'!$F$33)+N('Входные данные'!$F$34)+N('Входные данные'!$F$35) -> 300000 | E9: =N('Входные данные'!$G$29)+N('Входные данные'!$G$30)+N('Входные данные'!$G$31)+N('Входные данные'!$G$32)+N('Входные данные'!$G$33)+N('Входные данные'!$G$34)+N('Входные данные'!$G$35) -> 300000 | F9: Вопросы 4–5; юридические и страховые (dc7) не названы
B10: Прибыль заказа по оценке владельца (методы 1 и 3) | C10: =IF(N('Входные данные'!$E$26)=1,'Юнит-экономика'!$C$8*N('Входные данные'!$E$28),N('Входные данные'!$E$27)) -> 300000 | D10: =IF(N('Входные данные'!$F$26)=1,'Юнит-экономика'!$D$8*N('Входные данные'!$F$28),N('Входные данные'!$F$27)) -> 400000 | E10: =IF(N('Входные данные'!$G$26)=1,'Юнит-экономика'!$E$8*N('Входные данные'!$G$28),N('Входные данные'!$G$27)) -> 700000 | F10: Метод 3: средняя прибыль со слов владельца
B11: Прямые затраты на заказ | C11: =IF(N('Входные данные'!$E$26)=2,'Юнит-экономика'!$C$9,'Юнит-экономика'!$C$8-'Юнит-экономика'!$C$10) -> 720000 | D11: =IF(N('Входные данные'!$F$26)=2,'Юнит-экономика'!$D$9,'Юнит-экономика'!$D$8-'Юнит-экономика'!$D$10) -> 620000 | E11: =IF(N('Входные данные'!$G$26)=2,'Юнит-экономика'!$E$9,'Юнит-экономика'!$E$8-'Юнит-экономика'!$E$10) -> 320000 | F11: При методе 3 затраты = выручка − средняя прибыль
B12: Прибыль заказа до комиссий | C12: ='Юнит-экономика'!$C$8-'Юнит-экономика'!$C$11 -> 300000 | D12: ='Юнит-экономика'!$D$8-'Юнит-экономика'!$D$11 -> 400000 | E12: ='Юнит-экономика'!$E$8-'Юнит-экономика'!$E$11 -> 700000
B13: Прибыль, % выручки | C13: =IF('Юнит-экономика'!$C$8>0,'Юнит-экономика'!$C$12/'Юнит-экономика'!$C$8,0) -> 0.29411765 | D13: =IF('Юнит-экономика'!$D$8>0,'Юнит-экономика'!$D$12/'Юнит-экономика'!$D$8,0) -> 0.39215686 | E13: =IF('Юнит-экономика'!$E$8>0,'Юнит-экономика'!$E$12/'Юнит-экономика'!$E$8,0) -> 0.68627451
B14: Источник прибыли | C14: =IF(N('Входные данные'!$E$26)=2,IF('Юнит-экономика'!$C$9=0,"НЕТ ДАННЫХ: строки пусты","построчно"),IF(N('Входные данные'!$E$26)=3,"средняя со слов владельца [проверить]","процент владельца [проверить]")) -> средняя со слов владельца [проверить] | D14: =IF(N('Входные данные'!$F$26)=2,IF('Юнит-экономика'!$D$9=0,"НЕТ ДАННЫХ: строки пусты","построчно"),IF(N('Входные данные'!$F$26)=3,"средняя со слов владельца [проверить]","процент владельца [проверить]")) -> средняя со слов владельца [проверить] | E14: =IF(N('Входные данные'!$G$26)=2,IF('Юнит-экономика'!$E$9=0,"НЕТ ДАННЫХ: строки пусты","построчно"),IF(N('Входные данные'!$G$26)=3,"средняя со слов владельца [проверить]","процент владельца [проверить]")) -> средняя со слов владельца [проверить]
B15: Сверка: прибыль по построчным затратам (выручка − сумма строк) | C15: ='Юнит-экономика'!$C$8-'Юнит-экономика'!$C$9 -> 720000 | D15: ='Юнит-экономика'!$D$8-'Юнит-экономика'!$D$9 -> 720000 | E15: ='Юнит-экономика'!$E$8-'Юнит-экономика'!$E$9 -> 720000 | F15: Верхняя граница: в строках нет администратора и офиса, которые владелец вычел в вопросе 3
B16: Сверка: построчная прибыль минус прибыль владельца | C16: ='Юнит-экономика'!$C$15-'Юнит-экономика'!$C$10 -> 420000 | D16: ='Юнит-экономика'!$D$15-'Юнит-экономика'!$D$10 -> 320000 | E16: ='Юнит-экономика'!$E$15-'Юнит-экономика'!$E$10 -> 20000 | F16: Расхождение = то, что владелец вычел сверх строк вопросов 4–5. Если это постоянные расходы, дополнительный заказ их не увеличит
B18: 2. Вознаграждение рекомендателю (банк, брокер, нотариус)
B19: Вознаграждение за заказ, пришедший через рекомендателя | C19: =N('Входные данные'!$E$46)*'Юнит-экономика'!$C$8 -> 102000 | D19: =N('Входные данные'!$F$46)*'Юнит-экономика'!$D$8 -> 102000 | E19: =N('Входные данные'!$G$46)*'Юнит-экономика'!$E$8 -> 102000 | F19: [факт] планируют 10% от чека
B20: Прибыль такого заказа после вознаграждения | C20: ='Юнит-экономика'!$C$12-'Юнит-экономика'!$C$19 -> 198000 | D20: ='Юнит-экономика'!$D$12-'Юнит-экономика'!$D$19 -> 298000 | E20: ='Юнит-экономика'!$E$12-'Юнит-экономика'!$E$19 -> 598000
B21: Вознаграждение съедает, % прибыли | C21: =IF('Юнит-экономика'!$C$12>0,'Юнит-экономика'!$C$19/'Юнит-экономика'!$C$12,0) -> 0.34 | D21: =IF('Юнит-экономика'!$D$12>0,'Юнит-экономика'!$D$19/'Юнит-экономика'!$D$12,0) -> 0.255 | E21: =IF('Юнит-экономика'!$E$12>0,'Юнит-экономика'!$E$19/'Юнит-экономика'!$E$12,0) -> 0.14571429
B22: Вознаграждение на средний заказ (с учётом доли рекомендателей) | C22: =N('Входные данные'!$E$45)*'Юнит-экономика'!$C$19 -> 0 | D22: =N('Входные данные'!$F$45)*'Юнит-экономика'!$D$19 -> 0 | E22: =N('Входные данные'!$G$45)*'Юнит-экономика'!$E$19 -> 0 | F22: Доля рекомендателей не известна (нужно от Темура): пока 0
B23: Прибыль среднего заказа KMT после вознаграждения | C23: ='Юнит-экономика'!$C$12-'Юнит-экономика'!$C$22 -> 300000 | D23: ='Юнит-экономика'!$D$12-'Юнит-экономика'!$D$22 -> 400000 | E23: ='Юнит-экономика'!$E$12-'Юнит-экономика'!$E$22 -> 700000 | F23: До комиссии проекту
B25: 3. Комиссия сайта как агрегатора и доходы на один заказ с сайта
B26: Комиссия проекта с заказа KMT | C26: =N('Входные данные'!$E$39)*N('Входные данные'!$E$40)*'Юнит-экономика'!$C$8 -> 102000 | D26: =N('Входные данные'!$F$39)*N('Входные данные'!$F$40)*'Юнит-экономика'!$D$8 -> 102000 | E26: =N('Входные данные'!$G$39)*N('Входные данные'!$G$40)*'Юнит-экономика'!$E$8 -> 102000 | F26: 10% от суммы договора без НДС; платёж KMT → проект (внутри группы)
B27: Комиссия проекта с заказа партнёра | C27: =N('Входные данные'!$E$40)*N('Входные данные'!$E$43) -> 100000 | D27: =N('Входные данные'!$F$40)*N('Входные данные'!$F$43) -> 100000 | E27: =N('Входные данные'!$G$40)*N('Входные данные'!$G$43) -> 100000 | F27: Платит партнёр; реальный приход группы
B28: Прибыль KMT с заказа после комиссии проекту | C28: ='Юнит-экономика'!$C$23-'Юнит-экономика'!$C$26 -> 198000 | D28: ='Юнит-экономика'!$D$23-'Юнит-экономика'!$D$26 -> 298000 | E28: ='Юнит-экономика'!$E$23-'Юнит-экономика'!$E$26 -> 598000
B29: Доход проекта (Bizzone) с заказа KMT | C29: ='Юнит-экономика'!$C$26+N('Входные данные'!$E$44)*'Юнит-экономика'!$C$28 -> 102000 | D29: ='Юнит-экономика'!$D$26+N('Входные данные'!$F$44)*'Юнит-экономика'!$D$28 -> 102000 | E29: ='Юнит-экономика'!$E$26+N('Входные данные'!$G$44)*'Юнит-экономика'!$E$28 -> 102000 | F29: Комиссия + доля прибыли KMT (по умолчанию 0)
B30: I1 = только KMT: доход владельца на заказ сайта | C30: ='Юнит-экономика'!$C$23 -> 300000 | D30: ='Юнит-экономика'!$D$23 -> 400000 | E30: ='Юнит-экономика'!$E$23 -> 700000
B31: I1 = только KMT: доход проекта на заказ сайта | C31: ='Юнит-экономика'!$C$29 -> 102000 | D31: ='Юнит-экономика'!$D$29 -> 102000 | E31: ='Юнит-экономика'!$E$29 -> 102000
B32: I1 = агрегатор: доход владельца на заказ сайта (после подключения партнёров) | C32: =(1-N('Входные данные'!$E$41))*'Юнит-экономика'!$C$23+N('Входные данные'!$E$41)*'Юнит-экономика'!$C$27 -> 160000 | D32: =(1-N('Входные данные'!$F$41))*'Юнит-экономика'!$D$23+N('Входные данные'!$F$41)*'Юнит-экономика'!$D$27 -> 190000 | E32: =(1-N('Входные данные'!$G$41))*'Юнит-экономика'!$E$23+N('Входные данные'!$G$41)*'Юнит-экономика'!$E$27 -> 280000 | F32: Заказы партнёров приносят только комиссию, остальные — прибыль KMT
B33: I1 = агрегатор: доход проекта на заказ сайта | C33: =(1-N('Входные данные'!$E$41))*'Юнит-экономика'!$C$29+N('Входные данные'!$E$41)*'Юнит-экономика'!$C$27 -> 100600 | D33: =(1-N('Входные данные'!$F$41))*'Юнит-экономика'!$D$29+N('Входные данные'!$F$41)*'Юнит-экономика'!$D$27 -> 100600 | E33: =(1-N('Входные данные'!$G$41))*'Юнит-экономика'!$E$29+N('Входные данные'!$G$41)*'Юнит-экономика'!$E$27 -> 100600
B34: Выбранный вариант: доход владельца на заказ сайта | C34: =IF(N('Входные данные'!$E$37)=2,'Юнит-экономика'!$C$32,'Юнит-экономика'!$C$30) -> 160000 | D34: =IF(N('Входные данные'!$F$37)=2,'Юнит-экономика'!$D$32,'Юнит-экономика'!$D$30) -> 190000 | E34: =IF(N('Входные данные'!$G$37)=2,'Юнит-экономика'!$E$32,'Юнит-экономика'!$E$30) -> 280000 | F34: Без учёта ограничения мощности KMT
B35: Выбранный вариант: доход проекта на заказ сайта | C35: =IF(N('Входные данные'!$E$37)=2,'Юнит-экономика'!$C$33,'Юнит-экономика'!$C$31) -> 100600 | D35: =IF(N('Входные данные'!$F$37)=2,'Юнит-экономика'!$D$33,'Юнит-экономика'!$D$31) -> 100600 | E35: =IF(N('Входные данные'!$G$37)=2,'Юнит-экономика'!$E$33,'Юнит-экономика'!$E$31) -> 100600 | F35: Только комиссия: прибыль KMT проекту не передаётся
B37: 4. Допустимая стоимость привлечения (потолок = доля дохода)
B38: Допустимо на один заказ (по доходу владельца) | C38: =N('Входные данные'!$E$49)*MAX(0,'Юнит-экономика'!$C$34) -> 32000 | D38: =N('Входные данные'!$F$49)*MAX(0,'Юнит-экономика'!$D$34) -> 38000 | E38: =N('Входные данные'!$G$49)*MAX(0,'Юнит-экономика'!$E$34) -> 56000 | F38: [гипотеза] 20% (14, п.4.1)
B39: Допустимо на один заказ (только по доходу проекта) | C39: =N('Входные данные'!$E$49)*MAX(0,'Юнит-экономика'!$C$35) -> 20120 | D39: =N('Входные данные'!$F$49)*MAX(0,'Юнит-экономика'!$D$35) -> 20120 | E39: =N('Входные данные'!$G$49)*MAX(0,'Юнит-экономика'!$E$35) -> 20120 | F39: Если платит один проект, допустимо на порядок меньше
B40: Допустимо на один «интерес» (контакт, клик) | C40: ='Юнит-экономика'!$C$38*N('Входные данные'!$E$58) -> 1600 | D40: ='Юнит-экономика'!$D$38*N('Входные данные'!$F$58) -> 1900 | E40: ='Юнит-экономика'!$E$38*N('Входные данные'!$G$58) -> 2800
B41: Допустимо на один расчёт уровня 1 | C41: ='Юнит-экономика'!$C$38*N('Входные данные'!$E$57)*N('Входные данные'!$E$58)*N('Входные данные'!$E$59) -> 216 | D41: ='Юнит-экономика'!$D$38*N('Входные данные'!$F$57)*N('Входные данные'!$F$58)*N('Входные данные'!$F$59) -> 342 | E41: ='Юнит-экономика'!$E$38*N('Входные данные'!$G$57)*N('Входные данные'!$G$58)*N('Входные данные'!$G$59) -> 630 | F41: Платный трафик на потребительский калькулятор окупается только при очень дешёвом клике
B42: То же, долларов | C42: =IF(N('Входные данные'!$E$24)>0,'Юнит-экономика'!$C$41/N('Входные данные'!$E$24),0) -> 0.018 | D42: =IF(N('Входные данные'!$F$24)>0,'Юнит-экономика'!$D$41/N('Входные данные'!$F$24),0) -> 0.0285 | E42: =IF(N('Входные данные'!$G$24)>0,'Юнит-экономика'!$E$41/N('Входные данные'!$G$24),0) -> 0.0525
B43: Вознаграждение рекомендателю больше потолка привлечения в … раз | C43: =IF(AND('Юнит-экономика'!$C$20>0,N('Входные данные'!$E$49)>0),'Юнит-экономика'!$C$19/(N('Входные данные'!$E$49)*'Юнит-экономика'!$C$20),"н/д") -> 2.5757576 | D43: =IF(AND('Юнит-экономика'!$D$20>0,N('Входные данные'!$F$49)>0),'Юнит-экономика'!$D$19/(N('Входные данные'!$F$49)*'Юнит-экономика'!$D$20),"н/д") -> 1.7114094 | E43: =IF(AND('Юнит-экономика'!$E$20>0,N('Входные данные'!$G$49)>0),'Юнит-экономика'!$E$19/(N('Входные данные'!$G$49)*'Юнит-экономика'!$E$20),"н/д") -> 0.85284281 | F43: Если >1, вознаграждение выше потолка 20% и вводить его нельзя без пересмотра потолка

Sheet Воронка
A1: Воронка: посетитель → расчёт → интерес → заказ, и куда идут заказы
A2: Конверсии из 05_4P — гипотезы (c2 заменена вводом владельца). Режим = после выхода на режим и подключения партнёров.
B4: Показатель | C4: Пессимист | D4: База | E4: Оптимист | F4: Комментарий
B5: Посетителей в месяц | C5: =IF(N('Входные данные'!$E$56)>0,N('Входные данные'!$E$55)/N('Входные данные'!$E$56),"нужно измерить") -> нужно измерить | D5: =IF(N('Входные данные'!$F$56)>0,N('Входные данные'!$F$55)/N('Входные данные'!$F$56),"нужно измерить") -> нужно измерить | E5: =IF(N('Входные данные'!$G$56)>0,N('Входные данные'!$G$55)/N('Входные данные'!$G$56),"нужно измерить") -> нужно измерить | F5: Нужна конверсия посетитель → расчёт (нужно от Темура / E2)
B6: Расчётов уровня 1 в месяц | C6: =N('Входные данные'!$E$55) -> 100 | D6: =N('Входные данные'!$F$55) -> 300 | E6: =N('Входные данные'!$G$55) -> 900 | F6: [заглушка] до market_sizing.xlsx
B7: Конверсия расчёт → интерес | C7: =N('Входные данные'!$E$57) -> 0.15 | D7: =N('Входные данные'!$F$57) -> 0.2 | E7: =N('Входные данные'!$G$57) -> 0.25 | F7: [гипотеза] 05_4P
B8: Интересов в месяц | C8: =Воронка!$C$6*Воронка!$C$7 -> 15 | D8: =Воронка!$D$6*Воронка!$D$7 -> 60 | E8: =Воронка!$E$6*Воронка!$E$7 -> 225
B9: Конверсия интерес → заказ | C9: =N('Входные данные'!$E$58) -> 0.05 | D9: =N('Входные данные'!$F$58) -> 0.05 | E9: =N('Входные данные'!$G$58) -> 0.05 | F9: [гипотеза] ввод владельца 5%
B10: Заказов уровня 3 в месяц (всего) | C10: =Воронка!$C$8*Воронка!$C$9 -> 0.75 | D10: =Воронка!$D$8*Воронка!$D$9 -> 3 | E10: =Воронка!$E$8*Воронка!$E$9 -> 11.25
B11: Доля инкрементальных заказов | C11: =N('Входные данные'!$E$59) -> 0.9 | D11: =N('Входные данные'!$F$59) -> 0.9 | E11: =N('Входные данные'!$G$59) -> 0.9 | F11: [гипотеза] около 90% со слов владельца
B12: Инкрементальных заказов в месяц | C12: =Воронка!$C$10*Воронка!$C$11 -> 0.675 | D12: =Воронка!$D$10*Воронка!$D$11 -> 2.7 | E12: =Воронка!$E$10*Воронка!$E$11 -> 10.125
B13: Сквозная конверсия расчёт → инкрементальный заказ | C13: =Воронка!$C$7*Воронка!$C$9*Воронка!$C$11 -> 0.00675 | D13: =Воронка!$D$7*Воронка!$D$9*Воронка!$D$11 -> 0.009 | E13: =Воронка!$E$7*Воронка!$E$9*Воронка!$E$11 -> 0.01125
B14: Расчётов на один заказ | C14: =IF(Воронка!$C$13>0,1/Воронка!$C$13,"нет конверсии") -> 148.14815 | D14: =IF(Воронка!$D$13>0,1/Воронка!$D$13,"нет конверсии") -> 111.11111 | E14: =IF(Воронка!$E$13>0,1/Воронка!$E$13,"нет конверсии") -> 88.888889
B16: Влияние D10, мощность KMT и партнёры (режим)
B17: Множитель потока по выбранному D10 | C17: =IF(N('Входные данные'!$E$38)=2,N('Входные данные'!$E$47),1) -> 1 | D17: =IF(N('Входные данные'!$F$38)=2,N('Входные данные'!$F$47),1) -> 1 | E17: =IF(N('Входные данные'!$G$38)=2,N('Входные данные'!$G$47),1) -> 1 | F17: б+ = 100%; нейтральный текст = доля m_a [заглушка]
B18: Заказов с сайта в месяц (режим, с учётом D10) | C18: =Воронка!$C$12*Воронка!$C$17 -> 0.675 | D18: =Воронка!$D$12*Воронка!$D$17 -> 2.7 | E18: =Воронка!$E$12*Воронка!$E$17 -> 10.125
B19: Запас мощности KMT: заказов в месяц сверх нынешних | C19: =IF(N('Входные данные'!$E$52)>0,MAX(0,N('Входные данные'!$E$52)-N('Входные данные'!$E$51)),1000000000) -> 10 | D19: =IF(N('Входные данные'!$F$52)>0,MAX(0,N('Входные данные'!$F$52)-N('Входные данные'!$F$51)),1000000000) -> 10 | E19: =IF(N('Входные данные'!$G$52)>0,MAX(0,N('Входные данные'!$G$52)-N('Входные данные'!$G$51)),1000000000) -> 10 | F19: Максимум без найма − сейчас. 1 000 000 000 = ограничения нет (мощность не задана)
B20: Доля заказов, уходящая партнёрам (режим) | C20: =IF(N('Входные данные'!$E$37)=2,N('Входные данные'!$E$41),0) -> 0.7 | D20: =IF(N('Входные данные'!$F$37)=2,N('Входные данные'!$F$41),0) -> 0.7 | E20: =IF(N('Входные данные'!$G$37)=2,N('Входные данные'!$G$41),0) -> 0.7 | F20: Только при I1 = 2, после подключения партнёров
B21: Заказов, направленных в KMT, в месяц | C21: =Воронка!$C$18*(1-Воронка!$C$20) -> 0.2025 | D21: =Воронка!$D$18*(1-Воронка!$D$20) -> 0.81 | E21: =Воронка!$E$18*(1-Воронка!$E$20) -> 3.0375
B22: Заказов, которые KMT возьмёт (в пределах мощности) | C22: =MIN(Воронка!$C$21,Воронка!$C$19) -> 0.2025 | D22: =MIN(Воронка!$D$21,Воронка!$D$19) -> 0.81 | E22: =MIN(Воронка!$E$21,Воронка!$E$19) -> 3.0375
B23: Заказов теряется из-за мощности KMT | C23: =Воронка!$C$21-Воронка!$C$22 -> 0 | D23: =Воронка!$D$21-Воронка!$D$22 -> 0 | E23: =Воронка!$E$21-Воронка!$E$22 -> 0 | F23: Без найма людей эти заказы не выполнить
B24: Заказов уходит партнёрам в месяц | C24: =Воронка!$C$18*Воронка!$C$20 -> 0.4725 | D24: =Воронка!$D$18*Воронка!$D$20 -> 1.89 | E24: =Воронка!$E$18*Воронка!$E$20 -> 7.0875
B25: Выручка заказов в KMT, сум/мес (без НДС) | C25: =Воронка!$C$22*'Юнит-экономика'!$C$8 -> 206550 | D25: =Воронка!$D$22*'Юнит-экономика'!$D$8 -> 826200 | E25: =Воронка!$E$22*'Юнит-экономика'!$E$8 -> 3098250
B26: Доход проекта (Bizzone), сум/мес в режиме | C26: =Воронка!$C$22*'Юнит-экономика'!$C$29+Воронка!$C$24*'Юнит-экономика'!$C$27 -> 67905 | D26: =Воронка!$D$22*'Юнит-экономика'!$D$29+Воронка!$D$24*'Юнит-экономика'!$D$27 -> 271620 | E26: =Воронка!$E$22*'Юнит-экономика'!$E$29+Воронка!$E$24*'Юнит-экономика'!$E$27 -> 1018575 | F26: Комиссии с заказов KMT и партнёров
B27: Прибыль KMT после комиссии, сум/мес в режиме | C27: =Воронка!$C$22*'Юнит-экономика'!$C$28*(1-N('Входные данные'!$E$44)) -> 40095 | D27: =Воронка!$D$22*'Юнит-экономика'!$D$28*(1-N('Входные данные'!$F$44)) -> 241380 | E27: =Воронка!$E$22*'Юнит-экономика'!$E$28*(1-N('Входные данные'!$G$44)) -> 1816425
B28: Доход владельца (KMT + проект), сум/мес в режиме | C28: =Воронка!$C$26+Воронка!$C$27 -> 108000 | D28: =Воронка!$D$26+Воронка!$D$27 -> 513000 | E28: =Воронка!$E$26+Воронка!$E$27 -> 2835000 | F28: Комиссия KMT → проект в сумме гасится

Sheet Сценарии_BEP
A1: Точка безубыточности и окупаемость этапа 1 (три сценария)
A2: Разработка и запуск (этап 1, 3 мес) считаются отдельно до запуска; после запуска — 12 месяцев работы. Два взгляда: владелец (KMT + проект) и проект (Bizzone) отдельно.
B4: Показатель | C4: Пессимист | D4: База | E4: Оптимист | F4: Комментарий
B5: 1. Операционные расходы в месяц (после запуска)
B6: Хостинг и сервисы | C6: =N('Входные данные'!$E$62) -> 1000000 | D6: =N('Входные данные'!$F$62) -> 1000000 | E6: =N('Входные данные'!$G$62) -> 1000000 | F6: [факт]
B7: SMS, колл-центр, прочее | C7: =N('Входные данные'!$E$63) -> 6500000 | D7: =N('Входные данные'!$F$63) -> 6500000 | E7: =N('Входные данные'!$G$63) -> 6500000 | F7: [факт] 1 + 5 + 0,5 млн
B8: Маркетинг (постоянный бюджет) | C8: =N('Входные данные'!$E$50) -> 0 | D8: =N('Входные данные'!$F$50) -> 0 | E8: =N('Входные данные'!$G$50) -> 0 | F8: [факт] постоянного бюджета нет
B9: Денежные операционные расходы | C9: =Сценарии_BEP!$C$6+Сценарии_BEP!$C$7+Сценарии_BEP!$C$8 -> 7500000 | D9: =Сценарии_BEP!$D$6+Сценарии_BEP!$D$7+Сценарии_BEP!$D$8 -> 7500000 | E9: =Сценарии_BEP!$E$6+Сценарии_BEP!$E$7+Сценарии_BEP!$E$8 -> 7500000
B10: Часов в месяц на 1 час «периода» | C10: =IF(N('Входные данные'!$E$65)=1,52/12,IF(N('Входные данные'!$E$65)=2,1,IF(AND(N('Входные данные'!$E$65)=3,N('Входные данные'!$E$66)>0),1/N('Входные данные'!$E$66),0))) -> 4.3333333 | D10: =IF(N('Входные данные'!$F$65)=1,52/12,IF(N('Входные данные'!$F$65)=2,1,IF(AND(N('Входные данные'!$F$65)=3,N('Входные данные'!$F$66)>0),1/N('Входные данные'!$F$66),0))) -> 4.3333333 | E10: =IF(N('Входные данные'!$G$65)=1,52/12,IF(N('Входные данные'!$G$65)=2,1,IF(AND(N('Входные данные'!$G$65)=3,N('Входные данные'!$G$66)>0),1/N('Входные данные'!$G$66),0))) -> 4.3333333 | F10: 0, пока не заданы единицы часов
B11: Часов в месяц: Темур | C11: =N('Входные данные'!$E$67)*Сценарии_BEP!$C$10 -> 86.666667 | D11: =N('Входные данные'!$F$67)*Сценарии_BEP!$D$10 -> 75.833333 | E11: =N('Входные данные'!$G$67)*Сценарии_BEP!$E$10 -> 65
B12: Часов в месяц: Равшан | C12: =N('Входные данные'!$E$68)*Сценарии_BEP!$C$10 -> 86.666667 | D12: =N('Входные данные'!$F$68)*Сценарии_BEP!$D$10 -> 75.833333 | E12: =N('Входные данные'!$G$68)*Сценарии_BEP!$E$10 -> 65
B13: Часов в месяц: Азиз | C13: =N('Входные данные'!$E$69)*Сценарии_BEP!$C$10 -> 216.66667 | D13: =N('Входные данные'!$F$69)*Сценарии_BEP!$D$10 -> 216.66667 | E13: =N('Входные данные'!$G$69)*Сценарии_BEP!$E$10 -> 216.66667
B14: Стоимость месяца работы (все часы): Темур | C14: =IF(N('Входные данные'!$E$70)=1,Сценарии_BEP!$C$11*N('Входные данные'!$E$72),IF(N('Входные данные'!$E$70)=2,IF(N('Входные данные'!$E$71)>0,Сценарии_BEP!$C$11/(N('Входные данные'!$E$71)*52/12)*N('Входные данные'!$E$72),0),N('Входные данные'!$E$72))) -> 10000000 | D14: =IF(N('Входные данные'!$F$70)=1,Сценарии_BEP!$D$11*N('Входные данные'!$F$72),IF(N('Входные данные'!$F$70)=2,IF(N('Входные данные'!$F$71)>0,Сценарии_BEP!$D$11/(N('Входные данные'!$F$71)*52/12)*N('Входные данные'!$F$72),0),N('Входные данные'!$F$72))) -> 8750000 | E14: =IF(N('Входные данные'!$G$70)=1,Сценарии_BEP!$E$11*N('Входные данные'!$G$72),IF(N('Входные данные'!$G$70)=2,IF(N('Входные данные'!$G$71)>0,Сценарии_BEP!$E$11/(N('Входные данные'!$G$71)*52/12)*N('Входные данные'!$G$72),0),N('Входные данные'!$G$72))) -> 7500000 | F14: Чтение ставки задаётся параметром rate_mode
B15: Стоимость месяца работы (все часы): Равшан | C15: =IF(N('Входные данные'!$E$70)=1,Сценарии_BEP!$C$12*N('Входные данные'!$E$73),IF(N('Входные данные'!$E$70)=2,IF(N('Входные данные'!$E$71)>0,Сценарии_BEP!$C$12/(N('Входные данные'!$E$71)*52/12)*N('Входные данные'!$E$73),0),N('Входные данные'!$E$73))) -> 10000000 | D15: =IF(N('Входные данные'!$F$70)=1,Сценарии_BEP!$D$12*N('Входные данные'!$F$73),IF(N('Входные данные'!$F$70)=2,IF(N('Входные данные'!$F$71)>0,Сценарии_BEP!$D$12/(N('Входные данные'!$F$71)*52/12)*N('Входные данные'!$F$73),0),N('Входные данные'!$F$73))) -> 8750000 | E15: =IF(N('Входные данные'!$G$70)=1,Сценарии_BEP!$E$12*N('Входные данные'!$G$73),IF(N('Входные данные'!$G$70)=2,IF(N('Входные данные'!$G$71)>0,Сценарии_BEP!$E$12/(N('Входные данные'!$G$71)*52/12)*N('Входные данные'!$G$73),0),N('Входные данные'!$G$73))) -> 7500000 | F15: Чтение ставки задаётся параметром rate_mode
B16: Стоимость месяца работы (все часы): Азиз | C16: =IF(N('Входные данные'!$E$70)=1,Сценарии_BEP!$C$13*N('Входные данные'!$E$74),IF(N('Входные данные'!$E$70)=2,IF(N('Входные данные'!$E$71)>0,Сценарии_BEP!$C$13/(N('Входные данные'!$E$71)*52/12)*N('Входные данные'!$E$74),0),N('Входные данные'!$E$74))) -> 6250000 | D16: =IF(N('Входные данные'!$F$70)=1,Сценарии_BEP!$D$13*N('Входные данные'!$F$74),IF(N('Входные данные'!$F$70)=2,IF(N('Входные данные'!$F$71)>0,Сценарии_BEP!$D$13/(N('Входные данные'!$F$71)*52/12)*N('Входные данные'!$F$74),0),N('Входные данные'!$F$74))) -> 6250000 | E16: =IF(N('Входные данные'!$G$70)=1,Сценарии_BEP!$E$13*N('Входные данные'!$G$74),IF(N('Входные данные'!$G$70)=2,IF(N('Входные данные'!$G$71)>0,Сценарии_BEP!$E$13/(N('Входные данные'!$G$71)*52/12)*N('Входные данные'!$G$74),0),N('Входные данные'!$G$74))) -> 6250000 | F16: Чтение ставки задаётся параметром rate_mode
B17: Труд, постоянная часть: Темур | C17: =Сценарии_BEP!$C$14*(1-N('Входные данные'!$E$75)) -> 0 | D17: =Сценарии_BEP!$D$14*(1-N('Входные данные'!$F$75)) -> 0 | E17: =Сценарии_BEP!$E$14*(1-N('Входные данные'!$G$75)) -> 0 | F17: стоимость месяца × (1 − доля разработки)
B18: Труд, постоянная часть: Равшан | C18: =Сценарии_BEP!$C$15*(1-N('Входные данные'!$E$76)) -> 0 | D18: =Сценарии_BEP!$D$15*(1-N('Входные данные'!$F$76)) -> 0 | E18: =Сценарии_BEP!$E$15*(1-N('Входные данные'!$G$76)) -> 0 | F18: стоимость месяца × (1 − доля разработки)
B19: Труд, постоянная часть: Азиз | C19: =Сценарии_BEP!$C$16*(1-N('Входные данные'!$E$77)) -> 1250000 | D19: =Сценарии_BEP!$D$16*(1-N('Входные данные'!$F$77)) -> 1250000 | E19: =Сценарии_BEP!$E$16*(1-N('Входные данные'!$G$77)) -> 1250000 | F19: стоимость месяца × (1 − доля разработки)
B20: Труд команды (постоянная часть), сум/мес | C20: =Сценарии_BEP!$C$17+Сценарии_BEP!$C$18+Сценарии_BEP!$C$19 -> 1250000 | D20: =Сценарии_BEP!$D$17+Сценарии_BEP!$D$18+Сценарии_BEP!$D$19 -> 1250000 | E20: =Сценарии_BEP!$E$17+Сценарии_BEP!$E$18+Сценарии_BEP!$E$19 -> 1250000 | F20: Условная стоимость времени, не денежный расход
B21: Полные операционные расходы, сум/мес | C21: =Сценарии_BEP!$C$9+Сценарии_BEP!$C$20 -> 8750000 | D21: =Сценарии_BEP!$D$9+Сценарии_BEP!$D$20 -> 8750000 | E21: =Сценарии_BEP!$E$9+Сценарии_BEP!$E$20 -> 8750000
B23: 2. Разработка и запуск (разово, до запуска, отдельно от операционных)
B24: Разработка и запуск: Темур | C24: =Сценарии_BEP!$C$14*N('Входные данные'!$E$75)*N('Входные данные'!$E$66) -> 30000000 | D24: =Сценарии_BEP!$D$14*N('Входные данные'!$F$75)*N('Входные данные'!$F$66) -> 26250000 | E24: =Сценарии_BEP!$E$14*N('Входные данные'!$G$75)*N('Входные данные'!$G$66) -> 22500000 | F24: стоимость месяца × доля разработки × месяцев этапа
B25: Разработка и запуск: Равшан | C25: =Сценарии_BEP!$C$15*N('Входные данные'!$E$76)*N('Входные данные'!$E$66) -> 30000000 | D25: =Сценарии_BEP!$D$15*N('Входные данные'!$F$76)*N('Входные данные'!$F$66) -> 26250000 | E25: =Сценарии_BEP!$E$15*N('Входные данные'!$G$76)*N('Входные данные'!$G$66) -> 22500000 | F25: стоимость месяца × доля разработки × месяцев этапа
B26: Разработка и запуск: Азиз | C26: =Сценарии_BEP!$C$16*N('Входные данные'!$E$77)*N('Входные данные'!$E$66) -> 15000000 | D26: =Сценарии_BEP!$D$16*N('Входные данные'!$F$77)*N('Входные данные'!$F$66) -> 15000000 | E26: =Сценарии_BEP!$E$16*N('Входные данные'!$G$77)*N('Входные данные'!$G$66) -> 15000000 | F26: стоимость месяца × доля разработки × месяцев этапа
B27: Разработка: труд команды | C27: =Сценарии_BEP!$C$24+Сценарии_BEP!$C$25+Сценарии_BEP!$C$26 -> 75000000 | D27: =Сценарии_BEP!$D$24+Сценарии_BEP!$D$25+Сценарии_BEP!$D$26 -> 67500000 | E27: =Сценарии_BEP!$E$24+Сценарии_BEP!$E$25+Сценарии_BEP!$E$26 -> 60000000
B28: Разовые внешние расходы (включая пробную рекламу) | C28: =N('Входные данные'!$E$79)+N('Входные данные'!$E$80)+N('Входные данные'!$E$81)+N('Входные данные'!$E$82)+N('Входные данные'!$E$83) -> 4500000 | D28: =N('Входные данные'!$F$79)+N('Входные данные'!$F$80)+N('Входные данные'!$F$81)+N('Входные данные'!$F$82)+N('Входные данные'!$F$83) -> 4500000 | E28: =N('Входные данные'!$G$79)+N('Входные данные'!$G$80)+N('Входные данные'!$G$81)+N('Входные данные'!$G$82)+N('Входные данные'!$G$83) -> 4500000 | F28: [факт] 0,5 + 3 + 1 млн
B29: Разработка и запуск, итого | C29: =Сценарии_BEP!$C$27+Сценарии_BEP!$C$28 -> 79500000 | D29: =Сценарии_BEP!$D$27+Сценарии_BEP!$D$28 -> 72000000 | E29: =Сценарии_BEP!$E$27+Сценарии_BEP!$E$28 -> 64500000
B30: Из них денежные расходы (без условной стоимости труда) | C30: =Сценарии_BEP!$C$28 -> 4500000 | D30: =Сценарии_BEP!$D$28 -> 4500000 | E30: =Сценарии_BEP!$E$28 -> 4500000
B32: 3. Точка безубыточности в режиме (на выбранном варианте I1; без учёта мощности KMT)
B33: Доход владельца на заказ с сайта | C33: ='Юнит-экономика'!$C$34 -> 160000 | D33: ='Юнит-экономика'!$D$34 -> 190000 | E33: ='Юнит-экономика'!$E$34 -> 280000
B34: Доход проекта на заказ с сайта | C34: ='Юнит-экономика'!$C$35 -> 100600 | D34: ='Юнит-экономика'!$D$35 -> 100600 | E34: ='Юнит-экономика'!$E$35 -> 100600 | F34: Только комиссия
B35: Сквозная конверсия расчёт → заказ (с учётом D10) | C35: =Воронка!$C$13*Воронка!$C$17 -> 0.00675 | D35: =Воронка!$D$13*Воронка!$D$17 -> 0.009 | E35: =Воронка!$E$13*Воронка!$E$17 -> 0.01125
B36: БУ владельца, денежная: заказов с сайта в месяц | C36: =IF(Сценарии_BEP!$C$33>0,Сценарии_BEP!$C$9/Сценарии_BEP!$C$33,"нет БУ") -> 46.875 | D36: =IF(Сценарии_BEP!$D$33>0,Сценарии_BEP!$D$9/Сценарии_BEP!$D$33,"нет БУ") -> 39.473684 | E36: =IF(Сценарии_BEP!$E$33>0,Сценарии_BEP!$E$9/Сценарии_BEP!$E$33,"нет БУ") -> 26.785714
B37: БУ владельца, полная: заказов с сайта в месяц | C37: =IF(Сценарии_BEP!$C$33>0,Сценарии_BEP!$C$21/Сценарии_BEP!$C$33,"нет БУ") -> 54.6875 | D37: =IF(Сценарии_BEP!$D$33>0,Сценарии_BEP!$D$21/Сценарии_BEP!$D$33,"нет БУ") -> 46.052632 | E37: =IF(Сценарии_BEP!$E$33>0,Сценарии_BEP!$E$21/Сценарии_BEP!$E$33,"нет БУ") -> 31.25
B38: БУ владельца, денежная: расчётов уровня 1 в месяц | C38: =IF(AND(ISNUMBER(Сценарии_BEP!$C$36),Сценарии_BEP!$C$35>0),Сценарии_BEP!$C$36/Сценарии_BEP!$C$35,"нет БУ") -> 6944.4444 | D38: =IF(AND(ISNUMBER(Сценарии_BEP!$D$36),Сценарии_BEP!$D$35>0),Сценарии_BEP!$D$36/Сценарии_BEP!$D$35,"нет БУ") -> 4385.9649 | E38: =IF(AND(ISNUMBER(Сценарии_BEP!$E$36),Сценарии_BEP!$E$35>0),Сценарии_BEP!$E$36/Сценарии_BEP!$E$35,"нет БУ") -> 2380.9524
B39: БУ владельца, полная: расчётов уровня 1 в месяц | C39: =IF(AND(ISNUMBER(Сценарии_BEP!$C$37),Сценарии_BEP!$C$35>0),Сценарии_BEP!$C$37/Сценарии_BEP!$C$35,"нет БУ") -> 8101.8519 | D39: =IF(AND(ISNUMBER(Сценарии_BEP!$D$37),Сценарии_BEP!$D$35>0),Сценарии_BEP!$D$37/Сценарии_BEP!$D$35,"нет БУ") -> 5116.9591 | E39: =IF(AND(ISNUMBER(Сценарии_BEP!$E$37),Сценарии_BEP!$E$35>0),Сценарии_BEP!$E$37/Сценарии_BEP!$E$35,"нет БУ") -> 2777.7778
B40: БУ проекта, полная: заказов с сайта в месяц | C40: =IF(Сценарии_BEP!$C$34>0,Сценарии_BEP!$C$21/Сценарии_BEP!$C$34,"нет БУ") -> 86.978131 | D40: =IF(Сценарии_BEP!$D$34>0,Сценарии_BEP!$D$21/Сценарии_BEP!$D$34,"нет БУ") -> 86.978131 | E40: =IF(Сценарии_BEP!$E$34>0,Сценарии_BEP!$E$21/Сценарии_BEP!$E$34,"нет БУ") -> 86.978131
B41: БУ проекта, полная: расчётов уровня 1 в месяц | C41: =IF(AND(ISNUMBER(Сценарии_BEP!$C$40),Сценарии_BEP!$C$35>0),Сценарии_BEP!$C$40/Сценарии_BEP!$C$35,"нет БУ") -> 12885.649 | D41: =IF(AND(ISNUMBER(Сценарии_BEP!$D$40),Сценарии_BEP!$D$35>0),Сценарии_BEP!$D$40/Сценарии_BEP!$D$35,"нет БУ") -> 9664.2368 | E41: =IF(AND(ISNUMBER(Сценарии_BEP!$E$40),Сценарии_BEP!$E$35>0),Сценарии_BEP!$E$40/Сценарии_BEP!$E$35,"нет БУ") -> 7731.3894
B42: Хватит ли мощности KMT на заказы при полной БУ владельца | C42: =IF(ISNUMBER(Сценарии_BEP!$C$37),IF(Сценарии_BEP!$C$37*(1-Воронка!$C$20)<=Воронка!$C$19,"хватает","НЕ хватает: упрёмся в мощность KMT"),"н/д") -> НЕ хватает: упрёмся в мощность KMT | D42: =IF(ISNUMBER(Сценарии_BEP!$D$37),IF(Сценарии_BEP!$D$37*(1-Воронка!$D$20)<=Воронка!$D$19,"хватает","НЕ хватает: упрёмся в мощность KMT"),"н/д") -> НЕ хватает: упрёмся в мощность KMT | E42: =IF(ISNUMBER(Сценарии_BEP!$E$37),IF(Сценарии_BEP!$E$37*(1-Воронка!$E$20)<=Воронка!$E$19,"хватает","НЕ хватает: упрёмся в мощность KMT"),"н/д") -> хватает | F42: Нужно заказов в KMT при БУ против запаса мощности (вопрос 17)
B43: Объём сценария / БУ владельца полная (расчёты), раз | C43: =IF(ISNUMBER(Сценарии_BEP!$C$39),Воронка!$C$6/Сценарии_BEP!$C$39,"н/д") -> 0.012342857 | D43: =IF(ISNUMBER(Сценарии_BEP!$D$39),Воронка!$D$6/Сценарии_BEP!$D$39,"н/д") -> 0.058628571 | E43: =IF(ISNUMBER(Сценарии_BEP!$E$39),Воронка!$E$6/Сценарии_BEP!$E$39,"н/д") -> 0.324 | F43: Меньше 1 — сценарий не покрывает расходы
...

Sheet D10_I1
A1: Влияние решений D10 и I1: по два варианта, четыре сочетания
A2: Режим (после выхода на режим и подключения партнёров, с ограничением мощности KMT). I1: A = только KMT, B = агрегатор (партнёры берут долю заказов). D10: б+ = блок KMT с контактами, а = нейтральный текст.
B4: Сценарий: Пессимист
B5: Показатель | C5: I1=A · D10=б+ | D5: I1=A · D10=а | E5: I1=B · D10=б+ | F5: I1=B · D10=а
B6: Множитель потока D10 | C6: 1 | D6: =N('Входные данные'!$E$47) -> 0.25 | E6: 1 | F6: =N('Входные данные'!$E$47) -> 0.25
B7: Заказов с сайта в месяц | C7: =Воронка!$C$12*C6 -> 0.675 | D7: =Воронка!$C$12*D6 -> 0.16875 | E7: =Воронка!$C$12*E6 -> 0.675 | F7: =Воронка!$C$12*F6 -> 0.16875
B8: Доля партнёров | C8: 0 | D8: 0 | E8: =N('Входные данные'!$E$41) -> 0.7 | F8: =N('Входные данные'!$E$41) -> 0.7
B9: Заказов берёт KMT (в пределах мощности) | C9: =MIN(C7*(1-C8),Воронка!$C$19) -> 0.675 | D9: =MIN(D7*(1-D8),Воронка!$C$19) -> 0.16875 | E9: =MIN(E7*(1-E8),Воронка!$C$19) -> 0.2025 | F9: =MIN(F7*(1-F8),Воронка!$C$19) -> 0.050625
B10: Заказов у партнёров | C10: =C7*C8 -> 0 | D10: =D7*D8 -> 0 | E10: =E7*E8 -> 0.4725 | F10: =F7*F8 -> 0.118125
B11: Доход владельца на заказ сайта (без мощности) | C11: =(1-C8)*'Юнит-экономика'!$C$23+C8*'Юнит-экономика'!$C$27 -> 300000 | D11: =(1-D8)*'Юнит-экономика'!$C$23+D8*'Юнит-экономика'!$C$27 -> 300000 | E11: =(1-E8)*'Юнит-экономика'!$C$23+E8*'Юнит-экономика'!$C$27 -> 160000 | F11: =(1-F8)*'Юнит-экономика'!$C$23+F8*'Юнит-экономика'!$C$27 -> 160000
B12: Доход владельца в месяц | C12: =C13+C9*'Юнит-экономика'!$C$28*(1-N('Входные данные'!$E$44)) -> 202500 | D12: =D13+D9*'Юнит-экономика'!$C$28*(1-N('Входные данные'!$E$44)) -> 50625 | E12: =E13+E9*'Юнит-экономика'!$C$28*(1-N('Входные данные'!$E$44)) -> 108000 | F12: =F13+F9*'Юнит-экономика'!$C$28*(1-N('Входные данные'!$E$44)) -> 27000
B13: Доход проекта в месяц (комиссии) | C13: =C9*'Юнит-экономика'!$C$29+C10*'Юнит-экономика'!$C$27 -> 68850 | D13: =D9*'Юнит-экономика'!$C$29+D10*'Юнит-экономика'!$C$27 -> 17212.5 | E13: =E9*'Юнит-экономика'!$C$29+E10*'Юнит-экономика'!$C$27 -> 67905 | F13: =F9*'Юнит-экономика'!$C$29+F10*'Юнит-экономика'!$C$27 -> 16976.25
B14: Полные операционные расходы в месяц | C14: =Сценарии_BEP!$C$21 -> 8750000 | D14: =Сценарии_BEP!$C$21 -> 8750000 | E14: =Сценарии_BEP!$C$21 -> 8750000 | F14: =Сценарии_BEP!$C$21 -> 8750000
B15: Результат владельца в месяц | C15: =C12-C14 -> -8547500 | D15: =D12-D14 -> -8699375 | E15: =E12-E14 -> -8642000 | F15: =F12-F14 -> -8723000
B16: Результат проекта в месяц | C16: =C13-C14 -> -8681150 | D16: =D13-D14 -> -8732787.5 | E16: =E13-E14 -> -8682095 | F16: =F13-F14 -> -8733023.8
B17: Разница результата владельца с (A, б+) | C17: =C15-$C15 -> 0 | D17: =D15-$C15 -> -151875 | E17: =E15-$C15 -> -94500 | F17: =F15-$C15 -> -175500
B18: БУ владельца: заказов с сайта в месяц | C18: =IF(C11>0,C14/C11,"нет БУ") -> 29.166667 | D18: =IF(D11>0,D14/D11,"нет БУ") -> 29.166667 | E18: =IF(E11>0,E14/E11,"нет БУ") -> 54.6875 | F18: =IF(F11>0,F14/F11,"нет БУ") -> 54.6875
B19: БУ владельца: расчётов уровня 1 в месяц | C19: =IF(AND(ISNUMBER(C18),Воронка!$C$13*C6>0),C18/(Воронка!$C$13*C6),"нет БУ") -> 4320.9877 | D19: =IF(AND(ISNUMBER(D18),Воронка!$C$13*D6>0),D18/(Воронка!$C$13*D6),"нет БУ") -> 17283.951 | E19: =IF(AND(ISNUMBER(E18),Воронка!$C$13*E6>0),E18/(Воронка!$C$13*E6),"нет БУ") -> 8101.8519 | F19: =IF(AND(ISNUMBER(F18),Воронка!$C$13*F6>0),F18/(Воронка!$C$13*F6),"нет БУ") -> 32407.407
B20: Простая окупаемость разработки владельцем, мес | C20: =IF(Сценарии_BEP!$C$29<=0,"нет данных о разработке",IF(C15>0,Сценарии_BEP!$C$29/C15,"не окупается")) -> не окупается | D20: =IF(Сценарии_BEP!$C$29<=0,"нет данных о разработке",IF(D15>0,Сценарии_BEP!$C$29/D15,"не окупается")) -> не окупается | E20: =IF(Сценарии_BEP!$C$29<=0,"нет данных о разработке",IF(E15>0,Сценарии_BEP!$C$29/E15,"не окупается")) -> не окупается | F20: =IF(Сценарии_BEP!$C$29<=0,"нет данных о разработке",IF(F15>0,Сценарии_BEP!$C$29/F15,"не окупается")) -> не окупается
B22: Сценарий: База
B23: Показатель | C23: I1=A · D10=б+ | D23: I1=A · D10=а | E23: I1=B · D10=б+ | F23: I1=B · D10=а
B24: Множитель потока D10 | C24: 1 | D24: =N('Входные данные'!$F$47) -> 0.25 | E24: 1 | F24: =N('Входные данные'!$F$47) -> 0.25
B25: Заказов с сайта в месяц | C25: =Воронка!$D$12*C24 -> 2.7 | D25: =Воронка!$D$12*D24 -> 0.675 | E25: =Воронка!$D$12*E24 -> 2.7 | F25: =Воронка!$D$12*F24 -> 0.675
B26: Доля партнёров | C26: 0 | D26: 0 | E26: =N('Входные данные'!$F$41) -> 0.7 | F26: =N('Входные данные'!$F$41) -> 0.7
B27: Заказов берёт KMT (в пределах мощности) | C27: =MIN(C25*(1-C26),Воронка!$D$19) -> 2.7 | D27: =MIN(D25*(1-D26),Воронка!$D$19) -> 0.675 | E27: =MIN(E25*(1-E26),Воронка!$D$19) -> 0.81 | F27: =MIN(F25*(1-F26),Воронка!$D$19) -> 0.2025
B28: Заказов у партнёров | C28: =C25*C26 -> 0 | D28: =D25*D26 -> 0 | E28: =E25*E26 -> 1.89 | F28: =F25*F26 -> 0.4725
B29: Доход владельца на заказ сайта (без мощности) | C29: =(1-C26)*'Юнит-экономика'!$D$23+C26*'Юнит-экономика'!$D$27 -> 400000 | D29: =(1-D26)*'Юнит-экономика'!$D$23+D26*'Юнит-экономика'!$D$27 -> 400000 | E29: =(1-E26)*'Юнит-экономика'!$D$23+E26*'Юнит-экономика'!$D$27 -> 190000 | F29: =(1-F26)*'Юнит-экономика'!$D$23+F26*'Юнит-экономика'!$D$27 -> 190000
B30: Доход владельца в месяц | C30: =C31+C27*'Юнит-экономика'!$D$28*(1-N('Входные данные'!$F$44)) -> 1080000 | D30: =D31+D27*'Юнит-экономика'!$D$28*(1-N('Входные данные'!$F$44)) -> 270000 | E30: =E31+E27*'Юнит-экономика'!$D$28*(1-N('Входные данные'!$F$44)) -> 513000 | F30: =F31+F27*'Юнит-экономика'!$D$28*(1-N('Входные данные'!$F$44)) -> 128250
B31: Доход проекта в месяц (комиссии) | C31: =C27*'Юнит-экономика'!$D$29+C28*'Юнит-экономика'!$D$27 -> 275400 | D31: =D27*'Юнит-экономика'!$D$29+D28*'Юнит-экономика'!$D$27 -> 68850 | E31: =E27*'Юнит-экономика'!$D$29+E28*'Юнит-экономика'!$D$27 -> 271620 | F31: =F27*'Юнит-экономика'!$D$29+F28*'Юнит-экономика'!$D$27 -> 67905
B32: Полные операционные расходы в месяц | C32: =Сценарии_BEP!$D$21 -> 8750000 | D32: =Сценарии_BEP!$D$21 -> 8750000 | E32: =Сценарии_BEP!$D$21 -> 8750000 | F32: =Сценарии_BEP!$D$21 -> 8750000
B33: Результат владельца в месяц | C33: =C30-C32 -> -7670000 | D33: =D30-D32 -> -8480000 | E33: =E30-E32 -> -8237000 | F33: =F30-F32 -> -8621750
B34: Результат проекта в месяц | C34: =C31-C32 -> -8474600 | D34: =D31-D32 -> -8681150 | E34: =E31-E32 -> -8478380 | F34: =F31-F32 -> -8682095
B35: Разница результата владельца с (A, б+) | C35: =C33-$C33 -> 0 | D35: =D33-$C33 -> -810000 | E35: =E33-$C33 -> -567000 | F35: =F33-$C33 -> -951750
B36: БУ владельца: заказов с сайта в месяц | C36: =IF(C29>0,C32/C29,"нет БУ") -> 21.875 | D36: =IF(D29>0,D32/D29,"нет БУ") -> 21.875 | E36: =IF(E29>0,E32/E29,"нет БУ") -> 46.052632 | F36: =IF(F29>0,F32/F29,"нет БУ") -> 46.052632
B37: БУ владельца: расчётов уровня 1 в месяц | C37: =IF(AND(ISNUMBER(C36),Воронка!$D$13*C24>0),C36/(Воронка!$D$13*C24),"нет БУ") -> 2430.5556 | D37: =IF(AND(ISNUMBER(D36),Воронка!$D$13*D24>0),D36/(Воронка!$D$13*D24),"нет БУ") -> 9722.2222 | E37: =IF(AND(ISNUMBER(E36),Воронка!$D$13*E24>0),E36/(Воронка!$D$13*E24),"нет БУ") -> 5116.9591 | F37: =IF(AND(ISNUMBER(F36),Воронка!$D$13*F24>0),F36/(Воронка!$D$13*F24),"нет БУ") -> 20467.836
B38: Простая окупаемость разработки владельцем, мес | C38: =IF(Сценарии_BEP!$D$29<=0,"нет данных о разработке",IF(C33>0,Сценарии_BEP!$D$29/C33,"не окупается")) -> не окупается | D38: =IF(Сценарии_BEP!$D$29<=0,"нет данных о разработке",IF(D33>0,Сценарии_BEP!$D$29/D33,"не окупается")) -> не окупается | E38: =IF(Сценарии_BEP!$D$29<=0,"нет данных о разработке",IF(E33>0,Сценарии_BEP!$D$29/E33,"не окупается")) -> не окупается | F38: =IF(Сценарии_BEP!$D$29<=0,"нет данных о разработке",IF(F33>0,Сценарии_BEP!$D$29/F33,"не окупается")) -> не окупается
B40: Сценарий: Оптимист
B41: Показатель | C41: I1=A · D10=б+ | D41: I1=A · D10=а | E41: I1=B · D10=б+ | F41: I1=B · D10=а
B42: Множитель потока D10 | C42: 1 | D42: =N('Входные данные'!$G$47) -> 0.25 | E42: 1 | F42: =N('Входные данные'!$G$47) -> 0.25
B43: Заказов с сайта в месяц | C43: =Воронка!$E$12*C42 -> 10.125 | D43: =Воронка!$E$12*D42 -> 2.53125 | E43: =Воронка!$E$12*E42 -> 10.125 | F43: =Воронка!$E$12*F42 -> 2.53125
...

Sheet Чувствительность
A1: Чувствительность
A2: Оси сеток (синий шрифт) — перебор для чувствительности, не оценки. Все ячейки результатов — формулы; расчёт идёт от столбца «База».
B4: 1. Заказов с сайта в месяц (База): конверсия расчёт→интерес × интерес→заказ
B5: строки: расчёт→интерес | столбцы: интерес→заказ
C6: 0.01 | D6: 0.02 | E6: 0.035 | F6: 0.05 | G6: 0.07
B7: 0.1 | C7: =Воронка!$D$6*$B7*C$6*Воронка!$D$11*Воронка!$D$17 -> 0.27 | D7: =Воронка!$D$6*$B7*D$6*Воронка!$D$11*Воронка!$D$17 -> 0.54 | E7: =Воронка!$D$6*$B7*E$6*Воронка!$D$11*Воронка!$D$17 -> 0.945 | F7: =Воронка!$D$6*$B7*F$6*Воронка!$D$11*Воронка!$D$17 -> 1.35 | G7: =Воронка!$D$6*$B7*G$6*Воронка!$D$11*Воронка!$D$17 -> 1.89
B8: 0.15 | C8: =Воронка!$D$6*$B8*C$6*Воронка!$D$11*Воронка!$D$17 -> 0.405 | D8: =Воронка!$D$6*$B8*D$6*Воронка!$D$11*Воронка!$D$17 -> 0.81 | E8: =Воронка!$D$6*$B8*E$6*Воронка!$D$11*Воронка!$D$17 -> 1.4175 | F8: =Воронка!$D$6*$B8*F$6*Воронка!$D$11*Воронка!$D$17 -> 2.025 | G8: =Воронка!$D$6*$B8*G$6*Воронка!$D$11*Воронка!$D$17 -> 2.835
B9: 0.2 | C9: =Воронка!$D$6*$B9*C$6*Воронка!$D$11*Воронка!$D$17 -> 0.54 | D9: =Воронка!$D$6*$B9*D$6*Воронка!$D$11*Воронка!$D$17 -> 1.08 | E9: =Воронка!$D$6*$B9*E$6*Воронка!$D$11*Воронка!$D$17 -> 1.89 | F9: =Воронка!$D$6*$B9*F$6*Воронка!$D$11*Воронка!$D$17 -> 2.7 | G9: =Воронка!$D$6*$B9*G$6*Воронка!$D$11*Воронка!$D$17 -> 3.78
B10: 0.25 | C10: =Воронка!$D$6*$B10*C$6*Воронка!$D$11*Воронка!$D$17 -> 0.675 | D10: =Воронка!$D$6*$B10*D$6*Воронка!$D$11*Воронка!$D$17 -> 1.35 | E10: =Воронка!$D$6*$B10*E$6*Воронка!$D$11*Воронка!$D$17 -> 2.3625 | F10: =Воронка!$D$6*$B10*F$6*Воронка!$D$11*Воронка!$D$17 -> 3.375 | G10: =Воронка!$D$6*$B10*G$6*Воронка!$D$11*Воронка!$D$17 -> 4.725
B11: 0.3 | C11: =Воронка!$D$6*$B11*C$6*Воронка!$D$11*Воронка!$D$17 -> 0.81 | D11: =Воронка!$D$6*$B11*D$6*Воронка!$D$11*Воронка!$D$17 -> 1.62 | E11: =Воронка!$D$6*$B11*E$6*Воронка!$D$11*Воронка!$D$17 -> 2.835 | F11: =Воронка!$D$6*$B11*F$6*Воронка!$D$11*Воронка!$D$17 -> 4.05 | G11: =Воронка!$D$6*$B11*G$6*Воронка!$D$11*Воронка!$D$17 -> 5.67
B12: Объём расчётов — заглушка. Колонка 5% — ввод владельца; 2% и 3,5% — мои исходные гипотезы из 05_4P
B14: 2. Результат владельца в месяц (База, полные расходы), сум: c1 × c2
B15: строки: расчёт→интерес | столбцы: интерес→заказ
C16: 0.01 | D16: 0.02 | E16: 0.035 | F16: 0.05 | G16: 0.07
B17: 0.1 | C17: =(MIN(Воронка!$D$6*$B17*C$16*Воронка!$D$11*Воронка!$D$17*(1-Воронка!$D$20),Воронка!$D$19)*'Юнит-экономика'!$D$23+Воронка!$D$6*$B17*C$16*Воронка!$D$11*Воронка!$D$17*Воронка!$D$20*'Юнит-экономика'!$D$27)-Сценарии_BEP!$D$21 -> -8698700 | D17: =(MIN(Воронка!$D$6*$B17*D$16*Воронка!$D$11*Воронка!$D$17*(1-Воронка!$D$20),Воронка!$D$19)*'Юнит-экономика'!$D$23+Воронка!$D$6*$B17*D$16*Воронка!$D$11*Воронка!$D$17*Воронка!$D$20*'Юнит-экономика'!$D$27)-Сценарии_BEP!$D$21 -> -8647400 | E17: =(MIN(Воронка!$D$6*$B17*E$16*Воронка!$D$11*Воронка!$D$17*(1-Воронка!$D$20),Воронка!$D$19)*'Юнит-экономика'!$D$23+Воронка!$D$6*$B17*E$16*Воронка!$D$11*Воронка!$D$17*Воронка!$D$20*'Юнит-экономика'!$D$27)-Сценарии_BEP!$D$21 -> -8570450 | F17: =(MIN(Воронка!$D$6*$B17*F$16*Воронка!$D$11*Воронка!$D$17*(1-Воронка!$D$20),Воронка!$D$19)*'Юнит-экономика'!$D$23+Воронка!$D$6*$B17*F$16*Воронка!$D$11*Воронка!$D$17*Воронка!$D$20*'Юнит-экономика'!$D$27)-Сценарии_BEP!$D$21 -> -8493500 | G17: =(MIN(Воронка!$D$6*$B17*G$16*Воронка!$D$11*Воронка!$D$17*(1-Воронка!$D$20),Воронка!$D$19)*'Юнит-экономика'!$D$23+Воронка!$D$6*$B17*G$16*Воронка!$D$11*Воронка!$D$17*Воронка!$D$20*'Юнит-экономика'!$D$27)-Сценарии_BEP!$D$21 -> -8390900
B18: 0.15 | C18: =(MIN(Воронка!$D$6*$B18*C$16*Воронка!$D$11*Воронка!$D$17*(1-Воронка!$D$20),Воронка!$D$19)*'Юнит-экономика'!$D$23+Воронка!$D$6*$B18*C$16*Воронка!$D$11*Воронка!$D$17*Воронка!$D$20*'Юнит-экономика'!$D$27)-Сценарии_BEP!$D$21 -> -8673050 | D18: =(MIN(Воронка!$D$6*$B18*D$16*Воронка!$D$11*Воронка!$D$17*(1-Воронка!$D$20),Воронка!$D$19)*'Юнит-экономика'!$D$23+Воронка!$D$6*$B18*D$16*Воронка!$D$11*Воронка!$D$17*Воронка!$D$20*'Юнит-экономика'!$D$27)-Сценарии_BEP!$D$21 -> -8596100 | E18: =(MIN(Воронка!$D$6*$B18*E$16*Воронка!$D$11*Воронка!$D$17*(1-Воронка!$D$20),Воронка!$D$19)*'Юнит-экономика'!$D$23+Воронка!$D$6*$B18*E$16*Воронка!$D$11*Воронка!$D$17*Воронка!$D$20*'Юнит-экономика'!$D$27)-Сценарии_BEP!$D$21 -> -8480675 | F18: =(MIN(Воронка!$D$6*$B18*F$16*Воронка!$D$11*Воронка!$D$17*(1-Воронка!$D$20),Воронка!$D$19)*'Юнит-экономика'!$D$23+Воронка!$D$6*$B18*F$16*Воронка!$D$11*Воронка!$D$17*Воронка!$D$20*'Юнит-экономика'!$D$27)-Сценарии_BEP!$D$21 -> -8365250 | G18: =(MIN(Воронка!$D$6*$B18*G$16*Воронка!$D$11*Воронка!$D$17*(1-Воронка!$D$20),Воронка!$D$19)*'Юнит-экономика'!$D$23+Воронка!$D$6*$B18*G$16*Воронка!$D$11*Воронка!$D$17*Воронка!$D$20*'Юнит-экономика'!$D$27)-Сценарии_BEP!$D$21 -> -8211350
B19: 0.2 | C19: =(MIN(Воронка!$D$6*$B19*C$16*Воронка!$D$11*Воронка!$D$17*(1-Воронка!$D$20),Воронка!$D$19)*'Юнит-экономика'!$D$23+Воронка!$D$6*$B19*C$16*Воронка!$D$11*Воронка!$D$17*Воронка!$D$20*'Юнит-экономика'!$D$27)-Сценарии_BEP!$D$21 -> -8647400 | D19: =(MIN(Воронка!$D$6*$B19*D$16*Воронка!$D$11*Воронка!$D$17*(1-Воронка!$D$20),Воронка!$D$19)*'Юнит-экономика'!$D$23+Воронка!$D$6*$B19*D$16*Воронка!$D$11*Воронка!$D$17*Воронка!$D$20*'Юнит-экономика'!$D$27)-Сценарии_BEP!$D$21 -> -8544800 | E19: =(MIN(Воронка!$D$6*$B19*E$16*Воронка!$D$11*Воронка!$D$17*(1-Воронка!$D$20),Воронка!$D$19)*'Юнит-экономика'!$D$23+Воронка!$D$6*$B19*E$16*Воронка!$D$11*Воронка!$D$17*Воронка!$D$20*'Юнит-экономика'!$D$27)-Сценарии_BEP!$D$21 -> -8390900 | F19: =(MIN(Воронка!$D$6*$B19*F$16*Воронка!$D$11*Воронка!$D$17*(1-Воронка!$D$20),Воронка!$D$19)*'Юнит-экономика'!$D$23+Воронка!$D$6*$B19*F$16*Воронка!$D$11*Воронка!$D$17*Воронка!$D$20*'Юнит-экономика'!$D$27)-Сценарии_BEP!$D$21 -> -8237000 | G19: =(MIN(Воронка!$D$6*$B19*G$16*Воронка!$D$11*Воронка!$D$17*(1-Воронка!$D$20),Воронка!$D$19)*'Юнит-экономика'!$D$23+Воронка!$D$6*$B19*G$16*Воронка!$D$11*Воронка!$D$17*Воронка!$D$20*'Юнит-экономика'!$D$27)-Сценарии_BEP!$D$21 -> -8031800
B20: 0.25 | C20: =(MIN(Воронка!$D$6*$B20*C$16*Воронка!$D$11*Воронка!$D$17*(1-Воронка!$D$20),Воронка!$D$19)*'Юнит-экономика'!$D$23+Воронка!$D$6*$B20*C$16*Воронка!$D$11*Воронка!$D$17*Воронка!$D$20*'Юнит-экономика'!$D$27)-Сценарии_BEP!$D$21 -> -8621750 | D20: =(MIN(Воронка!$D$6*$B20*D$16*Воронка!$D$11*Воронка!$D$17*(1-Воронка!$D$20),Воронка!$D$19)*'Юнит-экономика'!$D$23+Воронка!$D$6*$B20*D$16*Воронка!$D$11*Воронка!$D$17*Воронка!$D$20*'Юнит-экономика'!$D$27)-Сценарии_BEP!$D$21 -> -8493500 | E20: =(MIN(Воронка!$D$6*$B20*E$16*Воронка!$D$11*Воронка!$D$17*(1-Воронка!$D$20),Воронка!$D$19)*'Юнит-экономика'!$D$23+Воронка!$D$6*$B20*E$16*Воронка!$D$11*Воронка!$D$17*Воронка!$D$20*'Юнит-экономика'!$D$27)-Сценарии_BEP!$D$21 -> -8301125 | F20: =(MIN(Воронка!$D$6*$B20*F$16*Воронка!$D$11*Воронка!$D$17*(1-Воронка!$D$20),Воронка!$D$19)*'Юнит-экономика'!$D$23+Воронка!$D$6*$B20*F$16*Воронка!$D$11*Воронка!$D$17*Воронка!$D$20*'Юнит-экономика'!$D$27)-Сценарии_BEP!$D$21 -> -8108750 | G20: =(MIN(Воронка!$D$6*$B20*G$16*Воронка!$D$11*Воронка!$D$17*(1-Воронка!$D$20),Воронка!$D$19)*'Юнит-экономика'!$D$23+Воронка!$D$6*$B20*G$16*Воронка!$D$11*Воронка!$D$17*Воронка!$D$20*'Юнит-экономика'!$D$27)-Сценарии_BEP!$D$21 -> -7852250
B21: 0.3 | C21: =(MIN(Воронка!$D$6*$B21*C$16*Воронка!$D$11*Воронка!$D$17*(1-Воронка!$D$20),Воронка!$D$19)*'Юнит-экономика'!$D$23+Воронка!$D$6*$B21*C$16*Воронка!$D$11*Воронка!$D$17*Воронка!$D$20*'Юнит-экономика'!$D$27)-Сценарии_BEP!$D$21 -> -8596100 | D21: =(MIN(Воронка!$D$6*$B21*D$16*Воронка!$D$11*Воронка!$D$17*(1-Воронка!$D$20),Воронка!$D$19)*'Юнит-экономика'!$D$23+Воронка!$D$6*$B21*D$16*Воронка!$D$11*Воронка!$D$17*Воронка!$D$20*'Юнит-экономика'!$D$27)-Сценарии_BEP!$D$21 -> -8442200 | E21: =(MIN(Воронка!$D$6*$B21*E$16*Воронка!$D$11*Воронка!$D$17*(1-Воронка!$D$20),Воронка!$D$19)*'Юнит-экономика'!$D$23+Воронка!$D$6*$B21*E$16*Воронка!$D$11*Воронка!$D$17*Воронка!$D$20*'Юнит-экономика'!$D$27)-Сценарии_BEP!$D$21 -> -8211350 | F21: =(MIN(Воронка!$D$6*$B21*F$16*Воронка!$D$11*Воронка!$D$17*(1-Воронка!$D$20),Воронка!$D$19)*'Юнит-экономика'!$D$23+Воронка!$D$6*$B21*F$16*Воронка!$D$11*Воронка!$D$17*Воронка!$D$20*'Юнит-экономика'!$D$27)-Сценарии_BEP!$D$21 -> -7980500 | G21: =(MIN(Воронка!$D$6*$B21*G$16*Воронка!$D$11*Воронка!$D$17*(1-Воронка!$D$20),Воронка!$D$19)*'Юнит-экономика'!$D$23+Воронка!$D$6*$B21*G$16*Воронка!$D$11*Воронка!$D$17*Воронка!$D$20*'Юнит-экономика'!$D$27)-Сценарии_BEP!$D$21 -> -7672700
B22: С учётом мощности KMT и выбранного I1
B24: 3. БУ: заказов в месяц
B25: строки: доход на заказ с сайта, сум | столбцы: операционные расходы в месяц, сум
C26: 1000000 | D26: 2500000 | E26: 3750000 | F26: 7500000 | G26: 8750000
B27: 100000 | C27: =IF($B27>0,C$26/$B27,"нет БУ") -> 10 | D27: =IF($B27>0,D$26/$B27,"нет БУ") -> 25 | E27: =IF($B27>0,E$26/$B27,"нет БУ") -> 37.5 | F27: =IF($B27>0,F$26/$B27,"нет БУ") -> 75 | G27: =IF($B27>0,G$26/$B27,"нет БУ") -> 87.5
B28: 200000 | C28: =IF($B28>0,C$26/$B28,"нет БУ") -> 5 | D28: =IF($B28>0,D$26/$B28,"нет БУ") -> 12.5 | E28: =IF($B28>0,E$26/$B28,"нет БУ") -> 18.75 | F28: =IF($B28>0,F$26/$B28,"нет БУ") -> 37.5 | G28: =IF($B28>0,G$26/$B28,"нет БУ") -> 43.75
B29: 300000 | C29: =IF($B29>0,C$26/$B29,"нет БУ") -> 3.3333333 | D29: =IF($B29>0,D$26/$B29,"нет БУ") -> 8.3333333 | E29: =IF($B29>0,E$26/$B29,"нет БУ") -> 12.5 | F29: =IF($B29>0,F$26/$B29,"нет БУ") -> 25 | G29: =IF($B29>0,G$26/$B29,"нет БУ") -> 29.166667
