Workbook

Sheet Входные данные
A1: Модель этапа 1 HomePrice.uz v0.1 — Входные данные
A2: Единицы: сум, если не указано иное. Формулы других листов читают только этот лист. Ячейка «База» (столбец F) — то, что вы вводите; «Пессимист» и «Оптимист» берутся из неё, если не заданы отдельно.
A4: Цветовая разметка
B5: [факт] — известно из документов или от владельца (18.10.2026)
B6: [гипотеза] — предположение; часть помечена [проверить]
B7: [заглушка] — временное значение до данных (market_sizing.xlsx и др.), не оценка
B8: нужно от Темура — пусто, пока нет данных; модель считает пустое как 0 и сообщает об этом в листе «Проверка»
B9: [выбор] — переключатель модели
B10: Статус проверки модели: | C10: =Проверка!C3 -> ФОРМУЛЫ ОК, НЕ ХВАТАЕТ ДАННЫХ ВЛАДЕЛЬЦА
A12: № | B12: Параметр | C12: Ед. | D12: Статус | E12: Пессимист | F12: База | G12: Оптимист | H12: Источник | I12: Комментарий / что нужно
A13: A. Цена и срок отчёта уровня 3
A14: P01 | B14: Цена отчёта уровня 3 (KMT), средний чек | C14: сум | D14: [факт] | E14: =IF(F14="","",F14) -> 1000000 | F14: 1000000 | G14: =IF(F14="","",F14) -> 1000000 | H14: Владелец 18.10.2026; 05_4P; 02_Marketing_Context | I14: Входит ли НДС — см. строку ниже.
A15: P02 | B15: Срок отчёта | C15: дней | D15: [факт] | E15: =IF(F15="","",F15) -> 2 | F15: 2 | G15: =IF(F15="","",F15) -> 2 | H15: 05_4P; 02_Marketing_Context | I15: Цель — 1 день. В расчёте не используется.
A16: P03 | B16: Цена включает НДС? (1 = да, 0 = нет) | C16: 1/0 | D16: нужно от Темура | E16: =IF(F16="","",F16) | G16: =IF(F16="","",F16) | H16: 14_Rebaseline п.4.1 [проверить] | I16: Пусто = НДС не вычитается (выручка = цена). Вопрос Q8.
A17: P04 | B17: Ставка НДС | C17: % | D17: нужно от Темура | E17: =IF(F17="","",F17) | G17: =IF(F17="","",F17) | H17: — | I17: Ставку не подставляю: проверить действующую у бухгалтера или юриста. Вопрос Q8.
A18: P05 | B18: Курс сум за доллар (справочно) | C18: сум/$ | D18: [гипотеза][проверить] | E18: =IF(F18="","",F18) -> 12000 | F18: 12000 | G18: =IF(F18="","",F18) -> 12000 | H18: 05_4P, 14_Rebaseline п.4.1 | I18: Только для пересчёта допустимой стоимости привлечения в доллары. Проверить на дату.
A19: B. Маржа и прямые затраты одного заказа
A20: P06 | B20: Метод маржи (1 = процент владельца, 2 = построчно) | C20: 1/2 | D20: [выбор] | E20: =IF(F20="","",F20) -> 1 | F20: 1 | G20: =IF(F20="","",F20) -> 1 | H20: Решение модели | I20: Перейти на 2, когда будут данные по 20–30 заказам (Q1–Q3). При методе 2 с пустыми строками маржа = 100% — лист «Проверка» это отмечает.
A21: P07 | B21: Маржа (прибыль) заказа, % выручки | C21: % | D21: [гипотеза][проверить] | E21: 0.3 | F21: 0.5 | G21: 0.5 | H21: Владелец 18.10: прибыль ≈50% (его оценка). Пессимист 30% — заглушка из иллюстрации 14 п.4.1 (200–500 тыс. сум) | I21: Не проверено по заказам. Что входит в «прибыль» (оценщик, выезд, налоги, время администрации)? Q1.
A22: P08 | B22: Гонорар оценщика / выплата специалисту | C22: сум/заказ | D22: нужно от Темура | E22: =IF(F22="","",F22) | G22: =IF(F22="","",F22) | H22: — | I22: Только для метода 2. Q3.
A23: P09 | B23: Выезд (транспорт, время специалиста) | C23: сум/заказ | D23: нужно от Темура | E23: =IF(F23="","",F23) | G23: =IF(F23="","",F23) | H23: — | I23: Только для метода 2. Q2.
A24: P10 | B24: Проверка документов, подготовка и оформление отчёта | C24: сум/заказ | D24: нужно от Темура | E24: =IF(F24="","",F24) | G24: =IF(F24="","",F24) | H24: — | I24: Только для метода 2. Q3.
A25: P11 | B25: Налоги и сборы с заказа | C25: сум/заказ | D25: нужно от Темура | E25: =IF(F25="","",F25) | G25: =IF(F25="","",F25) | H25: — | I25: Только для метода 2. Q1, Q8.
A26: P12 | B26: Платёжные и банковские комиссии | C26: сум/заказ | D26: нужно от Темура | E26: =IF(F26="","",F26) | G26: =IF(F26="","",F26) | H26: — | I26: Только для метода 2. Q7.
A27: P13 | B27: Администрирование, связь, печать | C27: сум/заказ | D27: нужно от Темура | E27: =IF(F27="","",F27) | G27: =IF(F27="","",F27) | H27: — | I27: Только для метода 2. Q1.
A28: P14 | B28: Юридические и страховые расходы (ответственность оценщика) | C28: сум/заказ | D28: нужно от Темура | E28: =IF(F28="","",F28) | G28: =IF(F28="","",F28) | H28: Навык ценообразования: [проверить] | I28: Только для метода 2. Q1.
A29: C. Решения I1, D10 и партнёры
A30: P15 | B30: I1: кому идут заказы (1 = только KMT, 2 = гибрид: клиент партнёра остаётся партнёру) | C30: 1/2 | D30: [факт] | E30: =IF(F30="","",F30) -> 1 | F30: 1 | G30: =IF(F30="","",F30) -> 1 | H30: Владелец 18.10: базовый сценарий — заказы только в KMT | I30: Решение I1 за владельцем и не записано в 08. Оба варианта считаются рядом в листе D10_I1.
A31: P16 | B31: D10: что видит клиент после оценки (1 = блок KMT с контактами без формы, 2 = нейтральный текст) | C31: 1/2 | D31: [факт] | E31: =IF(F31="","",F31) -> 1 | F31: 1 | G31: =IF(F31="","",F31) -> 1 | H31: Владелец 18.10: блок KMT с контактами, заказ идёт в KMT, без формы до A4 | I31: Решение D10 за владельцем и не записано в 08. Оба варианта считаются рядом в листе D10_I1.
A32: P17 | B32: Доля маржи заказа, учитываемая проекту (100% = взгляд владельца на Bizzone и KMT вместе) | C32: % | D32: [гипотеза][проверить] | E32: =IF(F32="","",F32) -> 1 | F32: 1 | G32: =IF(F32="","",F32) -> 1 | H32: CLAUDE.md: проект ведёт Bizzone, KMT — партнёр; договор Bizzone–KMT в документах не описан | I32: Если маржа остаётся у KMT, у проекта как юрлица дохода нет. Q9.
A33: P18 | B33: Доля заказов от рекомендателей (банк, брокер) с вознаграждением | C33: % | D33: [гипотеза] | E33: =IF(F33="","",F33) -> 0 | F33: 0 | G33: =IF(F33="","",F33) -> 0 | H33: 14_Rebaseline п.4.3: вознаграждение за передачу клиента не вводить, пока юрист не ответил | I33: Ноль на этапе 1. Q7.
A34: P19 | B34: Вознаграждение рекомендателю, % от чека | C34: % | D34: [гипотеза] | E34: =IF(F34="","",F34) -> 0.15 | F34: 0.15 | G34: =IF(F34="","",F34) -> 0.15 | H34: 05_4P: 10–20% от чека (взята середина) | I34: Применяется к заказам через рекомендателя; на средний заказ — через долю выше.
A35: P20 | B35: I1 = гибрид: доля заказов, уходящая партнёру (клиент по ссылке или коду партнёра) | C35: % | D35: [заглушка] | E35: =IF(F35="","",F35) -> 0.2 | F35: 0.2 | G35: =IF(F35="","",F35) -> 0.2 | H35: — | I35: Данных нет, значение условное. Q14. См. сетку в «Чувствительность».
A36: P21 | B36: I1 = гибрид: плата проекту с заказа, переданного партнёру, % от чека | C36: % | D36: [гипотеза] | E36: =IF(F36="","",F36) -> 0 | F36: 0 | G36: =IF(F36="","",F36) -> 0 | H36: 14 п.4.3: без вознаграждения на этапе 1; 05_4P: 10–20% — для агрегатора (модель B) | I36: Ноль на этапе 1.
A37: P22 | B37: D10 = нейтральный текст: какая доля заказов сохраняется относительно блока KMT | C37: % | D37: [заглушка] | E37: =IF(F37="","",F37) -> 0.25 | F37: 0.25 | G37: =IF(F37="","",F37) -> 0.25 | H37: — | I37: Данных нет. Измерять по кликам на первых 100 результатах (14 п.4.2). Q14.
A38: D. Допустимое привлечение
A39: P23 | B39: Потолок доли маржи на привлечение | C39: % | D39: [гипотеза] | E39: =IF(F39="","",F39) -> 0.2 | F39: 0.2 | G39: =IF(F39="","",F39) -> 0.2 | H39: 14_Rebaseline п.4.1: рабочий потолок 20% маржи, только для расчётов | I39: Не измерено на этом рынке. Пересмотр на неделе 8–10.
A40: P24 | B40: Маркетинговый бюджет в месяц | C40: сум/мес | D40: [факт] | E40: =IF(F40="","",F40) -> 0 | F40: 0 | G40: =IF(F40="","",F40) -> 0 | H40: 08_Decisions п.5; 05_4P: бюджета нет | I40: Сумму микротестов определяет владелец (Q12).
A41: E. Воронка
A42: P25 | B42: Расчётов уровня 1 в месяц (в режиме) | C42: шт/мес | D42: [заглушка] | E42: 100 | F42: 300 | G42: 900 | H42: Заглушка до market_sizing.xlsx. Ориентир: порог ≥100 расчётов из 05/14 | I42: Не прогноз. Заменить данными market_sizing.xlsx. Q16.
...

Sheet Вопросы к Темуру
A1: Вопросы к Темуру: что нужно, чтобы заполнить красные ячейки
A2: Чем раньше ответ, тем раньше модель перестанет занижать затраты. Срок маржи по записке пересборки — 28.10.2026 (14_Rebaseline п.4.1).
A4: № | B4: Вопрос | C4: Зачем (какие ячейки) | D4: Формат ответа
A5: Q1 | B5: Маржа последних 20–30 заказов KMT. По каждому: цена, гонорар оценщика, выезд, налоги, прочие прямые затраты, итоговая прибыль. Разбивка по сегментам: ипотека, наследство, суд, налог на имущество, прочее. Что входит в «прибыль ≈50%»? | C5: Маржа заказа (m_pct, dc1–dc7). Главный драйвер допустимого привлечения и БУ | D5: Таблица или выгрузка, без ФИО клиентов
A6: Q2 | B6: Себестоимость выезда: транспорт, время специалиста, доля заказов с выездом. | C6: dc2 | D6: Сум на заказ и доля
A7: Q3 | B7: Часы специалиста на один заказ ур.3 и как оплачивается оценщик (оклад, процент с заказа, сдельно). | C7: dc1, dc3 | D7: Часы и схема оплаты
A8: Q4 | B8: Единицы часов: «Темур и Равшан 15–20, Азиз 50» — в неделю, в месяц или на весь этап 1? Какая часть — разработка и запуск (разово), какая — постоянная работа (контент, поддержка)? | C8: h_unit, dT, dR, dA | D8: 1/2/3 и доли
A9: Q5 | B9: Ставки времени: считать ли время владельца, Равшана и Азиза по рыночной ставке, по зарплате или не считать? Сумма в сум за час или за месяц для каждого. | C9: rT, rR, rA | D9: Сум/час или сум/мес на человека
A10: Q6 | B10: Хостинг и сервисы 1 млн сум в месяц: что входит (сервер в РУз, домены, Telegram-бот, аналитика, SMS, ИИ-ассистент), с НДС ли, изменится ли после pd.gov.uz? Отдельно: SMS, колл-центр. | C10: host, oth | D10: Состав и сумма
A11: Q7 | B11: Комиссии: платим ли рекомендателям (банк, брокер, нотариус) и сколько; комиссия Click/Payme после K1; планируется ли плата партнёрам-оценщикам. Ответ юриста: допустимо ли вознаграждение за передачу клиента. | C11: share_ref, k_ref, fee_c, dc5 | D11: Процент и решение юриста
A12: Q8 | B12: НДС: цена 1 млн сум с НДС или без? Какая ставка применяется к KMT? | C12: vat_incl, vat_rate | D12: Да/нет и ставка
A13: Q9 | B13: Договор Bizzone–KMT: кому достаётся маржа заказа, есть ли плата проекту за лиды или лицензию на модели, кто платит за разработку и хостинг? | C13: share_bz. Определяет, окупается ли проект или только KMT | D13: Доля маржи проекту, %
A14: Q10 | B14: Сколько заказов в месяц KMT получает сейчас (в том числе по налогу на имущество) и сколько «новых» заказов пришли бы и без HomePrice? Какова мощность KMT? | C14: incr; ограничение по мощности | D14: Число и доля
A15: Q11 | B15: Длительность этапа 1 в месяцах и разовые расходы: юрист, pd.gov.uz, Click/Payme, внешняя разработка. | C15: stage_m, ot1–ot4 | D15: Месяцы и суммы
... A20: Q16 | B20: Когда будет готов market_sizing.xlsx? Подставлю объём расчётов вместо заглушки. | C20: calcs | D20: Дата

Sheet Юнит-экономика
A1: Юнит-экономика заказа уровня 3 (отчёт KMT)
A2: Все числа — из листа «Входные данные». Выручка и маржа заказа возникают в KMT; доля, учитываемая проекту, задаётся параметром share_bz.
B4: Показатель | C4: Пессимист | D4: База | E4: Оптимист | F4: Комментарий
B5: 1. Выручка и прямые затраты
B6: Цена отчёта | C6: =N('Входные данные'!$E$14) -> 1000000 | D6: =N('Входные данные'!$F$14) -> 1000000 | E6: =N('Входные данные'!$G$14) -> 1000000 | F6: [факт] 1 млн сум
B7: НДС в цене | C7: =IF(N('Входные данные'!$E$16)=1,'Юнит-экономика'!$C$6-'Юнит-экономика'!$C$6/(1+N('Входные данные'!$E$17)),0) -> 0 | D7: =IF(N('Входные данные'!$F$16)=1,'Юнит-экономика'!$D$6-'Юнит-экономика'!$D$6/(1+N('Входные данные'!$F$17)),0) -> 0 | E7: =IF(N('Входные данные'!$G$16)=1,'Юнит-экономика'!$E$6-'Юнит-экономика'!$E$6/(1+N('Входные данные'!$G$17)),0) -> 0 | F7: Пока НДС не задан — 0 (нужно от Темура)
B8: Выручка без НДС | C8: ='Юнит-экономика'!$C$6-'Юнит-экономика'!$C$7 -> 1000000 | D8: ='Юнит-экономика'!$D$6-'Юнит-экономика'!$D$7 -> 1000000 | E8: ='Юнит-экономика'!$E$6-'Юнит-экономика'!$E$7 -> 1000000
B9: Сумма построчных прямых затрат (метод 2) | C9: =N('Входные данные'!$E$22)+N('Входные данные'!$E$23)+N('Входные данные'!$E$24)+N('Входные данные'!$E$25)+N('Входные данные'!$E$26)+N('Входные данные'!$E$27)+N('Входные данные'!$E$28) -> 0 | D9: =N('Входные данные'!$F$22)+N('Входные данные'!$F$23)+N('Входные данные'!$F$24)+N('Входные данные'!$F$25)+N('Входные данные'!$F$26)+N('Входные данные'!$F$27)+N('Входные данные'!$F$28) -> 0 | E9: =N('Входные данные'!$G$22)+N('Входные данные'!$G$23)+N('Входные данные'!$G$24)+N('Входные данные'!$G$25)+N('Входные данные'!$G$26)+N('Входные данные'!$G$27)+N('Входные данные'!$G$28) -> 0 | F9: Пока пусто — нужно от Темура
B10: Прямые затраты на заказ | C10: =IF(N('Входные данные'!$E$20)=2,'Юнит-экономика'!$C$9,'Юнит-экономика'!$C$8*(1-N('Входные данные'!$E$21))) -> 700000 | D10: =IF(N('Входные данные'!$F$20)=2,'Юнит-экономика'!$D$9,'Юнит-экономика'!$D$8*(1-N('Входные данные'!$F$21))) -> 500000 | E10: =IF(N('Входные данные'!$G$20)=2,'Юнит-экономика'!$E$9,'Юнит-экономика'!$E$8*(1-N('Входные данные'!$G$21))) -> 500000 | F10: Метод 1: выручка × (1 − маржа владельца)
B11: Маржа заказа до комиссии | C11: ='Юнит-экономика'!$C$8-'Юнит-экономика'!$C$10 -> 300000 | D11: ='Юнит-экономика'!$D$8-'Юнит-экономика'!$D$10 -> 500000 | E11: ='Юнит-экономика'!$E$8-'Юнит-экономика'!$E$10 -> 500000
B12: Маржа, % выручки | C12: =IF('Юнит-экономика'!$C$8>0,'Юнит-экономика'!$C$11/'Юнит-экономика'!$C$8,0) -> 0.3 | D12: =IF('Юнит-экономика'!$D$8>0,'Юнит-экономика'!$D$11/'Юнит-экономика'!$D$8,0) -> 0.5 | E12: =IF('Юнит-экономика'!$E$8>0,'Юнит-экономика'!$E$11/'Юнит-экономика'!$E$8,0) -> 0.5
B13: Источник маржи | C13: =IF(N('Входные данные'!$E$20)=2,IF('Юнит-экономика'!$C$9=0,"НЕТ ДАННЫХ: строки пусты","построчно"),"оценка владельца [проверить]") -> оценка владельца [проверить] | D13: =IF(N('Входные данные'!$F$20)=2,IF('Юнит-экономика'!$D$9=0,"НЕТ ДАННЫХ: строки пусты","построчно"),"оценка владельца [проверить]") -> оценка владельца [проверить] | E13: =IF(N('Входные данные'!$G$20)=2,IF('Юнит-экономика'!$E$9=0,"НЕТ ДАННЫХ: строки пусты","построчно"),"оценка владельца [проверить]") -> оценка владельца [проверить]
B15: 2. Комиссия партнёра-рекомендателя
B16: Комиссия на заказ, пришедший через рекомендателя | C16: =N('Входные данные'!$E$34)*'Юнит-экономика'!$C$8 -> 150000 | D16: =N('Входные данные'!$F$34)*'Юнит-экономика'!$D$8 -> 150000 | E16: =N('Входные данные'!$G$34)*'Юнит-экономика'!$E$8 -> 150000 | F16: [гипотеза] 10–20% от чека (05_4P)
B17: Маржа такого заказа после комиссии | C17: ='Юнит-экономика'!$C$11-'Юнит-экономика'!$C$16 -> 150000 | D17: ='Юнит-экономика'!$D$11-'Юнит-экономика'!$D$16 -> 350000 | E17: ='Юнит-экономика'!$E$11-'Юнит-экономика'!$E$16 -> 350000
B18: Комиссия съедает, % маржи | C18: =IF('Юнит-экономика'!$C$11>0,'Юнит-экономика'!$C$16/'Юнит-экономика'!$C$11,0) -> 0.5 | D18: =IF('Юнит-экономика'!$D$11>0,'Юнит-экономика'!$D$16/'Юнит-экономика'!$D$11,0) -> 0.3 | E18: =IF('Юнит-экономика'!$E$11>0,'Юнит-экономика'!$E$16/'Юнит-экономика'!$E$11,0) -> 0.3 | F18: В 14_Rebaseline: 33–67% при марже 300 тыс. сум
B19: Комиссия на средний заказ (с учётом доли рекомендателей) | C19: =N('Входные данные'!$E$33)*'Юнит-экономика'!$C$16 -> 0 | D19: =N('Входные данные'!$F$33)*'Юнит-экономика'!$D$16 -> 0 | E19: =N('Входные данные'!$G$33)*'Юнит-экономика'!$E$16 -> 0 | F19: Доля на этапе 1 — 0 по рекомендации 14
B20: Маржа среднего заказа после комиссии | C20: ='Юнит-экономика'!$C$11-'Юнит-экономика'!$C$19 -> 300000 | D20: ='Юнит-экономика'!$D$11-'Юнит-экономика'!$D$19 -> 500000 | E20: ='Юнит-экономика'!$E$11-'Юнит-экономика'!$E$19 -> 500000 | F20: База для допустимого привлечения
B22: 3. Допустимая стоимость привлечения (потолок = доля маржи)
B23: Допустимо на один заказ | C23: =N('Входные данные'!$E$39)*MAX(0,'Юнит-экономика'!$C$20) -> 60000 | D23: =N('Входные данные'!$F$39)*MAX(0,'Юнит-экономика'!$D$20) -> 100000 | E23: =N('Входные данные'!$G$39)*MAX(0,'Юнит-экономика'!$E$20) -> 100000 | F23: [гипотеза] 20% маржи (14, п.4.1)
B24: Допустимо на один «интерес» (контакт, клик) | C24: ='Юнит-экономика'!$C$23*N('Входные данные'!$E$45) -> 1200 | D24: ='Юнит-экономика'!$D$23*N('Входные данные'!$F$45) -> 3500 | E24: ='Юнит-экономика'!$E$23*N('Входные данные'!$G$45) -> 5000
B25: Допустимо на один расчёт уровня 1 | C25: ='Юнит-экономика'!$C$23*N('Входные данные'!$E$44)*N('Входные данные'!$E$45)*N('Входные данные'!$E$46) -> 180 | D25: ='Юнит-экономика'!$D$23*N('Входные данные'!$F$44)*N('Входные данные'!$F$45)*N('Входные данные'!$F$46) -> 700 | E25: ='Юнит-экономика'!$E$23*N('Входные данные'!$G$44)*N('Входные данные'!$G$45)*N('Входные данные'!$G$46) -> 1250 | F25: Учитывает инкрементальность. Платный трафик на потребительский калькулятор окупается только при очень дешёвом клике
B26: То же, долларов | C26: =IF(N('Входные данные'!$E$18)>0,'Юнит-экономика'!$C$25/N('Входные данные'!$E$18),0) -> 0.015 | D26: =IF(N('Входные данные'!$F$18)>0,'Юнит-экономика'!$D$25/N('Входные данные'!$F$18),0) -> 0.058333333 | E26: =IF(N('Входные данные'!$G$18)>0,'Юнит-экономика'!$E$25/N('Входные данные'!$G$18),0) -> 0.10416667
B27: Комиссия рекомендателя больше потолка привлечения в … раз | C27: =IF(AND('Юнит-экономика'!$C$17>0,N('Входные данные'!$E$39)>0),'Юнит-экономика'!$C$16/(N('Входные данные'!$E$39)*'Юнит-экономика'!$C$17),"н/д") -> 5 | D27: =IF(AND('Юнит-экономика'!$D$17>0,N('Входные данные'!$F$39)>0),'Юнит-экономика'!$D$16/(N('Входные данные'!$F$39)*'Юнит-экономика'!$D$17),"н/д") -> 2.1428571 | E27: =IF(AND('Юнит-экономика'!$E$17>0,N('Входные данные'!$G$39)>0),'Юнит-экономика'!$E$16/(N('Входные данные'!$G$39)*'Юнит-экономика'!$E$17),"н/д") -> 2.1428571 | F27: Если >1, вознаграждение выше потолка 20% и вводить его нельзя без пересмотра потолка
B29: 4. Маржа проекта на один заказ по решению I1
B30: I1 = только KMT | C30: ='Юнит-экономика'!$C$20*N('Входные данные'!$E$32) -> 300000 | D30: ='Юнит-экономика'!$D$20*N('Входные данные'!$F$32) -> 500000 | E30: ='Юнит-экономика'!$E$20*N('Входные данные'!$G$32) -> 500000
B31: I1 = гибрид (клиент партнёра остаётся партнёру) | C31: =((1-N('Входные данные'!$E$35))*'Юнит-экономика'!$C$20+N('Входные данные'!$E$35)*N('Входные данные'!$E$36)*'Юнит-экономика'!$C$8)*N('Входные данные'!$E$32) -> 240000 | D31: =((1-N('Входные данные'!$F$35))*'Юнит-экономика'!$D$20+N('Входные данные'!$F$35)*N('Входные данные'!$F$36)*'Юнит-экономика'!$D$8)*N('Входные данные'!$F$32) -> 400000 | E31: =((1-N('Входные данные'!$G$35))*'Юнит-экономика'!$E$20+N('Входные данные'!$G$35)*N('Входные данные'!$G$36)*'Юнит-экономика'!$E$8)*N('Входные данные'!$G$32) -> 400000 | F31: Заказы партнёра дают только плату fee_c, остальное — маржу KMT
B32: Выбранный вариант (см. «Входные данные») | C32: =IF(N('Входные данные'!$E$30)=2,'Юнит-экономика'!$C$31,'Юнит-экономика'!$C$30) -> 300000 | D32: =IF(N('Входные данные'!$F$30)=2,'Юнит-экономика'!$D$31,'Юнит-экономика'!$D$30) -> 500000 | E32: =IF(N('Входные данные'!$G$30)=2,'Юнит-экономика'!$E$31,'Юнит-экономика'!$E$30) -> 500000

Sheet Воронка
A1: Воронка: посетитель → расчёт → интерес → заказ
A2: Конверсии из 05_4P — гипотезы. До A4 «интерес» измеряется анонимным кликом по блоку KMT, не контактом.
B4: Показатель | C4: Пессимист | D4: База | E4: Оптимист | F4: Комментарий
B5: Посетителей в месяц | C5: =IF(N('Входные данные'!$E$43)>0,N('Входные данные'!$E$42)/N('Входные данные'!$E$43),"нужно измерить") -> нужно измерить | D5: =IF(N('Входные данные'!$F$43)>0,N('Входные данные'!$F$42)/N('Входные данные'!$F$43),"нужно измерить") -> нужно измерить | E5: =IF(N('Входные данные'!$G$43)>0,N('Входные данные'!$G$42)/N('Входные данные'!$G$43),"нужно измерить") -> нужно измерить | F5: Нужна конверсия посетитель → расчёт (нужно от Темура / E2)
B6: Расчётов уровня 1 в месяц | C6: =N('Входные данные'!$E$42) -> 100 | D6: =N('Входные данные'!$F$42) -> 300 | E6: =N('Входные данные'!$G$42) -> 900 | F6: [заглушка] до market_sizing.xlsx
B7: Конверсия расчёт → интерес | C7: =N('Входные данные'!$E$44) -> 0.15 | D7: =N('Входные данные'!$F$44) -> 0.2 | E7: =N('Входные данные'!$G$44) -> 0.25 | F7: [гипотеза] 05_4P
B8: Интересов в месяц | C8: =Воронка!$C$6*Воронка!$C$7 -> 15 | D8: =Воронка!$D$6*Воронка!$D$7 -> 60 | E8: =Воронка!$E$6*Воронка!$E$7 -> 225
B9: Конверсия интерес → заказ | C9: =N('Входные данные'!$E$45) -> 0.02 | D9: =N('Входные данные'!$F$45) -> 0.035 | E9: =N('Входные данные'!$G$45) -> 0.05 | F9: [гипотеза] 05_4P
B10: Заказов уровня 3 в месяц (всего) | C10: =Воронка!$C$8*Воронка!$C$9 -> 0.3 | D10: =Воронка!$D$8*Воронка!$D$9 -> 2.1 | E10: =Воронка!$E$8*Воронка!$E$9 -> 11.25
B11: Доля инкрементальных заказов | C11: =N('Входные данные'!$E$46) -> 1 | D11: =N('Входные данные'!$F$46) -> 1 | E11: =N('Входные данные'!$G$46) -> 1 | F11: [гипотеза][проверить] верхняя граница 100%
B12: Инкрементальных заказов в месяц | C12: =Воронка!$C$10*Воронка!$C$11 -> 0.3 | D12: =Воронка!$D$10*Воронка!$D$11 -> 2.1 | E12: =Воронка!$E$10*Воронка!$E$11 -> 11.25
B13: Сквозная конверсия расчёт → инкрементальный заказ | C13: =Воронка!$C$7*Воронка!$C$9*Воронка!$C$11 -> 0.003 | D13: =Воронка!$D$7*Воронка!$D$9*Воронка!$D$11 -> 0.007 | E13: =Воронка!$E$7*Воронка!$E$9*Воронка!$E$11 -> 0.0125 | F13: Диапазон 0,3% – 1,25% совпадает с 14, п.4.1 (до инкрементальности)
B14: Расчётов на один заказ | C14: =IF(Воронка!$C$13>0,1/Воронка!$C$13,"нет конверсии") -> 333.33333 | D14: =IF(Воронка!$D$13>0,1/Воронка!$D$13,"нет конверсии") -> 142.85714 | E14: =IF(Воронка!$E$13>0,1/Воронка!$E$13,"нет конверсии") -> 80
B16: Влияние решения D10
B17: Множитель потока по выбранному D10 | C17: =IF(N('Входные данные'!$E$31)=2,N('Входные данные'!$E$37),1) -> 1 | D17: =IF(N('Входные данные'!$F$31)=2,N('Входные данные'!$F$37),1) -> 1 | E17: =IF(N('Входные данные'!$G$31)=2,N('Входные данные'!$G$37),1) -> 1 | F17: б+ = 100%; нейтральный текст = доля m_a [заглушка]
B18: Заказов в месяц с учётом D10 (режим) | C18: =Воронка!$C$12*Воронка!$C$17 -> 0.3 | D18: =Воронка!$D$12*Воронка!$D$17 -> 2.1 | E18: =Воронка!$E$12*Воронка!$E$17 -> 11.25
B19: Выручка заказов в KMT, сум/мес (без НДС) | C19: =Воронка!$C$18*'Юнит-экономика'!$C$8 -> 300000 | D19: =Воронка!$D$18*'Юнит-экономика'!$D$8 -> 2100000 | E19: =Воронка!$E$18*'Юнит-экономика'!$E$8 -> 11250000
B20: Маржа проекта, сум/мес (режим, по выбранному I1) | C20: =Воронка!$C$18*'Юнит-экономика'!$C$32 -> 90000 | D20: =Воронка!$D$18*'Юнит-экономика'!$D$32 -> 1050000 | E20: =Воронка!$E$18*'Юнит-экономика'!$E$32 -> 5625000

Sheet Сценарии_BEP
A1: Точка безубыточности и окупаемость этапа 1 (три сценария)
A2: Разработка и запуск считаются отдельно от операционных затрат. Пустые входы считаются нулём — итоги занижают затраты, пока их нет.
B4: Показатель | C4: Пессимист | D4: База | E4: Оптимист | F4: Комментарий
B5: 1. Операционные расходы в месяц
B6: Хостинг и сервисы | C6: =N('Входные данные'!$E$49) -> 1000000 | D6: =N('Входные данные'!$F$49) -> 1000000 | E6: =N('Входные данные'!$G$49) -> 1000000 | F6: [факт] 1 млн сум
B7: SMS, колл-центр, прочее | C7: =N('Входные данные'!$E$50) -> 0 | D7: =N('Входные данные'!$F$50) -> 0 | E7: =N('Входные данные'!$G$50) -> 0 | F7: нужно от Темура
B8: Маркетинг | C8: =N('Входные данные'!$E$40) -> 0 | D8: =N('Входные данные'!$F$40) -> 0 | E8: =N('Входные данные'!$G$40) -> 0 | F8: [факт] бюджета нет
B9: Денежные операционные расходы | C9: =Сценарии_BEP!$C$6+Сценарии_BEP!$C$7+Сценарии_BEP!$C$8 -> 1000000 | D9: =Сценарии_BEP!$D$6+Сценарии_BEP!$D$7+Сценарии_BEP!$D$8 -> 1000000 | E9: =Сценарии_BEP!$E$6+Сценарии_BEP!$E$7+Сценарии_BEP!$E$8 -> 1000000
B10: Часов в месяц на 1 час «периода» | C10: =IF(N('Входные данные'!$E$52)=1,52/12,IF(N('Входные данные'!$E$52)=2,1,IF(AND(N('Входные данные'!$E$52)=3,N('Входные данные'!$E$53)>0),1/N('Входные данные'!$E$53),0))) -> 0 | D10: =IF(N('Входные данные'!$F$52)=1,52/12,IF(N('Входные данные'!$F$52)=2,1,IF(AND(N('Входные данные'!$F$52)=3,N('Входные данные'!$F$53)>0),1/N('Входные данные'!$F$53),0))) -> 0 | E10: =IF(N('Входные данные'!$G$52)=1,52/12,IF(N('Входные данные'!$G$52)=2,1,IF(AND(N('Входные данные'!$G$52)=3,N('Входные данные'!$G$53)>0),1/N('Входные данные'!$G$53),0))) -> 0 | F10: 0, пока не заданы единицы часов (нужно от Темура)
B11: Труд, постоянная часть: Темур | C11: =N('Входные данные'!$E$54)*(1-N('Входные данные'!$E$60))*Сценарии_BEP!$C$10*N('Входные данные'!$E$57) -> 0 | D11: =N('Входные данные'!$F$54)*(1-N('Входные данные'!$F$60))*Сценарии_BEP!$D$10*N('Входные данные'!$F$57) -> 0 | E11: =N('Входные данные'!$G$54)*(1-N('Входные данные'!$G$60))*Сценарии_BEP!$E$10*N('Входные данные'!$G$57) -> 0 | F11: часы × (1 − доля разработки) × коэф. × ставка
B12: Труд, постоянная часть: Равшан | C12: =N('Входные данные'!$E$55)*(1-N('Входные данные'!$E$61))*Сценарии_BEP!$C$10*N('Входные данные'!$E$58) -> 0 | D12: =N('Входные данные'!$F$55)*(1-N('Входные данные'!$F$61))*Сценарии_BEP!$D$10*N('Входные данные'!$F$58) -> 0 | E12: =N('Входные данные'!$G$55)*(1-N('Входные данные'!$G$61))*Сценарии_BEP!$E$10*N('Входные данные'!$G$58) -> 0 | F12: часы × (1 − доля разработки) × коэф. × ставка
B13: Труд, постоянная часть: Азиз | C13: =N('Входные данные'!$E$56)*(1-N('Входные данные'!$E$62))*Сценарии_BEP!$C$10*N('Входные данные'!$E$59) -> 0 | D13: =N('Входные данные'!$F$56)*(1-N('Входные данные'!$F$62))*Сценарии_BEP!$D$10*N('Входные данные'!$F$59) -> 0 | E13: =N('Входные данные'!$G$56)*(1-N('Входные данные'!$G$62))*Сценарии_BEP!$E$10*N('Входные данные'!$G$59) -> 0 | F13: часы × (1 − доля разработки) × коэф. × ставка
B14: Труд команды (постоянная часть), сум/мес | C14: =Сценарии_BEP!$C$11+Сценарии_BEP!$C$12+Сценарии_BEP!$C$13 -> 0 | D14: =Сценарии_BEP!$D$11+Сценарии_BEP!$D$12+Сценарии_BEP!$D$13 -> 0 | E14: =Сценарии_BEP!$E$11+Сценарии_BEP!$E$12+Сценарии_BEP!$E$13 -> 0 | F14: Условная стоимость времени, не денежный расход
B15: Полные операционные расходы, сум/мес | C15: =Сценарии_BEP!$C$9+Сценарии_BEP!$C$14 -> 1000000 | D15: =Сценарии_BEP!$D$9+Сценарии_BEP!$D$14 -> 1000000 | E15: =Сценарии_BEP!$E$9+Сценарии_BEP!$E$14 -> 1000000
B17: 2. Разработка и запуск (разово, отдельно от операционных)
B18: Периодов часов за этап | C18: =IF(N('Входные данные'!$E$52)=1,N('Входные данные'!$E$53)*52/12,IF(N('Входные данные'!$E$52)=2,N('Входные данные'!$E$53),IF(N('Входные данные'!$E$52)=3,1,0))) -> 0 | D18: =IF(N('Входные данные'!$F$52)=1,N('Входные данные'!$F$53)*52/12,IF(N('Входные данные'!$F$52)=2,N('Входные данные'!$F$53),IF(N('Входные данные'!$F$52)=3,1,0))) -> 0 | E18: =IF(N('Входные данные'!$G$52)=1,N('Входные данные'!$G$53)*52/12,IF(N('Входные данные'!$G$52)=2,N('Входные данные'!$G$53),IF(N('Входные данные'!$G$52)=3,1,0))) -> 0 | F18: Нужны единицы часов и длительность этапа
B19: Разработка и запуск: Темур | C19: =N('Входные данные'!$E$54)*N('Входные данные'!$E$60)*N('Входные данные'!$E$57)*Сценарии_BEP!$C$18 -> 0 | D19: =N('Входные данные'!$F$54)*N('Входные данные'!$F$60)*N('Входные данные'!$F$57)*Сценарии_BEP!$D$18 -> 0 | E19: =N('Входные данные'!$G$54)*N('Входные данные'!$G$60)*N('Входные данные'!$G$57)*Сценарии_BEP!$E$18 -> 0
B20: Разработка и запуск: Равшан | C20: =N('Входные данные'!$E$55)*N('Входные данные'!$E$61)*N('Входные данные'!$E$58)*Сценарии_BEP!$C$18 -> 0 | D20: =N('Входные данные'!$F$55)*N('Входные данные'!$F$61)*N('Входные данные'!$F$58)*Сценарии_BEP!$D$18 -> 0 | E20: =N('Входные данные'!$G$55)*N('Входные данные'!$G$61)*N('Входные данные'!$G$58)*Сценарии_BEP!$E$18 -> 0
B21: Разработка и запуск: Азиз | C21: =N('Входные данные'!$E$56)*N('Входные данные'!$E$62)*N('Входные данные'!$E$59)*Сценарии_BEP!$C$18 -> 0 | D21: =N('Входные данные'!$F$56)*N('Входные данные'!$F$62)*N('Входные данные'!$F$59)*Сценарии_BEP!$D$18 -> 0 | E21: =N('Входные данные'!$G$56)*N('Входные данные'!$G$62)*N('Входные данные'!$G$59)*Сценарии_BEP!$E$18 -> 0
B22: Разработка: труд команды | C22: =Сценарии_BEP!$C$19+Сценарии_BEP!$C$20+Сценарии_BEP!$C$21 -> 0 | D22: =Сценарии_BEP!$D$19+Сценарии_BEP!$D$20+Сценарии_BEP!$D$21 -> 0 | E22: =Сценарии_BEP!$E$19+Сценарии_BEP!$E$20+Сценарии_BEP!$E$21 -> 0
B23: Разовые внешние расходы | C23: =N('Входные данные'!$E$64)+N('Входные данные'!$E$65)+N('Входные данные'!$E$66)+N('Входные данные'!$E$67) -> 0 | D23: =N('Входные данные'!$F$64)+N('Входные данные'!$F$65)+N('Входные данные'!$F$66)+N('Входные данные'!$F$67) -> 0 | E23: =N('Входные данные'!$G$64)+N('Входные данные'!$G$65)+N('Входные данные'!$G$66)+N('Входные данные'!$G$67) -> 0 | F23: нужно от Темура
B24: Разработка и запуск, итого | C24: =Сценарии_BEP!$C$22+Сценарии_BEP!$C$23 -> 0 | D24: =Сценарии_BEP!$D$22+Сценарии_BEP!$D$23 -> 0 | E24: =Сценарии_BEP!$E$22+Сценарии_BEP!$E$23 -> 0
B26: 3. Точка безубыточности (режим, без ramp)
B27: Маржа проекта на заказ (выбранный I1) | C27: ='Юнит-экономика'!$C$32 -> 300000 | D27: ='Юнит-экономика'!$D$32 -> 500000 | E27: ='Юнит-экономика'!$E$32 -> 500000
B28: Эффективная конверсия расчёт → заказ (с учётом D10) | C28: =Воронка!$C$13*Воронка!$C$17 -> 0.003 | D28: =Воронка!$D$13*Воронка!$D$17 -> 0.007 | E28: =Воронка!$E$13*Воронка!$E$17 -> 0.0125
B29: БУ денежная: заказов в месяц | C29: =IF(Сценарии_BEP!$C$27>0,Сценарии_BEP!$C$9/Сценарии_BEP!$C$27,"нет БУ: маржа ≤ 0") -> 3.3333333 | D29: =IF(Сценарии_BEP!$D$27>0,Сценарии_BEP!$D$9/Сценарии_BEP!$D$27,"нет БУ: маржа ≤ 0") -> 2 | E29: =IF(Сценарии_BEP!$E$27>0,Сценарии_BEP!$E$9/Сценарии_BEP!$E$27,"нет БУ: маржа ≤ 0") -> 2 | F29: Покрывает хостинг, сервисы, маркетинг
B30: БУ полная: заказов в месяц | C30: =IF(Сценарии_BEP!$C$27>0,Сценарии_BEP!$C$15/Сценарии_BEP!$C$27,"нет БУ: маржа ≤ 0") -> 3.3333333 | D30: =IF(Сценарии_BEP!$D$27>0,Сценарии_BEP!$D$15/Сценарии_BEP!$D$27,"нет БУ: маржа ≤ 0") -> 2 | E30: =IF(Сценарии_BEP!$E$27>0,Сценарии_BEP!$E$15/Сценарии_BEP!$E$27,"нет БУ: маржа ≤ 0") -> 2 | F30: Плюс условная стоимость труда
B31: БУ денежная: расчётов уровня 1 в месяц | C31: =IF(AND(ISNUMBER(Сценарии_BEP!$C$29),Сценарии_BEP!$C$28>0),Сценарии_BEP!$C$29/Сценарии_BEP!$C$28,"нет БУ") -> 1111.1111 | D31: =IF(AND(ISNUMBER(Сценарии_BEP!$D$29),Сценарии_BEP!$D$28>0),Сценарии_BEP!$D$29/Сценарии_BEP!$D$28,"нет БУ") -> 285.71429 | E31: =IF(AND(ISNUMBER(Сценарии_BEP!$E$29),Сценарии_BEP!$E$28>0),Сценарии_BEP!$E$29/Сценарии_BEP!$E$28,"нет БУ") -> 160
B32: БУ полная: расчётов уровня 1 в месяц | C32: =IF(AND(ISNUMBER(Сценарии_BEP!$C$30),Сценарии_BEP!$C$28>0),Сценарии_BEP!$C$30/Сценарии_BEP!$C$28,"нет БУ") -> 1111.1111 | D32: =IF(AND(ISNUMBER(Сценарии_BEP!$D$30),Сценарии_BEP!$D$28>0),Сценарии_BEP!$D$30/Сценарии_BEP!$D$28,"нет БУ") -> 285.71429 | E32: =IF(AND(ISNUMBER(Сценарии_BEP!$E$30),Сценарии_BEP!$E$28>0),Сценарии_BEP!$E$30/Сценарии_BEP!$E$28,"нет БУ") -> 160
B33: БУ полная, если тратить на привлечение весь потолок: заказов в месяц | C33: =IF(Сценарии_BEP!$C$27*(1-N('Входные данные'!$E$39))>0,Сценарии_BEP!$C$15/(Сценарии_BEP!$C$27*(1-N('Входные данные'!$E$39))),"нет БУ") -> 4.1666667 | D33: =IF(Сценарии_BEP!$D$27*(1-N('Входные данные'!$F$39))>0,Сценарии_BEP!$D$15/(Сценарии_BEP!$D$27*(1-N('Входные данные'!$F$39))),"нет БУ") -> 2.5 | E33: =IF(Сценарии_BEP!$E$27*(1-N('Входные данные'!$G$39))>0,Сценарии_BEP!$E$15/(Сценарии_BEP!$E$27*(1-N('Входные данные'!$G$39))),"нет БУ") -> 2.5 | F33: Маржа за вычетом привлечения по потолку
B34: Объём сценария / БУ полная (расчёты), раз | C34: =IF(ISNUMBER(Сценарии_BEP!$C$32),Воронка!$C$6/Сценарии_BEP!$C$32,"н/д") -> 0.09 | D34: =IF(ISNUMBER(Сценарии_BEP!$D$32),Воронка!$D$6/Сценарии_BEP!$D$32,"н/д") -> 1.05 | E34: =IF(ISNUMBER(Сценарии_BEP!$E$32),Воронка!$E$6/Сценарии_BEP!$E$32,"н/д") -> 5.625 | F34: Меньше 1 — сценарий не покрывает расходы
B35: Результат в режиме до труда (маржа − денежные), сум/мес | C35: =Воронка!$C$20-Сценарии_BEP!$C$9 -> -910000 | D35: =Воронка!$D$20-Сценарии_BEP!$D$9 -> 50000 | E35: =Воронка!$E$20-Сценарии_BEP!$E$9 -> 4625000
B36: Результат в режиме с трудом (маржа − полные), сум/мес | C36: =Воронка!$C$20-Сценарии_BEP!$C$15 -> -910000 | D36: =Воронка!$D$20-Сценарии_BEP!$D$15 -> 50000 | E36: =Воронка!$E$20-Сценарии_BEP!$E$15 -> 4625000
B37: Простая окупаемость разработки, мес | C37: =IF(Сценарии_BEP!$C$24<=0,"нет данных о затратах на разработку",IF(Сценарии_BEP!$C$36>0,Сценарии_BEP!$C$24/Сценарии_BEP!$C$36,"не окупается")) -> нет данных о затратах на разработку | D37: =IF(Сценарии_BEP!$D$24<=0,"нет данных о затратах на разработку",IF(Сценарии_BEP!$D$36>0,Сценарии_BEP!$D$24/Сценарии_BEP!$D$36,"не окупается")) -> нет данных о затратах на разработку | E37: =IF(Сценарии_BEP!$E$24<=0,"нет данных о затратах на разработку",IF(Сценарии_BEP!$E$36>0,Сценарии_BEP!$E$24/Сценарии_BEP!$E$36,"не окупается")) -> нет данных о затратах на разработку | F37: Разработка ÷ месячный результат в режиме
B39: 4. Итоги 12 месяцев (с ramp)
B40: Заказов за 12 мес | C40: =P54 -> 3.45 | D40: =P71 -> 24.15 | E40: =P88 -> 129.375
B41: Маржа проекта за 12 мес | C41: =P56 -> 1035000 | D41: =P73 -> 12075000 | E41: =P90 -> 64687500
B42: Операционный результат за 12 мес | C42: =P58 -> -10965000 | D42: =P75 -> 75000 | E42: =P92 -> 52687500
B43: Итог за 12 мес с разработкой | C43: =O61 -> -10965000 | D43: =O78 -> 75000 | E43: =O95 -> 52687500
B44: Месяц окупаемости операций | C44: =IF(COUNT(D62:O62)=0,"не окупается за 12 мес",MIN(D62:O62)) -> не окупается за 12 мес | D44: =IF(COUNT(D79:O79)=0,"не окупается за 12 мес",MIN(D79:O79)) -> 11 | E44: =IF(COUNT(D96:O96)=0,"не окупается за 12 мес",MIN(D96:O96)) -> 1
...

Sheet D10_I1
A1: Влияние решений D10 и I1: по два варианта, четыре сочетания
A2: Режим (без ramp). I1: A = только KMT, C = гибрид по принадлежности клиента. D10: б+ = блок KMT с контактами без формы, а = нейтральный текст. Варианты I1-B, I1-D и D10-в/г не моделируются.
B4: Сценарий: Пессимист
B5: Показатель | C5: I1=A · D10=б+ | D5: I1=A · D10=а | E5: I1=C · D10=б+ | F5: I1=C · D10=а
B6: Множитель потока D10 | C6: 1 | D6: =N('Входные данные'!$E$37) -> 0.25 | E6: 1 | F6: =N('Входные данные'!$E$37) -> 0.25
B7: Заказов в месяц | C7: =Воронка!$C$12*C6 -> 0.3 | D7: =Воронка!$C$12*D6 -> 0.075 | E7: =Воронка!$C$12*E6 -> 0.3 | F7: =Воронка!$C$12*F6 -> 0.075
B8: Маржа проекта на заказ | C8: ='Юнит-экономика'!$C$30 -> 300000 | D8: ='Юнит-экономика'!$C$30 -> 300000 | E8: ='Юнит-экономика'!$C$31 -> 240000 | F8: ='Юнит-экономика'!$C$31 -> 240000
B9: Маржа проекта в месяц | C9: =C7*C8 -> 90000 | D9: =D7*D8 -> 22500 | E9: =E7*E8 -> 72000 | F9: =F7*F8 -> 18000
B10: Полные операционные расходы в месяц | C10: =Сценарии_BEP!$C$15 -> 1000000 | D10: =Сценарии_BEP!$C$15 -> 1000000 | E10: =Сценарии_BEP!$C$15 -> 1000000 | F10: =Сценарии_BEP!$C$15 -> 1000000
B11: Результат в месяц | C11: =C9-C10 -> -910000 | D11: =D9-D10 -> -977500 | E11: =E9-E10 -> -928000 | F11: =F9-F10 -> -982000
B12: Разница с базовым сочетанием (A, б+) | C12: =C11-$C11 -> 0 | D12: =D11-$C11 -> -67500 | E12: =E11-$C11 -> -18000 | F12: =F11-$C11 -> -72000
B13: БУ: заказов в месяц | C13: =IF(C8>0,C10/C8,"нет БУ") -> 3.3333333 | D13: =IF(D8>0,D10/D8,"нет БУ") -> 3.3333333 | E13: =IF(E8>0,E10/E8,"нет БУ") -> 4.1666667 | F13: =IF(F8>0,F10/F8,"нет БУ") -> 4.1666667
B14: БУ: расчётов уровня 1 в месяц | C14: =IF(AND(ISNUMBER(C13),Воронка!$C$13*C6>0),C13/(Воронка!$C$13*C6),"нет БУ") -> 1111.1111 | D14: =IF(AND(ISNUMBER(D13),Воронка!$C$13*D6>0),D13/(Воронка!$C$13*D6),"нет БУ") -> 4444.4444 | E14: =IF(AND(ISNUMBER(E13),Воронка!$C$13*E6>0),E13/(Воронка!$C$13*E6),"нет БУ") -> 1388.8889 | F14: =IF(AND(ISNUMBER(F13),Воронка!$C$13*F6>0),F13/(Воронка!$C$13*F6),"нет БУ") -> 5555.5556
B15: Простая окупаемость разработки, мес | C15: =IF(Сценарии_BEP!$C$24<=0,"нет данных о разработке",IF(C11>0,Сценарии_BEP!$C$24/C11,"не окупается")) -> нет данных о разработке | D15: =IF(Сценарии_BEP!$C$24<=0,"нет данных о разработке",IF(D11>0,Сценарии_BEP!$C$24/D11,"не окупается")) -> нет данных о разработке | E15: =IF(Сценарии_BEP!$C$24<=0,"нет данных о разработке",IF(E11>0,Сценарии_BEP!$C$24/E11,"не окупается")) -> нет данных о разработке | F15: =IF(Сценарии_BEP!$C$24<=0,"нет данных о разработке",IF(F11>0,Сценарии_BEP!$C$24/F11,"не окупается")) -> нет данных о разработке
B17: Сценарий: База
B18: Показатель | C18: I1=A · D10=б+ | D18: I1=A · D10=а | E18: I1=C · D10=б+ | F18: I1=C · D10=а
B19: Множитель потока D10 | C19: 1 | D19: =N('Входные данные'!$F$37) -> 0.25 | E19: 1 | F19: =N('Входные данные'!$F$37) -> 0.25
B20: Заказов в месяц | C20: =Воронка!$D$12*C19 -> 2.1 | D20: =Воронка!$D$12*D19 -> 0.525 | E20: =Воронка!$D$12*E19 -> 2.1 | F20: =Воронка!$D$12*F19 -> 0.525
B21: Маржа проекта на заказ | C21: ='Юнит-экономика'!$D$30 -> 500000 | D21: ='Юнит-экономика'!$D$30 -> 500000 | E21: ='Юнит-экономика'!$D$31 -> 400000 | F21: ='Юнит-экономика'!$D$31 -> 400000
B22: Маржа проекта в месяц | C22: =C20*C21 -> 1050000 | D22: =D20*D21 -> 262500 | E22: =E20*E21 -> 840000 | F22: =F20*F21 -> 210000
B23: Полные операционные расходы в месяц | C23: =Сценарии_BEP!$D$15 -> 1000000 | D23: =Сценарии_BEP!$D$15 -> 1000000 | E23: =Сценарии_BEP!$D$15 -> 1000000 | F23: =Сценарии_BEP!$D$15 -> 1000000
B24: Результат в месяц | C24: =C22-C23 -> 50000 | D24: =D22-D23 -> -737500 | E24: =E22-E23 -> -160000 | F24: =F22-F23 -> -790000
B25: Разница с базовым сочетанием (A, б+) | C25: =C24-$C24 -> 0 | D25: =D24-$C24 -> -787500 | E25: =E24-$C24 -> -210000 | F25: =F24-$C24 -> -840000
B26: БУ: заказов в месяц | C26: =IF(C21>0,C23/C21,"нет БУ") -> 2 | D26: =IF(D21>0,D23/D21,"нет БУ") -> 2 | E26: =IF(E21>0,E23/E21,"нет БУ") -> 2.5 | F26: =IF(F21>0,F23/F21,"нет БУ") -> 2.5
B27: БУ: расчётов уровня 1 в месяц | C27: =IF(AND(ISNUMBER(C26),Воронка!$D$13*C19>0),C26/(Воронка!$D$13*C19),"нет БУ") -> 285.71429 | D27: =IF(AND(ISNUMBER(D26),Воронка!$D$13*D19>0),D26/(Воронка!$D$13*D19),"нет БУ") -> 1142.8571 | E27: =IF(AND(ISNUMBER(E26),Воронка!$D$13*E19>0),E26/(Воронка!$D$13*E19),"нет БУ") -> 357.14286 | F27: =IF(AND(ISNUMBER(F26),Воронка!$D$13*F19>0),F26/(Воронка!$D$13*F19),"нет БУ") -> 1428.5714
B28: Простая окупаемость разработки, мес | C28: =IF(Сценарии_BEP!$D$24<=0,"нет данных о разработке",IF(C24>0,Сценарии_BEP!$D$24/C24,"не окупается")) -> нет данных о разработке | D28: =IF(Сценарии_BEP!$D$24<=0,"нет данных о разработке",IF(D24>0,Сценарии_BEP!$D$24/D24,"не окупается")) -> нет данных о разработке | E28: =IF(Сценарии_BEP!$D$24<=0,"нет данных о разработке",IF(E24>0,Сценарии_BEP!$D$24/E24,"не окупается")) -> нет данных о разработке | F28: =IF(Сценарии_BEP!$D$24<=0,"нет данных о разработке",IF(F24>0,Сценарии_BEP!$D$24/F24,"не окупается")) -> нет данных о разработке
B30: Сценарий: Оптимист
B31: Показатель | C31: I1=A · D10=б+ | D31: I1=A · D10=а | E31: I1=C · D10=б+ | F31: I1=C · D10=а
B32: Множитель потока D10 | C32: 1 | D32: =N('Входные данные'!$G$37) -> 0.25 | E32: 1 | F32: =N('Входные данные'!$G$37) -> 0.25
B33: Заказов в месяц | C33: =Воронка!$E$12*C32 -> 11.25 | D33: =Воронка!$E$12*D32 -> 2.8125 | E33: =Воронка!$E$12*E32 -> 11.25 | F33: =Воронка!$E$12*F32 -> 2.8125
B34: Маржа проекта на заказ | C34: ='Юнит-экономика'!$E$30 -> 500000 | D34: ='Юнит-экономика'!$E$30 -> 500000 | E34: ='Юнит-экономика'!$E$31 -> 400000 | F34: ='Юнит-экономика'!$E$31 -> 400000
B35: Маржа проекта в месяц | C35: =C33*C34 -> 5625000 | D35: =D33*D34 -> 1406250 | E35: =E33*E34 -> 4500000 | F35: =F33*F34 -> 1125000
B36: Полные операционные расходы в месяц | C36: =Сценарии_BEP!$E$15 -> 1000000 | D36: =Сценарии_BEP!$E$15 -> 1000000 | E36: =Сценарии_BEP!$E$15 -> 1000000 | F36: =Сценарии_BEP!$E$15 -> 1000000
B37: Результат в месяц | C37: =C35-C36 -> 4625000 | D37: =D35-D36 -> 406250 | E37: =E35-E36 -> 3500000 | F37: =F35-F36 -> 125000
B38: Разница с базовым сочетанием (A, б+) | C38: =C37-$C37 -> 0 | D38: =D37-$C37 -> -4218750 | E38: =E37-$C37 -> -1125000 | F38: =F37-$C37 -> -4500000
B39: БУ: заказов в месяц | C39: =IF(C34>0,C36/C34,"нет БУ") -> 2 | D39: =IF(D34>0,D36/D34,"нет БУ") -> 2 | E39: =IF(E34>0,E36/E34,"нет БУ") -> 2.5 | F39: =IF(F34>0,F36/F34,"нет БУ") -> 2.5
B40: БУ: расчётов уровня 1 в месяц | C40: =IF(AND(ISNUMBER(C39),Воронка!$E$13*C32>0),C39/(Воронка!$E$13*C32),"нет БУ") -> 160 | D40: =IF(AND(ISNUMBER(D39),Воронка!$E$13*D32>0),D39/(Воронка!$E$13*D32),"нет БУ") -> 640 | E40: =IF(AND(ISNUMBER(E39),Воронка!$E$13*E32>0),E39/(Воронка!$E$13*E32),"нет БУ") -> 200 | F40: =IF(AND(ISNUMBER(F39),Воронка!$E$13*F32>0),F39/(Воронка!$E$13*F32),"нет БУ") -> 800
B41: Простая окупаемость разработки, мес | C41: =IF(Сценарии_BEP!$E$24<=0,"нет данных о разработке",IF(C37>0,Сценарии_BEP!$E$24/C37,"не окупается")) -> нет данных о разработке | D41: =IF(Сценарии_BEP!$E$24<=0,"нет данных о разработке",IF(D37>0,Сценарии_BEP!$E$24/D37,"не окупается")) -> нет данных о разработке | E41: =IF(Сценарии_BEP!$E$24<=0,"нет данных о разработке",IF(E37>0,Сценарии_BEP!$E$24/E37,"не окупается")) -> нет данных о разработке | F41: =IF(Сценарии_BEP!$E$24<=0,"нет данных о разработке",IF(F37>0,Сценарии_BEP!$E$24/F37,"не окупается")) -> нет данных о разработке
B43: Цена решений (маржа проекта, сум в месяц)
B44: Показатель | C44: Пессимист | D44: База | E44: Оптимист | F44: Как читать
...

Sheet Чувствительность
A1: Чувствительность
A2: Оси сеток (синий шрифт) — перебор для чувствительности, не оценки. Все ячейки результатов — формулы; расчёт идёт от столбца «База».
B4: 1. Заказов в месяц (База): конверсия расчёт→интерес × интерес→заказ
B5: строки: расчёт→интерес | столбцы: интерес→заказ
C6: 0.01 | D6: 0.02 | E6: 0.035 | F6: 0.05 | G6: 0.07
B7: 0.1 | C7: =Воронка!$D$6*$B7*C$6*Воронка!$D$11*Воронка!$D$17 -> 0.3 | D7: =Воронка!$D$6*$B7*D$6*Воронка!$D$11*Воронка!$D$17 -> 0.6 | E7: =Воронка!$D$6*$B7*E$6*Воронка!$D$11*Воронка!$D$17 -> 1.05 | F7: =Воронка!$D$6*$B7*F$6*Воронка!$D$11*Воронка!$D$17 -> 1.5 | G7: =Воронка!$D$6*$B7*G$6*Воронка!$D$11*Воронка!$D$17 -> 2.1
B8: 0.15 | C8: =Воронка!$D$6*$B8*C$6*Воронка!$D$11*Воронка!$D$17 -> 0.45 | D8: =Воронка!$D$6*$B8*D$6*Воронка!$D$11*Воронка!$D$17 -> 0.9 | E8: =Воронка!$D$6*$B8*E$6*Воронка!$D$11*Воронка!$D$17 -> 1.575 | F8: =Воронка!$D$6*$B8*F$6*Воронка!$D$11*Воронка!$D$17 -> 2.25 | G8: =Воронка!$D$6*$B8*G$6*Воронка!$D$11*Воронка!$D$17 -> 3.15
B9: 0.2 | C9: =Воронка!$D$6*$B9*C$6*Воронка!$D$11*Воронка!$D$17 -> 0.6 | D9: =Воронка!$D$6*$B9*D$6*Воронка!$D$11*Воронка!$D$17 -> 1.2 | E9: =Воронка!$D$6*$B9*E$6*Воронка!$D$11*Воронка!$D$17 -> 2.1 | F9: =Воронка!$D$6*$B9*F$6*Воронка!$D$11*Воронка!$D$17 -> 3 | G9: =Воронка!$D$6*$B9*G$6*Воронка!$D$11*Воронка!$D$17 -> 4.2
B10: 0.25 | C10: =Воронка!$D$6*$B10*C$6*Воронка!$D$11*Воронка!$D$17 -> 0.75 | D10: =Воронка!$D$6*$B10*D$6*Воронка!$D$11*Воронка!$D$17 -> 1.5 | E10: =Воронка!$D$6*$B10*E$6*Воронка!$D$11*Воронка!$D$17 -> 2.625 | F10: =Воронка!$D$6*$B10*F$6*Воронка!$D$11*Воронка!$D$17 -> 3.75 | G10: =Воронка!$D$6*$B10*G$6*Воронка!$D$11*Воронка!$D$17 -> 5.25
B11: 0.3 | C11: =Воронка!$D$6*$B11*C$6*Воронка!$D$11*Воронка!$D$17 -> 0.9 | D11: =Воронка!$D$6*$B11*D$6*Воронка!$D$11*Воронка!$D$17 -> 1.8 | E11: =Воронка!$D$6*$B11*E$6*Воронка!$D$11*Воронка!$D$17 -> 3.15 | F11: =Воронка!$D$6*$B11*F$6*Воронка!$D$11*Воронка!$D$17 -> 4.5 | G11: =Воронка!$D$6*$B11*G$6*Воронка!$D$11*Воронка!$D$17 -> 6.3
B12: Объём расчётов — заглушка
B14: 2. Результат проекта в месяц (База, с полными расходами), сум
B15: строки: расчёт→интерес | столбцы: интерес→заказ
C16: 0.01 | D16: 0.02 | E16: 0.035 | F16: 0.05 | G16: 0.07
B17: 0.1 | C17: =Воронка!$D$6*$B17*C$16*Воронка!$D$11*Воронка!$D$17*'Юнит-экономика'!$D$32-Сценарии_BEP!$D$15 -> -850000 | D17: =Воронка!$D$6*$B17*D$16*Воронка!$D$11*Воронка!$D$17*'Юнит-экономика'!$D$32-Сценарии_BEP!$D$15 -> -700000 | E17: =Воронка!$D$6*$B17*E$16*Воронка!$D$11*Воронка!$D$17*'Юнит-экономика'!$D$32-Сценарии_BEP!$D$15 -> -475000 | F17: =Воронка!$D$6*$B17*F$16*Воронка!$D$11*Воронка!$D$17*'Юнит-экономика'!$D$32-Сценарии_BEP!$D$15 -> -250000 | G17: =Воронка!$D$6*$B17*G$16*Воронка!$D$11*Воронка!$D$17*'Юнит-экономика'!$D$32-Сценарии_BEP!$D$15 -> 50000
B18: 0.15 | C18: =Воронка!$D$6*$B18*C$16*Воронка!$D$11*Воронка!$D$17*'Юнит-экономика'!$D$32-Сценарии_BEP!$D$15 -> -775000 | D18: =Воронка!$D$6*$B18*D$16*Воронка!$D$11*Воронка!$D$17*'Юнит-экономика'!$D$32-Сценарии_BEP!$D$15 -> -550000 | E18: =Воронка!$D$6*$B18*E$16*Воронка!$D$11*Воронка!$D$17*'Юнит-экономика'!$D$32-Сценарии_BEP!$D$15 -> -212500 | F18: =Воронка!$D$6*$B18*F$16*Воронка!$D$11*Воронка!$D$17*'Юнит-экономика'!$D$32-Сценарии_BEP!$D$15 -> 125000 | G18: =Воронка!$D$6*$B18*G$16*Воронка!$D$11*Воронка!$D$17*'Юнит-экономика'!$D$32-Сценарии_BEP!$D$15 -> 575000
B19: 0.2 | C19: =Воронка!$D$6*$B19*C$16*Воронка!$D$11*Воронка!$D$17*'Юнит-экономика'!$D$32-Сценарии_BEP!$D$15 -> -700000 | D19: =Воронка!$D$6*$B19*D$16*Воронка!$D$11*Воронка!$D$17*'Юнит-экономика'!$D$32-Сценарии_BEP!$D$15 -> -400000 | E19: =Воронка!$D$6*$B19*E$16*Воронка!$D$11*Воронка!$D$17*'Юнит-экономика'!$D$32-Сценарии_BEP!$D$15 -> 50000 | F19: =Воронка!$D$6*$B19*F$16*Воронка!$D$11*Воронка!$D$17*'Юнит-экономика'!$D$32-Сценарии_BEP!$D$15 -> 500000 | G19: =Воронка!$D$6*$B19*G$16*Воронка!$D$11*Воронка!$D$17*'Юнит-экономика'!$D$32-Сценарии_BEP!$D$15 -> 1100000
B20: 0.25 | C20: =Воронка!$D$6*$B20*C$16*Воронка!$D$11*Воронка!$D$17*'Юнит-экономика'!$D$32-Сценарии_BEP!$D$15 -> -625000 | D20: =Воронка!$D$6*$B20*D$16*Воронка!$D$11*Воронка!$D$17*'Юнит-экономика'!$D$32-Сценарии_BEP!$D$15 -> -250000 | E20: =Воронка!$D$6*$B20*E$16*Воронка!$D$11*Воронка!$D$17*'Юнит-экономика'!$D$32-Сценарии_BEP!$D$15 -> 312500 | F20: =Воронка!$D$6*$B20*F$16*Воронка!$D$11*Воронка!$D$17*'Юнит-экономика'!$D$32-Сценарии_BEP!$D$15 -> 875000 | G20: =Воронка!$D$6*$B20*G$16*Воронка!$D$11*Воронка!$D$17*'Юнит-экономика'!$D$32-Сценарии_BEP!$D$15 -> 1625000
B21: 0.3 | C21: =Воронка!$D$6*$B21*C$16*Воронка!$D$11*Воронка!$D$17*'Юнит-экономика'!$D$32-Сценарии_BEP!$D$15 -> -550000 | D21: =Воронка!$D$6*$B21*D$16*Воронка!$D$11*Воронка!$D$17*'Юнит-экономика'!$D$32-Сценарии_BEP!$D$15 -> -100000 | E21: =Воронка!$D$6*$B21*E$16*Воронка!$D$11*Воронка!$D$17*'Юнит-экономика'!$D$32-Сценарии_BEP!$D$15 -> 575000 | F21: =Воронка!$D$6*$B21*F$16*Воронка!$D$11*Воронка!$D$17*'Юнит-экономика'!$D$32-Сценарии_BEP!$D$15 -> 1250000 | G21: =Воронка!$D$6*$B21*G$16*Воронка!$D$11*Воронка!$D$17*'Юнит-экономика'!$D$32-Сценарии_BEP!$D$15 -> 2150000
B23: 3. БУ: заказов в месяц
B24: строки: маржа проекта на заказ, сум | столбцы: операционные расходы в месяц, сум
C25: 1000000 | D25: 1500000 | E25: 2000000 | F25: 3000000 | G25: 5000000
B26: 200000 | C26: =IF($B26>0,C$25/$B26,"нет БУ") -> 5 | D26: =IF($B26>0,D$25/$B26,"нет БУ") -> 7.5 | E26: =IF($B26>0,E$25/$B26,"нет БУ") -> 10 | F26: =IF($B26>0,F$25/$B26,"нет БУ") -> 15 | G26: =IF($B26>0,G$25/$B26,"нет БУ") -> 25
B27: 300000 | C27: =IF($B27>0,C$25/$B27,"нет БУ") -> 3.3333333 | D27: =IF($B27>0,D$25/$B27,"нет БУ") -> 5 | E27: =IF($B27>0,E$25/$B27,"нет БУ") -> 6.6666667 | F27: =IF($B27>0,F$25/$B27,"нет БУ") -> 10 | G27: =IF($B27>0,G$25/$B27,"нет БУ") -> 16.666667
B28: 400000 | C28: =IF($B28>0,C$25/$B28,"нет БУ") -> 2.5 | D28: =IF($B28>0,D$25/$B28,"нет БУ") -> 3.75 | E28: =IF($B28>0,E$25/$B28,"нет БУ") -> 5 | F28: =IF($B28>0,F$25/$B28,"нет БУ") -> 7.5 | G28: =IF($B28>0,G$25/$B28,"нет БУ") -> 12.5
B29: 500000 | C29: =IF($B29>0,C$25/$B29,"нет БУ") -> 2 | D29: =IF($B29>0,D$25/$B29,"нет БУ") -> 3 | E29: =IF($B29>0,E$25/$B29,"нет БУ") -> 4 | F29: =IF($B29>0,F$25/$B29,"нет БУ") -> 6 | G29: =IF($B29>0,G$25/$B29,"нет БУ") -> 10
B30: 600000 | C30: =IF($B30>0,C$25/$B30,"нет БУ") -> 1.6666667 | D30: =IF($B30>0,D$25/$B30,"нет БУ") -> 2.5 | E30: =IF($B30>0,E$25/$B30,"нет БУ") -> 3.3333333 | F30: =IF($B30>0,F$25/$B30,"нет БУ") -> 5 | G30: =IF($B30>0,G$25/$B30,"нет БУ") -> 8.3333333
B31: Столбец 1 млн сум = только хостинг и сервисы
B33: 4. БУ: расчётов уровня 1 в месяц при сквозной конверсии База
B34: строки: маржа проекта на заказ, сум | столбцы: операционные расходы в месяц, сум
C35: 1000000 | D35: 1500000 | E35: 2000000 | F35: 3000000 | G35: 5000000
B36: 200000 | C36: =IF(AND($B36>0,Сценарии_BEP!$D$28>0),C$35/$B36/Сценарии_BEP!$D$28,"нет БУ") -> 714.28571 | D36: =IF(AND($B36>0,Сценарии_BEP!$D$28>0),D$35/$B36/Сценарии_BEP!$D$28,"нет БУ") -> 1071.4286 | E36: =IF(AND($B36>0,Сценарии_BEP!$D$28>0),E$35/$B36/Сценарии_BEP!$D$28,"нет БУ") -> 1428.5714 | F36: =IF(AND($B36>0,Сценарии_BEP!$D$28>0),F$35/$B36/Сценарии_BEP!$D$28,"нет БУ") -> 2142.8571 | G36: =IF(AND($B36>0,Сценарии_BEP!$D$28>0),G$35/$B36/Сценарии_BEP!$D$28,"нет БУ") -> 3571.4286
B37: 300000 | C37: =IF(AND($B37>0,Сценарии_BEP!$D$28>0),C$35/$B37/Сценарии_BEP!$D$28,"нет БУ") -> 476.19048 | D37: =IF(AND($B37>0,Сценарии_BEP!$D$28>0),D$35/$B37/Сценарии_BEP!$D$28,"нет БУ") -> 714.28571 | E37: =IF(AND($B37>0,Сценарии_BEP!$D$28>0),E$35/$B37/Сценарии_BEP!$D$28,"нет БУ") -> 952.38095 | F37: =IF(AND($B37>0,Сценарии_BEP!$D$28>0),F$35/$B37/Сценарии_BEP!$D$28,"нет БУ") -> 1428.5714 | G37: =IF(AND($B37>0,Сценарии_BEP!$D$28>0),G$35/$B37/Сценарии_BEP!$D$28,"нет БУ") -> 2380.9524
B38: 400000 | C38: =IF(AND($B38>0,Сценарии_BEP!$D$28>0),C$35/$B38/Сценарии_BEP!$D$28,"нет БУ") -> 357.14286 | D38: =IF(AND($B38>0,Сценарии_BEP!$D$28>0),D$35/$B38/Сценарии_BEP!$D$28,"нет БУ") -> 535.71429 | E38: =IF(AND($B38>0,Сценарии_BEP!$D$28>0),E$35/$B38/Сценарии_BEP!$D$28,"нет БУ") -> 714.28571 | F38: =IF(AND($B38>0,Сценарии_BEP!$D$28>0),F$35/$B38/Сценарии_BEP!$D$28,"нет БУ") -> 1071.4286 | G38: =IF(AND($B38>0,Сценарии_BEP!$D$28>0),G$35/$B38/Сценарии_BEP!$D$28,"нет БУ") -> 1785.7143
B39: 500000 | C39: =IF(AND($B39>0,Сценарии_BEP!$D$28>0),C$35/$B39/Сценарии_BEP!$D$28,"нет БУ") -> 285.71429 | D39: =IF(AND($B39>0,Сценарии_BEP!$D$28>0),D$35/$B39/Сценарии_BEP!$D$28,"нет БУ") -> 428.57143 | E39: =IF(AND($B39>0,Сценарии_BEP!$D$28>0),E$35/$B39/Сценарии_BEP!$D$28,"нет БУ") -> 571.42857 | F39: =IF(AND($B39>0,Сценарии_BEP!$D$28>0),F$35/$B39/Сценарии_BEP!$D$28,"нет БУ") -> 857.14286 | G39: =IF(AND($B39>0,Сценарии_BEP!$D$28>0),G$35/$B39/Сценарии_BEP!$D$28,"нет БУ") -> 1428.5714
B40: 600000 | C40: =IF(AND($B40>0,Сценарии_BEP!$D$28>0),C$35/$B40/Сценарии_BEP!$D$28,"нет БУ") -> 238.09524 | D40: =IF(AND($B40>0,Сценарии_BEP!$D$28>0),D$35/$B40/Сценарии_BEP!$D$28,"нет БУ") -> 357.14286 | E40: =IF(AND($B40>0,Сценарии_BEP!$D$28>0),E$35/$B40/Сценарии_BEP!$D$28,"нет БУ") -> 476.19048 | F40: =IF(AND($B40>0,Сценарии_BEP!$D$28>0),F$35/$B40/Сценарии_BEP!$D$28,"нет БУ") -> 714.28571 | G40: =IF(AND($B40>0,Сценарии_BEP!$D$28>0),G$35/$B40/Сценарии_BEP!$D$28,"нет БУ") -> 1190.4762
B42: 5. Допустимая стоимость привлечения на один расчёт, сум (потолок из «Входные данные»)
B43: строки: маржа заказа после комиссии, сум | столбцы: сквозная конверсия расчёт→заказ
C44: 0.003 | D44: 0.007 | E44: 0.0125 | F44: 0.02
B45: 200000 | C45: =$B45*N('Входные данные'!$F$39)*C$44 -> 120 | D45: =$B45*N('Входные данные'!$F$39)*D$44 -> 280 | E45: =$B45*N('Входные данные'!$F$39)*E$44 -> 500 | F45: =$B45*N('Входные данные'!$F$39)*F$44 -> 800
...

Sheet Проверка
A1: Проверка модели
A2: Статусы: OK, ОШИБКА (нужно исправить формулу), НЕТ ДАННЫХ (формулы верны, нужен ввод владельца).
B3: Общий статус: | C3: =IF(COUNTIF(D6:D25,"ОШИБКА")>0,"ЕСТЬ ОШИБКИ",IF(COUNTIF(D6:D25,"НЕТ ДАННЫХ")>0,"ФОРМУЛЫ ОК, НЕ ХВАТАЕТ ДАННЫХ ВЛАДЕЛЬЦА","ВСЁ ОК")) -> ФОРМУЛЫ ОК, НЕ ХВАТАЕТ ДАННЫХ ВЛАДЕЛЬЦА
A5: № | B5: Проверка | C5: Значение | D5: Статус | E5: Комментарий
A6: C01 | B6: Ошибки формул: Входные данные | C6: =SUMPRODUCT(--ISERROR('Входные данные'!E13:G69)) -> 0 | D6: =IF(C6=0,"OK","ОШИБКА") -> OK
A7: C02 | B7: Ошибки формул: Юнит-экономика | C7: =SUMPRODUCT(--ISERROR('Юнит-экономика'!C5:E40)) -> 0 | D7: =IF(C7=0,"OK","ОШИБКА") -> OK
A8: C03 | B8: Ошибки формул: Воронка | C8: =SUMPRODUCT(--ISERROR(Воронка!C5:E25)) -> 0 | D8: =IF(C8=0,"OK","ОШИБКА") -> OK
A9: C04 | B9: Ошибки формул: Сценарии_BEP | C9: =SUMPRODUCT(--ISERROR(Сценарии_BEP!C5:P102)) -> 0 | D9: =IF(C9=0,"OK","ОШИБКА") -> OK
A10: C05 | B10: Ошибки формул: D10_I1 | C10: =SUMPRODUCT(--ISERROR(D10_I1!C4:F60)) -> 0 | D10: =IF(C10=0,"OK","ОШИБКА") -> OK
A11: C06 | B11: Ошибки формул: Чувствительность | C11: =SUMPRODUCT(--ISERROR(Чувствительность!B4:H98)) -> 0 | D11: =IF(C11=0,"OK","ОШИБКА") -> OK
A12: C07 | B12: Тождество юнит-экономики: выручка − прямые затраты − комиссия − маржа = 0 (по 3 сценариям) | C12: =ABS('Юнит-экономика'!$C$8-'Юнит-экономика'!$C$10-'Юнит-экономика'!$C$19-'Юнит-экономика'!$C$20)+ABS('Юнит-экономика'!$D$8-'Юнит-экономика'!$D$10-'Юнит-экономика'!$D$19-'Юнит-экономика'!$D$20)+ABS('Юнит-экономика'!$E$8-'Юнит-экономика'!$E$10-'Юнит-экономика'!$E$19-'Юнит-экономика'!$E$20) -> 0 | D12: =IF(C12<0.001,"OK","ОШИБКА") -> OK
A13: C08 | B13: Маржа при методе 1 равна вводу владельца | C13: =IF(AND(N('Входные данные'!$E$20)=1,'Юнит-экономика'!$C$8>0),ABS('Юнит-экономика'!$C$12-N('Входные данные'!$E$21)),0)+IF(AND(N('Входные данные'!$F$20)=1,'Юнит-экономика'!$D$8>0),ABS('Юнит-экономика'!$D$12-N('Входные данные'!$F$21)),0)+IF(AND(N('Входные данные'!$G$20)=1,'Юнит-экономика'!$E$8>0),ABS('Юнит-экономика'!$E$12-N('Входные данные'!$G$21)),0) -> 0 | D13: =IF(C13<0.001,"OK","ОШИБКА") -> OK | E13: Проверяется, когда выручка > 0
A14: C09 | B14: Воронка: заказы = расчёты × c1 × c2 × инкрементальность | C14: =ABS(Воронка!$C$12-N('Входные данные'!$E$42)*N('Входные данные'!$E$44)*N('Входные данные'!$E$45)*N('Входные данные'!$E$46))+ABS(Воронка!$D$12-N('Входные данные'!$F$42)*N('Входные данные'!$F$44)*N('Входные данные'!$F$45)*N('Входные данные'!$F$46))+ABS(Воронка!$E$12-N('Входные данные'!$G$42)*N('Входные данные'!$G$44)*N('Входные данные'!$G$45)*N('Входные данные'!$G$46)) -> 0 | D14: =IF(C14<0.001,"OK","ОШИБКА") -> OK
A15: C10 | B15: Помесячная модель: итог за 12 мес = −разработка + сумма операций (по 3 сценариям) | C15: =ABS(Сценарии_BEP!O61-(Сценарии_BEP!C60+Сценарии_BEP!P58))+ABS(Сценарии_BEP!O78-(Сценарии_BEP!C77+Сценарии_BEP!P75))+ABS(Сценарии_BEP!O95-(Сценарии_BEP!C94+Сценарии_BEP!P92)) -> 0 | D15: =IF(C15<0.001,"OK","ОШИБКА") -> OK
A16: C11 | B16: Помесячная модель выходит на режим: заказы в 12-м месяце = режим Воронки | C16: =IF(N('Входные данные'!$F$47)>12,0,ABS(Сценарии_BEP!O54-Воронка!$C$18)+ABS(Сценарии_BEP!O71-Воронка!$D$18)+ABS(Сценарии_BEP!O88-Воронка!$E$18)) -> 0 | D16: =IF(C16<0.001,"OK","ОШИБКА") -> OK | E16: Проверка пропускается, если время выхода на режим больше 12 мес
A17: C12 | B17: D10_I1: выбранное сочетание совпадает с основным расчётом (лист БУ) | C17: =ABS(INDEX(D10_I1!C11:F11,1,(N('Входные данные'!$E$30)-1)*2+N('Входные данные'!$E$31))-Сценарии_BEP!$C$36)+ABS(INDEX(D10_I1!C24:F24,1,(N('Входные данные'!$F$30)-1)*2+N('Входные данные'!$F$31))-Сценарии_BEP!$D$36)+ABS(INDEX(D10_I1!C37:F37,1,(N('Входные данные'!$G$30)-1)*2+N('Входные данные'!$G$31))-Сценарии_BEP!$E$36) -> 0 | D17: =IF(C17<0.001,"OK","ОШИБКА") -> OK
A18: C13 | B18: Доли и конверсии лежат в диапазоне 0–100% | C18: =IF(AND(MIN('Входные данные'!E21:G21)>=0,MAX('Входные данные'!E21:G21)<=1,MIN('Входные данные'!E32:G32)>=0,MAX('Входные данные'!E32:G32)<=1,MIN('Входные данные'!E33:G33)>=0,MAX('Входные данные'!E33:G33)<=1,MIN('Входные данные'!E34:G34)>=0,MAX('Входные данные'!E34:G34)<=1,MIN('Входные данные'!E35:G35)>=0,MAX('Входные данные'!E35:G35)<=1,MIN('Входные данные'!E36:G36)>=0,MAX('Входные данные'!E36:G36)<=1,MIN('Входные данные'!E37:G37)>=0,MAX('Входные данные'!E37:G37)<=1,MIN('Входные данные'!E39:G39)>=0,MAX('Входные данные'!E39:G39)<=1,MIN('Входные данные'!E44:G44)>=0,MAX('Входные данные'!E44:G44)<=1,MIN('Входные данные'!E45:G45)>=0,MAX('Входные данные'!E45:G45)<=1,MIN('Входные данные'!E46:G46)>=0,MAX('Входные данные'!E46:G46)<=1,MIN('Входные данные'!E60:G60)>=0,MAX('Входные данные'!E60:G60)<=1,MIN('Входные данные'!E61:G61)>=0,MAX('Входные данные'!E61:G61)<=1,MIN('Входные данные'!E62:G62)>=0,MAX('Входные данные'!E62:G62)<=1),0,1) -> 0 | D18: =IF(C18=0,"OK","ОШИБКА") -> OK
A19: C14 | B19: Переключатели допустимы (метод 1/2, I1 1/2, D10 1/2, часы 0/1/2/3) | C19: =IF(AND(OR('Входные данные'!F20=1,'Входные данные'!F20=2),OR('Входные данные'!F30=1,'Входные данные'!F30=2),OR('Входные данные'!F31=1,'Входные данные'!F31=2),OR(N('Входные данные'!F52)=0,N('Входные данные'!F52)=1,N('Входные данные'!F52)=2,N('Входные данные'!F52)=3)),0,1) -> 0 | D19: =IF(C19=0,"OK","ОШИБКА") -> OK
A20: C15 | B20: Метод 2 выбран, но построчные затраты пусты (маржа вышла бы 100%) | C20: =IF(AND('Входные данные'!F20=2,'Юнит-экономика'!$D$9=0),1,0) -> 0 | D20: =IF(C20=0,"OK","ОШИБКА") -> OK
A21: C16 | B21: Пустых входов «нужно от Темура» (из 21) | C21: =IF('Входные данные'!F16="",1,0)+IF('Входные данные'!F17="",1,0)+IF('Входные данные'!F22="",1,0)+IF('Входные данные'!F23="",1,0)+IF('Входные данные'!F24="",1,0)+IF('Входные данные'!F25="",1,0)+IF('Входные данные'!F26="",1,0)+IF('Входные данные'!F27="",1,0)+IF('Входные данные'!F28="",1,0)+IF('Входные данные'!F43="",1,0)+IF('Входные данные'!F50="",1,0)+IF('Входные данные'!F52="",1,0)+IF('Входные данные'!F53="",1,0)+IF('Входные данные'!F57="",1,0)+IF('Входные данные'!F58="",1,0)+IF('Входные данные'!F59="",1,0)+IF('Входные данные'!F64="",1,0)+IF('Входные данные'!F65="",1,0)+IF('Входные данные'!F66="",1,0)+IF('Входные данные'!F67="",1,0)+IF('Входные данные'!F69="",1,0) -> 21 | D21: =IF(C21=0,"OK","НЕТ ДАННЫХ") -> НЕТ ДАННЫХ | E21: Список вопросов — лист «Вопросы к Темуру»
A22: C17 | B22: Единицы часов не заданы: труд команды не оценён | C22: =IF(N('Входные данные'!F52)=0,1,0) -> 1 | D22: =IF(C22=0,"OK","НЕТ ДАННЫХ") -> НЕТ ДАННЫХ
A23: C18 | B23: Единицы часов заданы, а длительность этапа нет: разработка и труд занижены | C23: =IF(AND(N('Входные данные'!F52)>0,N('Входные данные'!F53)<=0),1,0) -> 0 | D23: =IF(C23=0,"OK","НЕТ ДАННЫХ") -> OK
A24: C19 | B24: Ставки не заданы: труд команды = 0 | C24: =IF(AND(N('Входные данные'!F57)=0,N('Входные данные'!F58)=0,N('Входные данные'!F59)=0),1,0) -> 1 | D24: =IF(C24=0,"OK","НЕТ ДАННЫХ") -> НЕТ ДАННЫХ
A25: C20 | B25: Затраты на разработку не заданы: окупаемость разработки не считается | C25: =IF(Сценарии_BEP!$D$24<=0,1,0) -> 1 | D25: =IF(C25=0,"OK","НЕТ ДАННЫХ") -> НЕТ ДАННЫХ
B27: Баланс допущений (по статусам строк во «Входные данные»)
B28: [факт] | C28: =SUMPRODUCT(--(LEFT('Входные данные'!D13:D69,6)="[факт]")) -> 9
B29: [гипотеза] (включая [проверить]) | C29: =SUMPRODUCT(--(LEFT('Входные данные'!D13:D69,10)="[гипотеза]")) -> 14
B30: [заглушка] | C30: =SUMPRODUCT(--(LEFT('Входные данные'!D13:D69,10)="[заглушка]")) -> 3
B31: нужно от Темура | C31: =SUMPRODUCT(--(LEFT('Входные данные'!D13:D69,15)="нужно от Темура")) -> 21
B32: [выбор] | C32: =SUMPRODUCT(--(LEFT('Входные данные'!D13:D69,7)="[выбор]")) -> 1
B33: Всего параметров | C33: =SUM(C28:C32) -> 48 | D33: =IF(C33=48,"OK","ОШИБКА") -> OK | E33: Сумма по статусам должна равняться числу параметров
B34: Драйверы выручки (объём, c1, c2, инкрементальность, маржа): из них [факт] | C34: =IF(LEFT('Входные данные'!D42,6)="[факт]",1,0)+IF(LEFT('Входные данные'!D44,6)="[факт]",1,0)+IF(LEFT('Входные данные'!D45,6)="[факт]",1,0)+IF(LEFT('Входные данные'!D46,6)="[факт]",1,0)+IF(LEFT('Входные данные'!D21,6)="[факт]",1,0) -> 0 | E34: из 5: основной вывод модели держится на гипотезах и заглушках
B36: Граничные случаи (прогон скриптом при создании файла; каждый — отдельная копия книги с пересчётом)
A37: № | B37: Случай | C37: Ошибок формул | D37: Результат | E37: Что показали
A38: T01 | B38: Исходное состояние: все «нужно от Темура» пусты | C38: 0 | D38: OK | E38: Считается без ошибок; 4 проверки честно показывают «НЕТ ДАННЫХ». База: БУ 2,0 заказа в месяц, покрывает только хостинг.
A39: T02 | B39: Маржа заказа = 0% во всех сценариях | C39: 0 | D39: OK | E39: БУ показывает «нет БУ», допустимое привлечение 0, деления на ноль нет.
A40: T03 | B40: Конверсия расчёт → интерес = 0 | C40: 0 | D40: OK | E40: БУ в расчётах — «нет БУ»; результат −1 млн сум в месяц (расходы без дохода).
A41: T04 | B41: Расчётов уровня 1 в месяц = 0 | C41: 0 | D41: OK | E41: Результат −1 млн сум в месяц; БУ считается без ошибок.
A42: T05 | B42: Потолок привлечения = 0 | C42: 0 | D42: OK | E42: Допустимо на заказ 0; отношение комиссии к потолку — «н/д».
A43: T06 | B43: Цена отчёта = 0 | C43: 0 | D43: OK | E43: Маржа 0, БУ «нет БУ», ошибок нет.
...
